Workbook

Sheet 1、架空线路红外检测
A1: 广供电输二〔2023〕1号附件2
A2: 输电管理二所2023年人机协同预试检测计划（关键和重要线路1年2测，一般和关注线路1年1测）
A3: 序号 | B3: 工作类型 | C3: 计划类型 | D3: 电压等级 | E3: 线路重要度 | F3: 线路名称 | G3: 作业内容 | H3: 设备设施名称 | I3: 复合绝缘子：杆塔数量（基） | J3: 绝缘子数量（串） | K3: 合成绝缘子投运年限 | L3: 导地线：杆塔数量（基） | M3: 计划开始日期 | N3: 计划结束日期 | O3: 是否停电 | P3: 责任单位 | Q3: 中心负责人 | R3: 线路专责人 | S3: 责任中心 | T3: 计划完成数 | U3: 实际开始日期(自动计算） | V3: 实际结束日期(自动计算） | W3: 实际完成数 (自动计算） | X3: 合格数量 (自动计算） | Y3: 完成率 (自动计算） | Z3: 合格率 (自动计算） | AA3: 备注（异常情况、未按时完成原因） | AB3: 对应系统中计划编号 | AC3: 对应系统中计划状态 | AD3: 问题 | AE3: 提醒 | AF3: 中心反馈
A4: 1 | B4: 预试 | C4: 考核 | D4: 500kV | E4: 关键 | F4: 从科甲线 | G4: 机巡区复合绝缘子 | H4: #01、#02、#03、#04、#05、#06、#07、#08、#09、#10、#11、#13、#14、#15、#16、#17、#18、#19、#20、#21、#22、#23、#24、#26、#28、#29、#30、#31、#33、#34、#35、#36、#37、#38、#39、#40、#41、#42、#43、#44、#45、#46、#47、#48、#49、#50、#51、#52、#53、#54、#55、#56、#57、#58、#59、#60、#61、#62、#63、#64、#65、#66、#67、#68、#69、#70、#71、#72、#73、#74、#75、#76、#77、#78、#79、#80、#81、#82、#83、#84、#85、#86、#87、#88、#89、#90、#91、#92、#96、#97、#98、#99、#100、#101、#102、#103、#104、#105、#106、#107、#108、#109、#110、#111、#112、#113、#115 | I4: 107 | J4: 448 | K4: 9 | M4: 44986 | N4: 2023年3月31日 | O4: 否 | P4: 输电管理二所 | Q4: 吴达 | R4: 甘永叶 | S4: 天河中心 | T4: 448 | U4: 2023-03-17 08:48:00 | V4: 2023-03-17 11:57:00 | W4: 448 | X4: 448 | Y4: 1 | Z4: 1 | AB4: JH030120230111-010828 | AC4: 已完成 | AH4: =IF(N4="2023年01月","2023年01月31日",IF(N4="2023年02月","2023年02月28日",IF(N4="2023年3月","2023年3月31日",IF(N4="2023年4月","2023年4月30日",IF(N4="2023年5月","2023年5月31日",IF(N4="2023年6月","2023年6月30日",IF(N4="2023年7月","2023年7月31日",IF(N4="2023年8月","2023年8月31日",IF(N4="2023年9月","2023年9月30日",IF(N4="2023年10月","2023年10月31日",IF(N4="2023年11月","2023年11月30日",IF(N4="2023年12月","2023年12月31日")))))))))))) -> FALSE
A5: 2 | B5: 预试 | C5: 考核 | D5: 500kV | E5: 关键 | F5: 从科甲线 | G5: 导、地线连接位置 | H5: 耐张线夹： #01、#05、#09、#10、#12、#20、#23、#25、#27、#28、#29、#31、#32、#34、#35、#37、#38、#40、#44、#49、#52、#57、#63、#66、#69、#71、#78、#82、#83、#85、#87、#89、#91、#95、#98、#100、#101、#103、#105、#106、#107、#108、#111、#113、#114、#116、#117、#118 | L5: 48 | M5: 44986 | N5: 2023年3月31日 | O5: 否 | P5: 输电管理二所 | Q5: 吴达 | R5: 甘永叶 | S5: 天河中心 | T5: 48 | U5: 2023-03-17 08:48:00 | V5: 2023-03-17 11:57:00 | W5: 48 | X5: 48 | Y5: 1 | Z5: 1 | AB5: JH030120230111-010828 | AC5: 已完成 | AH5: =IF(N5="2023年01月","2023年01月31日",IF(N5="2023年02月","2023年02月28日",IF(N5="2023年3月","2023年3月31日",IF(N5="2023年4月","2023年4月30日",IF(N5="2023年5月","2023年5月31日",IF(N5="2023年6月","2023年6月30日",IF(N5="2023年7月","2023年7月31日",IF(N5="2023年8月","2023年8月31日",IF(N5="2023年9月","2023年9月30日",IF(N5="2023年10月","2023年10月31日",IF(N5="2023年11月","2023年11月30日",IF(N5="2023年12月","2023年12月31日")))))))))))) -> FALSE
A6: 3 | B6: 预试 | C6: 考核 | D6: 500kV | E6: 关键 | F6: 从科甲线 | G6: 导、地线连接位置 | H6: 接续管或预绞丝：#02-#03（B相）、#04-#05（A相）、#04-#05（C相）、#07-#08（B相）、#10-#11（C相）、#11-#12（C相）、#15-#16（A相）、#15-#16（B相）、#15-#16（C相）、#18-#19（B相）、#19-#20（A相）、#19-#20（C相）、#23-#24（B相）、#27-#28（A相）、#27-#28（C相）、#33-#34（A相）、#33-#34（B相）、#41-#42（C相）、#43-#44（A相）、#44-#45（A相）、#44-#45（B相）、#44-#45（C相）、#46-#47（B相）、#47-#48（B相）、#49-#50（C相）、#49-#50（B相）、#50-#51（A相）、#50-#51（B相）、#50-#51（C相）、#52-#53（B相）、#53-#54（A相）、#53-#54（B相）、#54-#55（C相）、#57-#58（A相）、#57-#58（B相）、#59-#60（C相）、#60-#61（B相）、#65-#66（B相）、#66-#67（A相）、#68-#69（B相）、#71-#72（C相）、#73-#74（B相）、#75-#76（A相）、#76-#77（C相）、#80-#81（B相）、#91-#92（B相）、#91-#92（C相）、#97-#98（A相）、#97-#98（B相）、#97-#98（C相）、#104-#105（B相）、#113-#114（B相）、#113-#114（C相） | L6: 53 | M6: 44986 | N6: 2023年3月31日 | O6: 否 | P6: 输电管理二所 | Q6: 吴达 | R6: 甘永叶 | S6: 天河中心 | T6: 53 | U6: 2023-03-17 08:48:00 | V6: 2023-03-17 11:57:00 | W6: 53 | X6: 53 | Y6: 1 | Z6: 1 | AB6: JH030120230111-010828 | AC6: 已完成 | AH6: =IF(N6="2023年01月","2023年01月31日",IF(N6="2023年02月","2023年02月28日",IF(N6="2023年3月","2023年3月31日",IF(N6="2023年4月","2023年4月30日",IF(N6="2023年5月","2023年5月31日",IF(N6="2023年6月","2023年6月30日",IF(N6="2023年7月","2023年7月31日",IF(N6="2023年8月","2023年8月31日",IF(N6="2023年9月","2023年9月30日",IF(N6="2023年10月","2023年10月31日",IF(N6="2023年11月","2023年11月30日",IF(N6="2023年12月","2023年12月31日")))))))))))) -> FALSE
A7: 4 | B7: 预试 | C7: 考核 | D7: 500kV | E7: 关键 | F7: 从科甲线 | G7: 机巡区复合绝缘子 | H7: #01、#02、#03、#04、#05、#06、#07、#08、#09、#10、#11、#13、#14、#15、#16、#17、#18、#19、#20、#21、#22、#23、#24、#26、#28、#29、#30、#31、#33、#34、#35、#36、#37、#38、#39、#40、#41、#42、#43、#44、#45、#46、#47、#48、#49、#50、#51、#52、#53、#54、#55、#56、#57、#58、#59、#60、#61、#62、#63、#64、#65、#66、#67、#68、#69、#70、#71、#72、#73、#74、#75、#76、#77、#78、#79、#80、#81、#82、#83、#84、#85、#86、#87、#88、#89、#90、#91、#92、#96、#97、#98、#99、#100、#101、#102、#103、#104、#105、#106、#107、#108、#109、#110、#111、#112、#113、#115 | I7: 107 | J7: 448 | K7: 9 | M7: 45170 | N7: 2023年9月30日 | O7: 否 | P7: 输电管理二所 | Q7: 吴达 | R7: 甘永叶 | S7: 天河中心 | T7: 448 | U7: 2023-09-07 08:46:00 | V7: 2023-09-07 12:07:00 | W7: 448 | X7: 448 | Y7: 1 | Z7: 1 | AB7: JH030120230111-014592 | AC7: 已完成 | AH7: =IF(N7="2023年01月","2023年01月31日",IF(N7="2023年02月","2023年02月28日",IF(N7="2023年3月","2023年3月31日",IF(N7="2023年4月","2023年4月30日",IF(N7="2023年5月","2023年5月31日",IF(N7="2023年6月","2023年6月30日",IF(N7="2023年7月","2023年7月31日",IF(N7="2023年8月","2023年8月31日",IF(N7="2023年9月","2023年9月30日",IF(N7="2023年10月","2023年10月31日",IF(N7="2023年11月","2023年11月30日",IF(N7="2023年12月","2023年12月31日")))))))))))) -> FALSE
A8: 5 | B8: 预试 | C8: 考核 | D8: 500kV | E8: 关键 | F8: 从科甲线 | G8: 导、地线连接位置 | H8: 耐张线夹： #01、#05、#09、#10、#12、#20、#23、#25、#27、#28、#29、#31、#32、#34、#35、#37、#38、#40、#44、#49、#52、#57、#63、#66、#69、#71、#78、#82、#83、#85、#87、#89、#91、#95、#98、#100、#101、#103、#105、#106、#107、#108、#111、#113、#114、#116、#117、#118 | L8: 48 | M8: 45170 | N8: 2023年9月30日 | O8: 否 | P8: 输电管理二所 | Q8: 吴达 | R8: 甘永叶 | S8: 天河中心 | T8: 48 | U8: 2023-09-07 08:46:00 | V8: 2023-09-07 12:07:00 | W8: 48 | X8: 48 | Y8: 1 | Z8: 1 | AB8: JH030120230111-014592 | AC8: 已完成 | AH8: =IF(N8="2023年01月","2023年01月31日",IF(N8="2023年02月","2023年02月28日",IF(N8="2023年3月","2023年3月31日",IF(N8="2023年4月","2023年4月30日",IF(N8="2023年5月","2023年5月31日",IF(N8="2023年6月","2023年6月30日",IF(N8="2023年7月","2023年7月31日",IF(N8="2023年8月","2023年8月31日",IF(N8="2023年9月","2023年9月30日",IF(N8="2023年10月","2023年10月31日",IF(N8="2023年11月","2023年11月30日",IF(N8="2023年12月","2023年12月31日")))))))))))) -> FALSE
A9: 6 | B9: 预试 | C9: 考核 | D9: 500kV | E9: 关键 | F9: 从科甲线 | G9: 导、地线连接位置 | H9: 接续管或预绞丝：#02-#03（B相）、#04-#05（A相）、#04-#05（C相）、#07-#08（B相）、#10-#11（C相）、#11-#12（C相）、#15-#16（A相）、#15-#16（B相）、#15-#16（C相）、#18-#19（B相）、#19-#20（A相）、#19-#20（C相）、#23-#24（B相）、#27-#28（A相）、#27-#28（C相）、#33-#34（A相）、#33-#34（B相）、#41-#42（C相）、#43-#44（A相）、#44-#45（A相）、#44-#45（B相）、#44-#45（C相）、#46-#47（B相）、#47-#48（B相）、#49-#50（C相）、#49-#50（B相）、#50-#51（A相）、#50-#51（B相）、#50-#51（C相）、#52-#53（B相）、#53-#54（A相）、#53-#54（B相）、#54-#55（C相）、#57-#58（A相）、#57-#58（B相）、#59-#60（C相）、#60-#61（B相）、#65-#66（B相）、#66-#67（A相）、#68-#69（B相）、#71-#72（C相）、#73-#74（B相）、#75-#76（A相）、#76-#77（C相）、#80-#81（B相）、#91-#92（B相）、#91-#92（C相）、#97-#98（A相）、#97-#98（B相）、#97-#98（C相）、#104-#105（B相）、#113-#114（B相）、#113-#114（C相） | L9: 53 | M9: 45170 | N9: 2023年9月30日 | O9: 否 | P9: 输电管理二所 | Q9: 吴达 | R9: 甘永叶 | S9: 天河中心 | T9: 53 | U9: 2023-09-07 08:46:00 | V9: 2023-09-07 12:07:00 | W9: 53 | X9: 53 | Y9: 1 | Z9: 1 | AB9: JH030120230111-014592 | AC9: 已完成 | AH9: =IF(N9="2023年01月","2023年01月31日",IF(N9="2023年02月","2023年02月28日",IF(N9="2023年3月","2023年3月31日",IF(N9="2023年4月","2023年4月30日",IF(N9="2023年5月","2023年5月31日",IF(N9="2023年6月","2023年6月30日",IF(N9="2023年7月","2023年7月31日",IF(N9="2023年8月","2023年8月31日",IF(N9="2023年9月","2023年9月30日",IF(N9="2023年10月","2023年10月31日",IF(N9="2023年11月","2023年11月30日",IF(N9="2023年12月","2023年12月31日")))))))))))) -> FALSE
A10: 7 | B10: 预试 | C10: 考核 | D10: 500kV | E10: 关键 | F10: 从科乙线 | G10: 机巡区复合绝缘子 | H10: #01、#02、#03、#04、#05、#06、#07、#08、#09、#10、#11、#12、#13、#14、#15、#16、#17、#18、#19、#20、#21、#22、#24、#25、#26、#27、#28、#30、#31、#32、#33、#34、#35、#36、#37、#38、#39、#40、#41、#42、#43、#44、#45、#46、#47、#48、#49、#50、#51、#52、#53、#54、#55、#56、#57、#58、#59、#60、#61、#62、#63、#64、#65、#66、#67、#68、#69、#70、#71、#72、#73、#74、#75、#76、#77、#78、#79、#80、#81、#82、#83、#84、#85、#86、#87、#88、#89、#90、#91、#92、#96、#97、#98、#99、#100、#101、#102、#103、#104、#105、#106、#107、#108、#109、#110、#111、#112、#113、#115 | I10: 109 | J10: 442 | K10: 9 | M10: 44986 | N10: 2023年3月31日 | O10: 否 | P10: 输电管理二所 | Q10: 吴达 | R10: 甘永叶 | S10: 天河中心 | T10: 442 | U10: 2023-03-17 08:48:00 | V10: 2023-03-17 11:57:00 | W10: 442 | X10: 442 | Y10: 1 | Z10: 1 | AB10: JH030120230111-010828 | AC10: 已完成 | AH10: =IF(N10="2023年01月","2023年01月31日",IF(N10="2023年02月","2023年02月28日",IF(N10="2023年3月","2023年3月31日",IF(N10="2023年4月","2023年4月30日",IF(N10="2023年5月","2023年5月31日",IF(N10="2023年6月","2023年6月30日",IF(N10="2023年7月","2023年7月31日",IF(N10="2023年8月","2023年8月31日",IF(N10="2023年9月","2023年9月30日",IF(N10="2023年10月","2023年10月31日",IF(N10="2023年11月","2023年11月30日",IF(N10="2023年12月","2023年12月31日")))))))))))) -> FALSE
A11: 8 | B11: 预试 | C11: 考核 | D11: 500kV | E11: 关键 | F11: 从科乙线 | G11: 机巡区瓷质绝缘子 | H11: #12、#20、#23、#25、#27、#28、#29、#31、#32 | I11: 9 | J11: 108 | K11: 9 | M11: 44986 | N11: 2023年3月31日 | O11: 否 | P11: 输电管理二所 | Q11: 吴达 | R11: 甘永叶 | S11: 天河中心 | T11: 108 | U11: 2023-03-17 08:48:00 | V11: 2023-03-17 11:57:00 | W11: 108 | X11: 108 | Y11: 1 | Z11: 1 | AB11: JH030120230111-010828 | AC11: 已完成 | AH11: =IF(N11="2023年01月","2023年01月31日",IF(N11="2023年02月","2023年02月28日",IF(N11="2023年3月","2023年3月31日",IF(N11="2023年4月","2023年4月30日",IF(N11="2023年5月","2023年5月31日",IF(N11="2023年6月","2023年6月30日",IF(N11="2023年7月","2023年7月31日",IF(N11="2023年8月","2023年8月31日",IF(N11="2023年9月","2023年9月30日",IF(N11="2023年10月","2023年10月31日",IF(N11="2023年11月","2023年11月30日",IF(N11="2023年12月","2023年12月31日")))))))))))) -> FALSE
A12: 9 | B12: 预试 | C12: 考核 | D12: 500kV | E12: 关键 | F12: 从科乙线 | G12: 导、地线连接位置 | H12: 耐张线夹： #01、#05、#09、#10、#12、#20、#23、#25、#27、#28、#29、#31、#32、#34、#35、#37、#38、#40、#44、#49、#52、#57、#63、#66、#69、#71、#78、#82、#83、#85、#87、#89、#91、#95、#98、#100、#101、#103、#105、#106、#107、#110、#111、#113、#114、#116、#117、#118 | L12: 48 | M12: 44986 | N12: 2023年3月31日 | O12: 否 | P12: 输电管理二所 | Q12: 吴达 | R12: 甘永叶 | S12: 天河中心 | T12: 48 | U12: 2023-03-17 08:48:00 | V12: 2023-03-17 11:57:00 | W12: 48 | X12: 48 | Y12: 1 | Z12: 1 | AB12: JH030120230111-010828 | AC12: 已完成 | AH12: =IF(N12="2023年01月","2023年01月31日",IF(N12="2023年02月","2023年02月28日",IF(N12="2023年3月","2023年3月31日",IF(N12="2023年4月","2023年4月30日",IF(N12="2023年5月","2023年5月31日",IF(N12="2023年6月","2023年6月30日",IF(N12="2023年7月","2023年7月31日",IF(N12="2023年8月","2023年8月31日",IF(N12="2023年9月","2023年9月30日",IF(N12="2023年10月","2023年10月31日",IF(N12="2023年11月","2023年11月30日",IF(N12="2023年12月","2023年12月31日")))))))))))) -> FALSE
A13: 10 | B13: 预试 | C13: 考核 | D13: 500kV | E13: 关键 | F13: 从科乙线 | G13: 导、地线连接位置 | H13: 接续管或预绞丝：#04-#05（B相）、#07-#08（A相）、#08-#09（地线）、#08-#09（B相）、#11-#12（B相）、#11-#12（C相）、#12-#13（地线）、#15-#16（A相）、#15-#16（B相）、#15-#16（C相）、#17-#18（B相）、#17-#18（地线）、#18-#19（A相）、#18-#19（A相）、#19-#20（B相）、#19-#20（C相）、#23-#24（A相）、#27-#28（B相）、#27-#28（C相）、#33-#34（A相）、#33-#34（C相）、#37-#38（B相）、#41-#42（C相）、#44-#45（A相）、#44-#45（B相）、#44-#45（C相）、#44-#45（地线）、#46-#47（A相）、#48-#49（地线）、#49-#50（B相）、#49-#50（C相）、#50-#51（A相）、#50-#51（B相）、#50-#51（C相）、#51-#52（A相）、#54-#55（B相）、#54-#55（C相）、#56-#57（A相）、#57-#58（A相）、#59-#60（B相）、#59-#60（C相）、#65-#66（B相）、#68-#69（A相）、#68-#69（B相）、#70-#71（A相）、#71-#72（A相）、#73-#74（B相）、#75-#76（C相 ）、#76-#77（A相 ）、#77-#78（地线）、#80-#81（B相）、#87-#88（B相）、#88-#89（C相）、#96-#97（A相）、#100-#101（B相）、#100-#101（C相）、#113-#114（B相） | L13: 57 | M13: 44986 | N13: 2023年3月31日 | O13: 否 | P13: 输电管理二所 | Q13: 吴达 | R13: 甘永叶 | S13: 天河中心 | T13: 57 | U13: 2023-03-17 08:48:00 | V13: 2023-03-17 11:57:00 | W13: 57 | X13: 57 | Y13: 1 | Z13: 1 | AB13: JH030120230111-010828 | AC13: 已完成 | AH13: =IF(N13="2023年01月","2023年01月31日",IF(N13="2023年02月","2023年02月28日",IF(N13="2023年3月","2023年3月31日",IF(N13="2023年4月","2023年4月30日",IF(N13="2023年5月","2023年5月31日",IF(N13="2023年6月","2023年6月30日",IF(N13="2023年7月","2023年7月31日",IF(N13="2023年8月","2023年8月31日",IF(N13="2023年9月","2023年9月30日",IF(N13="2023年10月","2023年10月31日",IF(N13="2023年11月","2023年11月30日",IF(N13="2023年12月","2023年12月31日")))))))))))) -> FALSE
A14: 11 | B14: 预试 | C14: 考核 | D14: 500kV | E14: 关键 | F14: 从科乙线 | G14: 机巡区复合绝缘子 | H14: #01、#02、#03、#04、#05、#06、#07、#08、#09、#10、#11、#12、#13、#14、#15、#16、#17、#18、#19、#20、#21、#22、#24、#25、#26、#27、#28、#30、#31、#32、#33、#34、#35、#36、#37、#38、#39、#40、#41、#42、#43、#44、#45、#46、#47、#48、#49、#50、#51、#52、#53、#54、#55、#56、#57、#58、#59、#60、#61、#62、#63、#64、#65、#66、#67、#68、#69、#70、#71、#72、#73、#74、#75、#76、#77、#78、#79、#80、#81、#82、#83、#84、#85、#86、#87、#88、#89、#90、#91、#92、#96、#97、#98、#99、#100、#101、#102、#103、#104、#105、#106、#107、#108、#109、#110、#111、#112、#113、#115 | I14: 109 | J14: 442 | K14: 9 | M14: 45170 | N14: 2023年9月30日 | O14: 否 | P14: 输电管理二所 | Q14: 吴达 | R14: 甘永叶 | S14: 天河中心 | T14: 442 | U14: 2023-09-07 08:46:00 | V14: 2023-09-07 12:07:00 | W14: 442 | X14: 442 | Y14: 1 | Z14: 1 | AB14: JH030120230111-014592 | AC14: 已完成 | AH14: =IF(N14="2023年01月","2023年01月31日",IF(N14="2023年02月","2023年02月28日",IF(N14="2023年3月","2023年3月31日",IF(N14="2023年4月","2023年4月30日",IF(N14="2023年5月","2023年5月31日",IF(N14="2023年6月","2023年6月30日",IF(N14="2023年7月","2023年7月31日",IF(N14="2023年8月","2023年8月31日",IF(N14="2023年9月","2023年9月30日",IF(N14="2023年10月","2023年10月31日",IF(N14="2023年11月","2023年11月30日",IF(N14="2023年12月","2023年12月31日")))))))))))) -> FALSE
A15: 12 | B15: 预试 | C15: 考核 | D15: 500kV | E15: 关键 | F15: 从科乙线 | G15: 机巡区瓷质绝缘子 | H15: #12、#20、#23、#25、#27、#28、#29、#31、#32 | I15: 9 | J15: 108 | K15: 9 | M15: 45170 | N15: 2023年9月30日 | O15: 否 | P15: 输电管理二所 | Q15: 吴达 | R15: 甘永叶 | S15: 天河中心 | T15: 108 | U15: 2023-09-07 08:46:00 | V15: 2023-09-07 12:07:00 | W15: 108 | X15: 108 | Y15: 1 | Z15: 1 | AB15: JH030120230111-014592 | AC15: 已完成 | AH15: =IF(N15="2023年01月","2023年01月31日",IF(N15="2023年02月","2023年02月28日",IF(N15="2023年3月","2023年3月31日",IF(N15="2023年4月","2023年4月30日",IF(N15="2023年5月","2023年5月31日",IF(N15="2023年6月","2023年6月30日",IF(N15="2023年7月","2023年7月31日",IF(N15="2023年8月","2023年8月31日",IF(N15="2023年9月","2023年9月30日",IF(N15="2023年10月","2023年10月31日",IF(N15="2023年11月","2023年11月30日",IF(N15="2023年12月","2023年12月31日")))))))))))) -> FALSE
A16: 13 | B16: 预试 | C16: 考核 | D16: 500kV | E16: 关键 | F16: 从科乙线 | G16: 导、地线连接位置 | H16: 耐张线夹： #01、#05、#09、#10、#12、#20、#23、#25、#27、#28、#29、#31、#32、#34、#35、#37、#38、#40、#44、#49、#52、#57、#63、#66、#69、#71、#78、#82、#83、#85、#87、#89、#91、#95、#98、#100、#101、#103、#105、#106、#107、#110、#111、#113、#114、#116、#117、#118 | L16: 48 | M16: 45170 | N16: 2023年9月30日 | O16: 否 | P16: 输电管理二所 | Q16: 吴达 | R16: 甘永叶 | S16: 天河中心 | T16: 48 | U16: 2023-09-07 08:46:00 | V16: 2023-09-07 12:07:00 | W16: 48 | X16: 48 | Y16: 1 | Z16: 1 | AB16: JH030120230111-014592 | AC16: 已完成 | AH16: =IF(N16="2023年01月","2023年01月31日",IF(N16="2023年02月","2023年02月28日",IF(N16="2023年3月","2023年3月31日",IF(N16="2023年4月","2023年4月30日",IF(N16="2023年5月","2023年5月31日",IF(N16="2023年6月","2023年6月30日",IF(N16="2023年7月","2023年7月31日",IF(N16="2023年8月","2023年8月31日",IF(N16="2023年9月","2023年9月30日",IF(N16="2023年10月","2023年10月31日",IF(N16="2023年11月","2023年11月30日",IF(N16="2023年12月","2023年12月31日")))))))))))) -> FALSE
A17: 14 | B17: 预试 | C17: 考核 | D17: 500kV | E17: 关键 | F17: 从科乙线 | G17: 导、地线连接位置 | H17: 接续管或预绞丝：#04-#05（B相）、#07-#08（A相）、#08-#09（地线）、#08-#09（B相）、#11-#12（B相）、#11-#12（C相）、#12-#13（地线）、#15-#16（A相）、#15-#16（B相）、#15-#16（C相）、#17-#18（B相）、#17-#18（地线）、#18-#19（A相）、#18-#19（A相）、#19-#20（B相）、#19-#20（C相）、#23-#24（A相）、#27-#28（B相）、#27-#28（C相）、#33-#34（A相）、#33-#34（C相）、#37-#38（B相）、#41-#42（C相）、#44-#45（A相）、#44-#45（B相）、#44-#45（C相）、#44-#45（地线）、#46-#47（A相）、#48-#49（地线）、#49-#50（B相）、#49-#50（C相）、#50-#51（A相）、#50-#51（B相）、#50-#51（C相）、#51-#52（A相）、#54-#55（B相）、#54-#55（C相）、#56-#57（A相）、#57-#58（A相）、#59-#60（B相）、#59-#60（C相）、#65-#66（B相）、#68-#69（A相）、#68-#69（B相）、#70-#71（A相）、#71-#72（A相）、#73-#74（B相）、#75-#76（C相 ）、#76-#77（A相 ）、#77-#78（地线）、#80-#81（B相）、#87-#88（B相）、#88-#89（C相）、#96-#97（A相）、#100-#101（B相）、#100-#101（C相）、#113-#114（B相） | L17: 57 | M17: 45170 | N17: 2023年9月30日 | O17: 否 | P17: 输电管理二所 | Q17: 吴达 | R17: 甘永叶 | S17: 天河中心 | T17: 57 | U17: 2023-09-07 08:46:00 | V17: 2023-09-07 12:07:00 | W17: 57 | X17: 57 | Y17: 1 | Z17: 1 | AB17: JH030120230111-014592 | AC17: 已完成 | AH17: =IF(N17="2023年01月","2023年01月31日",IF(N17="2023年02月","2023年02月28日",IF(N17="2023年3月","2023年3月31日",IF(N17="2023年4月","2023年4月30日",IF(N17="2023年5月","2023年5月31日",IF(N17="2023年6月","2023年6月30日",IF(N17="2023年7月","2023年7月31日",IF(N17="2023年8月","2023年8月31日",IF(N17="2023年9月","2023年9月30日",IF(N17="2023年10月","2023年10月31日",IF(N17="2023年11月","2023年11月30日",IF(N17="2023年12月","2023年12月31日")))))))))))) -> FALSE
A18: 15 | B18: 预试 | C18: 考核 | D18: 500kV | E18: 关键 | F18: 科木甲线 | G18: 机巡区复合绝缘子 | H18: #02、#04、#06、#07、#08、#09、#10、#11、#12、#13、#14、#15、#16、#17、#18、#19、#20、#21、#22、#23、#24、#25、#26、#27 | I18: 24 | J18: 102 | K18: 9 | M18: 44986 | N18: 2023年3月31日 | O18: 否 | P18: 输电管理二所 | Q18: 吴达 | R18: 甘永叶 | S18: 天河中心 | T18: 102 | U18: 45014 | V18: 45014 | W18: 102 | X18: 102 | Y18: 1 | Z18: 1 | AA18: 已完成（外委直升机精巡） | AB18: JH030120230113-006784、JH030120230113-006781、JH030120230113-006770、JH030120230113-006768、JH030120230113-006788 | AC18: 已完成 | AH18: =IF(N18="2023年01月","2023年01月31日",IF(N18="2023年02月","2023年02月28日",IF(N18="2023年3月","2023年3月31日",IF(N18="2023年4月","2023年4月30日",IF(N18="2023年5月","2023年5月31日",IF(N18="2023年6月","2023年6月30日",IF(N18="2023年7月","2023年7月31日",IF(N18="2023年8月","2023年8月31日",IF(N18="2023年9月","2023年9月30日",IF(N18="2023年10月","2023年10月31日",IF(N18="2023年11月","2023年11月30日",IF(N18="2023年12月","2023年12月31日")))))))))))) -> FALSE
A19: 16 | B19: 预试 | C19: 考核 | D19: 500kV | E19: 关键 | F19: 科木甲线 | G19: 导、地线连接位置 | H19: 耐张线夹：#01、#03、#05、#07、#09、#11、#14、#16、#19、#23、#24、#28、#29 | L19: 13 | M19: 44986 | N19: 2023年3月31日 | O19: 否 | P19: 输电管理二所 | Q19: 吴达 | R19: 甘永叶 | S19: 天河中心 | T19: 13 | U19: 45014 | V19: 45014 | W19: 13 | X19: 13 | Y19: 1 | Z19: 1 | AA19: 已完成（外委直升机精巡） | AB19: JH030120230113-006784、JH030120230113-006781、JH030120230113-006770、JH030120230113-006768、JH030120230113-006788 | AC19: 已完成 | AH19: =IF(N19="2023年01月","2023年01月31日",IF(N19="2023年02月","2023年02月28日",IF(N19="2023年3月","2023年3月31日",IF(N19="2023年4月","2023年4月30日",IF(N19="2023年5月","2023年5月31日",IF(N19="2023年6月","2023年6月30日",IF(N19="2023年7月","2023年7月31日",IF(N19="2023年8月","2023年8月31日",IF(N19="2023年9月","2023年9月30日",IF(N19="2023年10月","2023年10月31日",IF(N19="2023年11月","2023年11月30日",IF(N19="2023年12月","2023年12月31日")))))))))))) -> FALSE
A20: 17 | B20: 预试 | C20: 考核 | D20: 500kV | E20: 关键 | F20: 科木甲线 | G20: 导、地线连接位置 | H20: 接续管或预绞丝：#05-#06（A相）、#05-#06（C相）、#18-#19（B相）、#20-#21（A相）、#20-#21（C相）、#27-#28（A相）、#27-#28（B相）、#27-#28（C相） | L20: 8 | M20: 44986 | N20: 2023年3月31日 | O20: 否 | P20: 输电管理二所 | Q20: 吴达 | R20: 甘永叶 | S20: 天河中心 | T20: 8 | U20: 45014 | V20: 45014 | W20: 8 | X20: 8 | Y20: 1 | Z20: 1 | AA20: 已完成（外委直升机精巡） | AB20: JH030120230113-006784、JH030120230113-006781、JH030120230113-006770、JH030120230113-006768、JH030120230113-006788 | AC20: 已完成 | AH20: =IF(N20="2023年01月","2023年01月31日",IF(N20="2023年02月","2023年02月28日",IF(N20="2023年3月","2023年3月31日",IF(N20="2023年4月","2023年4月30日",IF(N20="2023年5月","2023年5月31日",IF(N20="2023年6月","2023年6月30日",IF(N20="2023年7月","2023年7月31日",IF(N20="2023年8月","2023年8月31日",IF(N20="2023年9月","2023年9月30日",IF(N20="2023年10月","2023年10月31日",IF(N20="2023年11月","2023年11月30日",IF(N20="2023年12月","2023年12月31日")))))))))))) -> FALSE
A21: 18 | B21: 预试 | C21: 考核 | D21: 500kV | E21: 关键 | F21: 科木甲线 | G21: 机巡区复合绝缘子 | H21: #02、#04、#06、#07、#08、#09、#10、#11、#12、#13、#14、#15、#16、#17、#18、#19、#20、#21、#22、#23、#24、#25、#26、#27 | I21: 24 | J21: 102 | K21: 9 | M21: 45170 | N21: 2023年9月30日 | O21: 否 | P21: 输电管理二所 | Q21: 吴达 | R21: 甘永叶 | S21: 天河中心 | T21: 102 | U21: 2023-09-15 08:57:00 | V21: 2023-09-15 12:06:00 | W21: 102 | X21: 102 | Y21: 1 | Z21: 1 | AB21: JH030120230111-014596 | AC21: 已完成 | AH21: =IF(N21="2023年01月","2023年01月31日",IF(N21="2023年02月","2023年02月28日",IF(N21="2023年3月","2023年3月31日",IF(N21="2023年4月","2023年4月30日",IF(N21="2023年5月","2023年5月31日",IF(N21="2023年6月","2023年6月30日",IF(N21="2023年7月","2023年7月31日",IF(N21="2023年8月","2023年8月31日",IF(N21="2023年9月","2023年9月30日",IF(N21="2023年10月","2023年10月31日",IF(N21="2023年11月","2023年11月30日",IF(N21="2023年12月","2023年12月31日")))))))))))) -> FALSE
A22: 19 | B22: 预试 | C22: 考核 | D22: 500kV | E22: 关键 | F22: 科木甲线 | G22: 导、地线连接位置 | H22: 耐张线夹：#01、#03、#05、#07、#09、#11、#14、#16、#19、#23、#24、#28、#29 | L22: 13 | M22: 45170 | N22: 2023年9月30日 | O22: 否 | P22: 输电管理二所 | Q22: 吴达 | R22: 甘永叶 | S22: 天河中心 | T22: 13 | U22: 2023-09-15 08:57:00 | V22: 2023-09-15 12:06:00 | W22: 13 | X22: 13 | Y22: 1 | Z22: 1 | AB22: JH030120230111-014596 | AC22: 已完成 | AH22: =IF(N22="2023年01月","2023年01月31日",IF(N22="2023年02月","2023年02月28日",IF(N22="2023年3月","2023年3月31日",IF(N22="2023年4月","2023年4月30日",IF(N22="2023年5月","2023年5月31日",IF(N22="2023年6月","2023年6月30日",IF(N22="2023年7月","2023年7月31日",IF(N22="2023年8月","2023年8月31日",IF(N22="2023年9月","2023年9月30日",IF(N22="2023年10月","2023年10月31日",IF(N22="2023年11月","2023年11月30日",IF(N22="2023年12月","2023年12月31日")))))))))))) -> FALSE
A23: 20 | B23: 预试 | C23: 考核 | D23: 500kV | E23: 关键 | F23: 科木甲线 | G23: 导、地线连接位置 | H23: 接续管或预绞丝：#05-#06（A相）、#05-#06（C相）、#18-#19（B相）、#20-#21（A相）、#20-#21（C相）、#27-#28（A相）、#27-#28（B相）、#27-#28（C相） | L23: 8 | M23: 45170 | N23: 2023年9月30日 | O23: 否 | P23: 输电管理二所 | Q23: 吴达 | R23: 甘永叶 | S23: 天河中心 | T23: 8 | U23: 2023-09-15 08:57:00 | V23: 2023-09-15 12:06:00 | W23: 8 | X23: 8 | Y23: 1 | Z23: 1 | AB23: JH030120230111-014596 | AC23: 已完成 | AH23: =IF(N23="2023年01月","2023年01月31日",IF(N23="2023年02月","2023年02月28日",IF(N23="2023年3月","2023年3月31日",IF(N23="2023年4月","2023年4月30日",IF(N23="2023年5月","2023年5月31日",IF(N23="2023年6月","2023年6月30日",IF(N23="2023年7月","2023年7月31日",IF(N23="2023年8月","2023年8月31日",IF(N23="2023年9月","2023年9月30日",IF(N23="2023年10月","2023年10月31日",IF(N23="2023年11月","2023年11月30日",IF(N23="2023年12月","2023年12月31日")))))))))))) -> FALSE
A24: 21 | B24: 预试 | C24: 考核 | D24: 500kV | E24: 关键 | F24: 科木乙线 | G24: 机巡区复合绝缘子 | H24: #02、#04、#06、#07、#08、#09、#10、#11、#12、#13、#14、#15、#16、#17、#18、#19、#20、#21、#22、#23、#24、#25、#26、#27 | I24: 24 | J24: 108 | K24: 9 | M24: 44986 | N24: 2023年3月31日 | O24: 否 | P24: 输电管理二所 | Q24: 吴达 | R24: 甘永叶 | S24: 天河中心 | T24: 108 | U24: 45014 | V24: 45014 | W24: 108 | X24: 108 | Y24: 1 | Z24: 1 | AA24: 已完成（外委直升机精巡） | AB24: JH030120230113-006784、JH030120230113-006781、JH030120230113-006770、JH030120230113-006768、JH030120230113-006788 | AC24: 已完成 | AH24: =IF(N24="2023年01月","2023年01月31日",IF(N24="2023年02月","2023年02月28日",IF(N24="2023年3月","2023年3月31日",IF(N24="2023年4月","2023年4月30日",IF(N24="2023年5月","2023年5月31日",IF(N24="2023年6月","2023年6月30日",IF(N24="2023年7月","2023年7月31日",IF(N24="2023年8月","2023年8月31日",IF(N24="2023年9月","2023年9月30日",IF(N24="2023年10月","2023年10月31日",IF(N24="2023年11月","2023年11月30日",IF(N24="2023年12月","2023年12月31日")))))))))))) -> FALSE
A25: 22 | B25: 预试 | C25: 考核 | D25: 500kV | E25: 关键 | F25: 科木乙线 | G25: 导、地线连接位置 | H25: 耐张线夹：#01、#03、#05、#07、#09、#11、#14、#16、#19、#23、#24、#28、#29 | L25: 13 | M25: 44986 | N25: 2023年3月31日 | O25: 否 | P25: 输电管理二所 | Q25: 吴达 | R25: 甘永叶 | S25: 天河中心 | T25: 13 | U25: 45014 | V25: 45014 | W25: 13 | X25: 13 | Y25: 1 | Z25: 1 | AA25: 已完成（外委直升机精巡） | AB25: JH030120230113-006784、JH030120230113-006781、JH030120230113-006770、JH030120230113-006768、JH030120230113-006788 | AC25: 已完成 | AH25: =IF(N25="2023年01月","2023年01月31日",IF(N25="2023年02月","2023年02月28日",IF(N25="2023年3月","2023年3月31日",IF(N25="2023年4月","2023年4月30日",IF(N25="2023年5月","2023年5月31日",IF(N25="2023年6月","2023年6月30日",IF(N25="2023年7月","2023年7月31日",IF(N25="2023年8月","2023年8月31日",IF(N25="2023年9月","2023年9月30日",IF(N25="2023年10月","2023年10月31日",IF(N25="2023年11月","2023年11月30日",IF(N25="2023年12月","2023年12月31日")))))))))))) -> FALSE
A26: 23 | B26: 预试 | C26: 考核 | D26: 500kV | E26: 关键 | F26: 科木乙线 | G26: 导、地线连接位置 | H26: 接续管或预绞丝：#14-#15（地线）、#15-#16（地线）、#18-#19（A相 ）、#19-#20（C相）、#19-#20（B相） | L26: 5 | M26: 44986 | N26: 2023年3月31日 | O26: 否 | P26: 输电管理二所 | Q26: 吴达 | R26: 甘永叶 | S26: 天河中心 | T26: 5 | U26: 45014 | V26: 45014 | W26: 5 | X26: 5 | Y26: 1 | Z26: 1 | AA26: 已完成（外委直升机精巡） | AB26: JH030120230113-006784、JH030120230113-006781、JH030120230113-006770、JH030120230113-006768、JH030120230113-006788 | AC26: 已完成 | AH26: =IF(N26="2023年01月","2023年01月31日",IF(N26="2023年02月","2023年02月28日",IF(N26="2023年3月","2023年3月31日",IF(N26="2023年4月","2023年4月30日",IF(N26="2023年5月","2023年5月31日",IF(N26="2023年6月","2023年6月30日",IF(N26="2023年7月","2023年7月31日",IF(N26="2023年8月","2023年8月31日",IF(N26="2023年9月","2023年9月30日",IF(N26="2023年10月","2023年10月31日",IF(N26="2023年11月","2023年11月30日",IF(N26="2023年12月","2023年12月31日")))))))))))) -> FALSE
A27: 24 | B27: 预试 | C27: 考核 | D27: 500kV | E27: 关键 | F27: 科木乙线 | G27: 机巡区复合绝缘子 | H27: #02、#04、#06、#07、#08、#09、#10、#11、#12、#13、#14、#15、#16、#17、#18、#19、#20、#21、#22、#23、#24、#25、#26、#27 | I27: 24 | J27: 108 | K27: 9 | M27: 45170 | N27: 2023年9月30日 | O27: 否 | P27: 输电管理二所 | Q27: 吴达 | R27: 甘永叶 | S27: 天河中心 | T27: 108 | U27: 2023-09-15 08:57:00 | V27: 2023-09-15 12:06:00 | W27: 108 | X27: 108 | Y27: 1 | Z27: 1 | AB27: JH030120230111-014596 | AC27: 已完成 | AH27: =IF(N27="2023年01月","2023年01月31日",IF(N27="2023年02月","2023年02月28日",IF(N27="2023年3月","2023年3月31日",IF(N27="2023年4月","2023年4月30日",IF(N27="2023年5月","2023年5月31日",IF(N27="2023年6月","2023年6月30日",IF(N27="2023年7月","2023年7月31日",IF(N27="2023年8月","2023年8月31日",IF(N27="2023年9月","2023年9月30日",IF(N27="2023年10月","2023年10月31日",IF(N27="2023年11月","2023年11月30日",IF(N27="2023年12月","2023年12月31日")))))))))))) -> FALSE
A28: 25 | B28: 预试 | C28: 考核 | D28: 500kV | E28: 关键 | F28: 科木乙线 | G28: 导、地线连接位置 | H28: 耐张线夹：#01、#03、#05、#07、#09、#11、#14、#16、#19、#23、#24、#28、#29 | L28: 13 | M28: 45170 | N28: 2023年9月30日 | O28: 否 | P28: 输电管理二所 | Q28: 吴达 | R28: 甘永叶 | S28: 天河中心 | T28: 13 | U28: 2023-09-15 08:57:00 | V28: 2023-09-15 12:06:00 | W28: 13 | X28: 13 | Y28: 1 | Z28: 1 | AB28: JH030120230111-014596 | AC28: 已完成 | AH28: =IF(N28="2023年01月","2023年01月31日",IF(N28="2023年02月","2023年02月28日",IF(N28="2023年3月","2023年3月31日",IF(N28="2023年4月","2023年4月30日",IF(N28="2023年5月","2023年5月31日",IF(N28="2023年6月","2023年6月30日",IF(N28="2023年7月","2023年7月31日",IF(N28="2023年8月","2023年8月31日",IF(N28="2023年9月","2023年9月30日",IF(N28="2023年10月","2023年10月31日",IF(N28="2023年11月","2023年11月30日",IF(N28="2023年12月","2023年12月31日")))))))))))) -> FALSE
A29: 26 | B29: 预试 | C29: 考核 | D29: 500kV | E29: 关键 | F29: 科木乙线 | G29: 导、地线连接位置 | H29: 接续管或预绞丝：#14-#15（地线）、#15-#16（地线）、#18-#19（A相 ）、#19-#20（C相）、#19-#20（B相） | L29: 5 | M29: 45170 | N29: 2023年9月30日 | O29: 否 | P29: 输电管理二所 | Q29: 吴达 | R29: 甘永叶 | S29: 天河中心 | T29: 5 | U29: 2023-09-15 08:57:00 | V29: 2023-09-15 12:06:00 | W29: 5 | X29: 5 | Y29: 1 | Z29: 1 | AB29: JH030120230111-014596 | AC29: 已完成 | AH29: =IF(N29="2023年01月","2023年01月31日",IF(N29="2023年02月","2023年02月28日",IF(N29="2023年3月","2023年3月31日",IF(N29="2023年4月","2023年4月30日",IF(N29="2023年5月","2023年5月31日",IF(N29="2023年6月","2023年6月30日",IF(N29="2023年7月","2023年7月31日",IF(N29="2023年8月","2023年8月31日",IF(N29="2023年9月","2023年9月30日",IF(N29="2023年10月","2023年10月31日",IF(N29="2023年11月","2023年11月30日",IF(N29="2023年12月","2023年12月31日")))))))))))) -> FALSE
A30: 27 | B30: 预试 | C30: 考核 | D30: 500kV | E30: 关键 | F30: 从木丙线 | G30: 机巡区复合绝缘子 | H30: #1、#2、#3、#4、#5、#6、#7、#8、#9、#10、#11、#12、#13、#14、#15、#16、#17、#18、#19、#20、#21、#22、#23、#24、#25、#26、#27、#28、#29、#30、#31、#32、#33、#34、#35、#36、#37、#38、#39、#40、#41、#42、#43、#44、#45、#46、#47、#48、#49、#50、#51、#52、#53、#54、#55、#56、#57、#58、#59、#60、#61、#62、#63、#64、#65、#66、#67、#68、#69、#70、#71、#72、#73、#74、#75、#76、#77、#78、#79、#80、#81、#82、#83、#84、#85、#86、#87、#88、#89、#90、#91、#92、#93、#94、#95、#96、#97、#98、#99、#100、#101、#102、#103、#104、#105、#106、#107、#108、#109、#110、#111、#112、#113、#114、#115、#116、#117、#118、#119、#120、#121、#122、#123、#124、#125、#126、#127、#128、#129、#130、#131、#132、#133、#134、#135 | I30: 135 | J30: 624 | K30: 9 | M30: 44986 | N30: 2023年3月31日 | O30: 否 | P30: 输电管理二所 | Q30: 吴达 | R30: 朱常镇 | S30: 天河中心 | T30: 624 | U30: 2023-03-17 08:48:00 | V30: 2023-03-17 11:57:00 | W30: 624 | X30: 624 | Y30: 1 | Z30: 1 | AB30: JH030120230111-010828 | AC30: 已完成 | AH30: =IF(N30="2023年01月","2023年01月31日",IF(N30="2023年02月","2023年02月28日",IF(N30="2023年3月","2023年3月31日",IF(N30="2023年4月","2023年4月30日",IF(N30="2023年5月","2023年5月31日",IF(N30="2023年6月","2023年6月30日",IF(N30="2023年7月","2023年7月31日",IF(N30="2023年8月","2023年8月31日",IF(N30="2023年9月","2023年9月30日",IF(N30="2023年10月","2023年10月31日",IF(N30="2023年11月","2023年11月30日",IF(N30="2023年12月","2023年12月31日")))))))))))) -> FALSE
A31: 28 | B31: 预试 | C31: 考核 | D31: 500kV | E31: 关键 | F31: 从木丙线 | G31: 导、地线连接位置 | H31: 耐张线夹：#1、#3、#8、#10、#11、#13、#18、#22、#24、#25、#29、#31、#33、#34、#36、#37、#39、#41、#43、#47、#50、#55、#61、#64、#66、#68、#70、#78、#82、#85、#87、#89、#91、#94、#97、#100、#101、#103、#105、#106、#107、#110、#111、#112、#116、#117、#119、#122、#124、#127、#132、#133、#136、#137 | L31: 58 | M31: 44986 | N31: 2023年3月31日 | O31: 否 | P31: 输电管理二所 | Q31: 吴达 | R31: 朱常镇 | S31: 天河中心 | T31: 58 | U31: 2023-03-17 08:48:00 | V31: 2023-03-17 11:57:00 | W31: 58 | X31: 58 | Y31: 1 | Z31: 1 | AB31: JH030120230111-010828 | AC31: 已完成 | AH31: =IF(N31="2023年01月","2023年01月31日",IF(N31="2023年02月","2023年02月28日",IF(N31="2023年3月","2023年3月31日",IF(N31="2023年4月","2023年4月30日",IF(N31="2023年5月","2023年5月31日",IF(N31="2023年6月","2023年6月30日",IF(N31="2023年7月","2023年7月31日",IF(N31="2023年8月","2023年8月31日",IF(N31="2023年9月","2023年9月30日",IF(N31="2023年10月","2023年10月31日",IF(N31="2023年11月","2023年11月30日",IF(N31="2023年12月","2023年12月31日")))))))))))) -> FALSE
A32: 29 | B32: 预试 | C32: 考核 | D32: 500kV | E32: 关键 | F32: 从木丙线 | G32: 导、地线连接位置 | H32: 接续管或预绞丝：#06-#07（地线）、#06-#07（A相）、#06-#07（B相）、#06-#07（C相 ）、#15-#16（A相 ）、#15-#16（B相 ）、#20-21（A相 ）、#20-21（B相 ）、#20-21（C相 ）、#28-29（A相 ）、#28-29（B相 ）、#29-#30（地线）、#38-39（B相 ）、#40-41（C相 ）、#43-#44（地线）、#43-#44（A相 ）、#43-#44（B相）、#43-#44（C相）、#47-#48（A相）、#47-#48（B相）、#47-#48（C相）、#50-#51（C相）、#52-#53（A相）、#52-#53（B相）、#52-#53（C相）、#53-#54（C相）、#58-#59（地线）、#58-#59（A相）、#58-#59（B相）、#58-#59（C相 ）、#63-#64（C相 ）、#65-#66（B相 ）、#69-#70（B相 ）、#71-#72（A相 ）、#72-#73（C相 ）、#73-#74（C相 ）、#75-#76（B相 ）、#77-#78（地线）、#77-#78（A相 ）、#77-#78（B相）、#79-#80（C相）、#80-#81（地线）、#81-#82（B相）、#91-#92（C相）、#93-#94（B相）、#94-#95（A相）、#99-#100（A相）、#99-#100（B相）、#99-#100（C相）、#127-#128（地线）、#127-#128（C相）、#127-#128（B相）、#127-#128（A相 ）、#134-#135（A相 ） | L32: 54 | M32: 44986 | N32: 2023年3月31日 | O32: 否 | P32: 输电管理二所 | Q32: 吴达 | R32: 朱常镇 | S32: 天河中心 | T32: 54 | U32: 2023-03-17 08:48:00 | V32: 2023-03-17 11:57:00 | W32: 54 | X32: 54 | Y32: 1 | Z32: 1 | AB32: JH030120230111-010828 | AC32: 已完成 | AH32: =IF(N32="2023年01月","2023年01月31日",IF(N32="2023年02月","2023年02月28日",IF(N32="2023年3月","2023年3月31日",IF(N32="2023年4月","2023年4月30日",IF(N32="2023年5月","2023年5月31日",IF(N32="2023年6月","2023年6月30日",IF(N32="2023年7月","2023年7月31日",IF(N32="2023年8月","2023年8月31日",IF(N32="2023年9月","2023年9月30日",IF(N32="2023年10月","2023年10月31日",IF(N32="2023年11月","2023年11月30日",IF(N32="2023年12月","2023年12月31日")))))))))))) -> FALSE
A33: 30 | B33: 预试 | C33: 考核 | D33: 500kV | E33: 关键 | F33: 从木丙线 | G33: 机巡区复合绝缘子 | H33: #1、#2、#3、#4、#5、#6、#7、#8、#9、#10、#11、#12、#13、#14、#15、#16、#17、#18、#19、#20、#21、#22、#23、#24、#25、#26、#27、#28、#29、#30、#31、#32、#33、#34、#35、#36、#37、#38、#39、#40、#41、#42、#43、#44、#45、#46、#47、#48、#49、#50、#51、#52、#53、#54、#55、#56、#57、#58、#59、#60、#61、#62、#63、#64、#65、#66、#67、#68、#69、#70、#71、#72、#73、#74、#75、#76、#77、#78、#79、#80、#81、#82、#83、#84、#85、#86、#87、#88、#89、#90、#91、#92、#93、#94、#95、#96、#97、#98、#99、#100、#101、#102、#103、#104、#105、#106、#107、#108、#109、#110、#111、#112、#113、#114、#115、#116、#117、#118、#119、#120、#121、#122、#123、#124、#125、#126、#127、#128、#129、#130、#131、#132、#133、#134、#135 | I33: 135 | J33: 624 | K33: 9 | M33: 45170 | N33: 2023年9月30日 | O33: 否 | P33: 输电管理二所 | Q33: 吴达 | R33: 朱常镇 | S33: 天河中心 | T33: 624 | U33: 2023-09-07 08:46:00 | V33: 2023-09-07 12:07:00 | W33: 624 | X33: 624 | Y33: 1 | Z33: 1 | AB33: JH030120230111-014592 | AC33: 已完成 | AH33: =IF(N33="2023年01月","2023年01月31日",IF(N33="2023年02月","2023年02月28日",IF(N33="2023年3月","2023年3月31日",IF(N33="2023年4月","2023年4月30日",IF(N33="2023年5月","2023年5月31日",IF(N33="2023年6月","2023年6月30日",IF(N33="2023年7月","2023年7月31日",IF(N33="2023年8月","2023年8月31日",IF(N33="2023年9月","2023年9月30日",IF(N33="2023年10月","2023年10月31日",IF(N33="2023年11月","2023年11月30日",IF(N33="2023年12月","2023年12月31日")))))))))))) -> FALSE
A34: 31 | B34: 预试 | C34: 考核 | D34: 500kV | E34: 关键 | F34: 从木丙线 | G34: 导、地线连接位置 | H34: 耐张线夹：#1、#3、#8、#10、#11、#13、#18、#22、#24、#25、#29、#31、#33、#34、#36、#37、#39、#41、#43、#47、#50、#55、#61、#64、#66、#68、#70、#78、#82、#85、#87、#89、#91、#94、#97、#100、#101、#103、#105、#106、#107、#110、#111、#112、#116、#117、#119、#122、#124、#127、#132、#133、#136、#137 | L34: 58 | M34: 45170 | N34: 2023年9月30日 | O34: 否 | P34: 输电管理二所 | Q34: 吴达 | R34: 朱常镇 | S34: 天河中心 | T34: 58 | U34: 2023-09-07 08:46:00 | V34: 2023-09-07 12:07:00 | W34: 58 | X34: 58 | Y34: 1 | Z34: 1 | AB34: JH030120230111-014592 | AC34: 已完成 | AH34: =IF(N34="2023年01月","2023年01月31日",IF(N34="2023年02月","2023年02月28日",IF(N34="2023年3月","2023年3月31日",IF(N34="2023年4月","2023年4月30日",IF(N34="2023年5月","2023年5月31日",IF(N34="2023年6月","2023年6月30日",IF(N34="2023年7月","2023年7月31日",IF(N34="2023年8月","2023年8月31日",IF(N34="2023年9月","2023年9月30日",IF(N34="2023年10月","2023年10月31日",IF(N34="2023年11月","2023年11月30日",IF(N34="2023年12月","2023年12月31日")))))))))))) -> FALSE
A35: 32 | B35: 预试 | C35: 考核 | D35: 500kV | E35: 关键 | F35: 从木丙线 | G35: 导、地线连接位置 | H35: 接续管或预绞丝：#06-#07（地线）、#06-#07（A相）、#06-#07（B相）、#06-#07（C相 ）、#15-#16（A相 ）、#15-#16（B相 ）、#20-21（A相 ）、#20-21（B相 ）、#20-21（C相 ）、#28-29（A相 ）、#28-29（B相 ）、#29-#30（地线）、#38-39（B相 ）、#40-41（C相 ）、#43-#44（地线）、#43-#44（A相 ）、#43-#44（B相）、#43-#44（C相）、#47-#48（A相）、#47-#48（B相）、#47-#48（C相）、#50-#51（C相）、#52-#53（A相）、#52-#53（B相）、#52-#53（C相）、#53-#54（C相）、#58-#59（地线）、#58-#59（A相）、#58-#59（B相）、#58-#59（C相 ）、#63-#64（C相 ）、#65-#66（B相 ）、#69-#70（B相 ）、#71-#72（A相 ）、#72-#73（C相 ）、#73-#74（C相 ）、#75-#76（B相 ）、#77-#78（地线）、#77-#78（A相 ）、#77-#78（B相）、#79-#80（C相）、#80-#81（地线）、#81-#82（B相）、#91-#92（C相）、#93-#94（B相）、#94-#95（A相）、#99-#100（A相）、#99-#100（B相）、#99-#100（C相）、#127-#128（地线）、#127-#128（C相）、#127-#128（B相）、#127-#128（A相 ）、#134-#135（A相 ） | L35: 54 | M35: 45170 | N35: 2023年9月30日 | O35: 否 | P35: 输电管理二所 | Q35: 吴达 | R35: 朱常镇 | S35: 天河中心 | T35: 54 | U35: 2023-09-07 08:46:00 | V35: 2023-09-07 12:07:00 | W35: 54 | X35: 54 | Y35: 1 | Z35: 1 | AB35: JH030120230111-014592 | AC35: 已完成 | AH35: =IF(N35="2023年01月","2023年01月31日",IF(N35="2023年02月","2023年02月28日",IF(N35="2023年3月","2023年3月31日",IF(N35="2023年4月","2023年4月30日",IF(N35="2023年5月","2023年5月31日",IF(N35="2023年6月","2023年6月30日",IF(N35="2023年7月","2023年7月31日",IF(N35="2023年8月","2023年8月31日",IF(N35="2023年9月","2023年9月30日",IF(N35="2023年10月","2023年10月31日",IF(N35="2023年11月","2023年11月30日",IF(N35="2023年12月","2023年12月31日")))))))))))) -> FALSE
A36: 33 | B36: 预试 | C36: 考核 | D36: 500kV | E36: 关键 | F36: 从木丁线 | G36: 机巡区复合绝缘子 | H36: #1、#2、#3、#4、#5、#6、#7、#8、#9、#10、#11、#12、#13、#14、#15、#16、#17、#18、#19、#20、#21、#22、#23、#24、#25、#26、#27、#28、#29、#30、#31、#32、#33、#34、#35、#36、#37、#38、#39、#40、#41、#42、#43、#44、#45、#46、#47、#48、#49、#50、#51、#52、#53、#54、#55、#56、#57、#58、#59、#60、#61、#62、#63、#64、#65、#66、#67、#68、#69、#70、#71、#72、#73、#74、#75、#76、#77、#78、#79、#80、#81、#82、#83、#84、#85、#86、#87、#88、#89、#90、#91、#92、#93、#94、#95、#96、#97、#98、#99、#100、#101、#102、#103、#104、#105、#106、#107、#108、#109、#110、#111、#112、#113、#114、#115、#116、#117、#118、#119、#120、#121、#122、#123、#124、#125、#126、#127、#128、#129、#130、#131、#132、#133、#134、#135 | I36: 135 | J36: 624 | K36: 9 | M36: 44986 | N36: 2023年3月31日 | O36: 否 | P36: 输电管理二所 | Q36: 吴达 | R36: 朱常镇 | S36: 天河中心 | T36: 624 | U36: 2023-03-17 08:48:00 | V36: 2023-03-17 11:57:00 | W36: 624 | X36: 624 | Y36: 1 | Z36: 1 | AB36: JH030120230111-010828 | AC36: 已完成 | AH36: =IF(N36="2023年01月","2023年01月31日",IF(N36="2023年02月","2023年02月28日",IF(N36="2023年3月","2023年3月31日",IF(N36="2023年4月","2023年4月30日",IF(N36="2023年5月","2023年5月31日",IF(N36="2023年6月","2023年6月30日",IF(N36="2023年7月","2023年7月31日",IF(N36="2023年8月","2023年8月31日",IF(N36="2023年9月","2023年9月30日",IF(N36="2023年10月","2023年10月31日",IF(N36="2023年11月","2023年11月30日",IF(N36="2023年12月","2023年12月31日")))))))))))) -> FALSE
A37: 34 | B37: 预试 | C37: 考核 | D37: 500kV | E37: 关键 | F37: 从木丁线 | G37: 导、地线连接位置 | H37: 耐张线夹：#1、#3、#8、#10、#11、#13、#18、#22、#24、#25、#29、#31、#33、#34、#36、#37、#39、#41、#43、#47、#50、#55、#61、#64、#66、#68、#70、#78、#82、#85、#87、#89、#91、#94、#97、#100、#101、#103、#105、#106、#107、#110、#111、#112、#116、#117、#119、#122、#124、#127、#132、#133、#136、#137 | L37: 58 | M37: 44986 | N37: 2023年3月31日 | O37: 否 | P37: 输电管理二所 | Q37: 吴达 | R37: 朱常镇 | S37: 天河中心 | T37: 58 | U37: 2023-03-17 08:48:00 | V37: 2023-03-17 11:57:00 | W37: 58 | X37: 58 | Y37: 1 | Z37: 1 | AB37: JH030120230111-010828 | AC37: 已完成 | AH37: =IF(N37="2023年01月","2023年01月31日",IF(N37="2023年02月","2023年02月28日",IF(N37="2023年3月","2023年3月31日",IF(N37="2023年4月","2023年4月30日",IF(N37="2023年5月","2023年5月31日",IF(N37="2023年6月","2023年6月30日",IF(N37="2023年7月","2023年7月31日",IF(N37="2023年8月","2023年8月31日",IF(N37="2023年9月","2023年9月30日",IF(N37="2023年10月","2023年10月31日",IF(N37="2023年11月","2023年11月30日",IF(N37="2023年12月","2023年12月31日")))))))))))) -> FALSE
A38: 35 | B38: 预试 | C38: 考核 | D38: 500kV | E38: 关键 | F38: 从木丁线 | G38: 导、地线连接位置 | H38: 接续管或预绞丝：#05-#06（A相）、#05-#06（B相）、#05-#06（C相 ）、#10-#11（A相 ）、#15-#16（A相 ）、#15-#16（B相 ）、#15-#16（C相 ）、#20-#21（A相 ）、#20-#21（B相 ）、#20-#21（C相 ）、#28-#29（B相 ）、#28-#29（C相 ）、#36-37（B相 ）、#40-41（C相 ）、#43-#44（A相 ）、#43-#44（B相）、#43-#44（C相）、#47-#48（A相）、#47-#48（B相）、#47-#48（C相）、#50-#51（A相）、#50-#51（B相）、#52-#53（A相）、#52-#53（B相）、#52-#53（C相）、#58-#59（A相）、#58-#59（B相）、#58-#59（C相 ）、#63-#64（C相 ）、#65-#66（A相 ）、#67-#68（C相 ）、#69-#70（B相 ）、#71-#72（A相 ）、#73-#74（C相）、#74-#75（A相 ）、#76-#77（B相）、#77-#78（B相）、#91-#92（A相）、#93-#94（B相）、#94-#95（C相）、#99-#100（A相）、#99-#100（B相）、#99-#100（C相）、#123-#124（B相）、#127-#128（A相 ）、#127-#128（B相）、#127-#128（C相） | L38: 47 | M38: 44986 | N38: 2023年3月31日 | O38: 否 | P38: 输电管理二所 | Q38: 吴达 | R38: 朱常镇 | S38: 天河中心 | T38: 47 | U38: 2023-03-17 08:48:00 | V38: 2023-03-17 11:57:00 | W38: 47 | X38: 47 | Y38: 1 | Z38: 1 | AB38: JH030120230111-010828 | AC38: 已完成 | AH38: =IF(N38="2023年01月","2023年01月31日",IF(N38="2023年02月","2023年02月28日",IF(N38="2023年3月","2023年3月31日",IF(N38="2023年4月","2023年4月30日",IF(N38="2023年5月","2023年5月31日",IF(N38="2023年6月","2023年6月30日",IF(N38="2023年7月","2023年7月31日",IF(N38="2023年8月","2023年8月31日",IF(N38="2023年9月","2023年9月30日",IF(N38="2023年10月","2023年10月31日",IF(N38="2023年11月","2023年11月30日",IF(N38="2023年12月","2023年12月31日")))))))))))) -> FALSE
A39: 36 | B39: 预试 | C39: 考核 | D39: 500kV | E39: 关键 | F39: 从木丁线 | G39: 机巡区复合绝缘子 | H39: #1、#2、#3、#4、#5、#6、#7、#8、#9、#10、#11、#12、#13、#14、#15、#16、#17、#18、#19、#20、#21、#22、#23、#24、#25、#26、#27、#28、#29、#30、#31、#32、#33、#34、#35、#36、#37、#38、#39、#40、#41、#42、#43、#44、#45、#46、#47、#48、#49、#50、#51、#52、#53、#54、#55、#56、#57、#58、#59、#60、#61、#62、#63、#64、#65、#66、#67、#68、#69、#70、#71、#72、#73、#74、#75、#76、#77、#78、#79、#80、#81、#82、#83、#84、#85、#86、#87、#88、#89、#90、#91、#92、#93、#94、#95、#96、#97、#98、#99、#100、#101、#102、#103、#104、#105、#106、#107、#108、#109、#110、#111、#112、#113、#114、#115、#116、#117、#118、#119、#120、#121、#122、#123、#124、#125、#126、#127、#128、#129、#130、#131、#132、#133、#134、#135 | I39: 135 | J39: 624 | K39: 9 | M39: 45170 | N39: 2023年9月30日 | O39: 否 | P39: 输电管理二所 | Q39: 吴达 | R39: 朱常镇 | S39: 天河中心 | T39: 624 | U39: 2023-09-07 08:46:00 | V39: 2023-09-07 12:07:00 | W39: 624 | X39: 624 | Y39: 1 | Z39: 1 | AB39: JH030120230111-014592 | AC39: 已完成 | AH39: =IF(N39="2023年01月","2023年01月31日",IF(N39="2023年02月","2023年02月28日",IF(N39="2023年3月","2023年3月31日",IF(N39="2023年4月","2023年4月30日",IF(N39="2023年5月","2023年5月31日",IF(N39="2023年6月","2023年6月30日",IF(N39="2023年7月","2023年7月31日",IF(N39="2023年8月","2023年8月31日",IF(N39="2023年9月","2023年9月30日",IF(N39="2023年10月","2023年10月31日",IF(N39="2023年11月","2023年11月30日",IF(N39="2023年12月","2023年12月31日")))))))))))) -> FALSE
A40: 37 | B40: 预试 | C40: 考核 | D40: 500kV | E40: 关键 | F40: 从木丁线 | G40: 导、地线连接位置 | H40: 耐张线夹：#1、#3、#8、#10、#11、#13、#18、#22、#24、#25、#29、#31、#33、#34、#36、#37、#39、#41、#43、#47、#50、#55、#61、#64、#66、#68、#70、#78、#82、#85、#87、#89、#91、#94、#97、#100、#101、#103、#105、#106、#107、#110、#111、#112、#116、#117、#119、#122、#124、#127、#132、#133、#136、#137 | L40: 58 | M40: 45170 | N40: 2023年9月30日 | O40: 否 | P40: 输电管理二所 | Q40: 吴达 | R40: 朱常镇 | S40: 天河中心 | T40: 58 | U40: 2023-09-07 08:46:00 | V40: 2023-09-07 12:07:00 | W40: 58 | X40: 58 | Y40: 1 | Z40: 1 | AB40: JH030120230111-014592 | AC40: 已完成 | AH40: =IF(N40="2023年01月","2023年01月31日",IF(N40="2023年02月","2023年02月28日",IF(N40="2023年3月","2023年3月31日",IF(N40="2023年4月","2023年4月30日",IF(N40="2023年5月","2023年5月31日",IF(N40="2023年6月","2023年6月30日",IF(N40="2023年7月","2023年7月31日",IF(N40="2023年8月","2023年8月31日",IF(N40="2023年9月","2023年9月30日",IF(N40="2023年10月","2023年10月31日",IF(N40="2023年11月","2023年11月30日",IF(N40="2023年12月","2023年12月31日")))))))))))) -> FALSE
...

Sheet 2、架空线路接地电阻测试
A1: 输电管理二所2023年接地电阻测试计划
A2: 序号 | B2: 工作类型 | C2: 计划类型 | D2: 电压等级 | E2: 线路重要度 | F2: 线路名称 | G2: 线路段 | H2: 工作计划 | I2: 杆塔数量（基） | J2: 计划开始日期 | K2: 计划结束日期 | L2: 是否停电 | M2: 责任单位 | N2: 中心负责人 | O2: 线路专责人 | P2: 责任中心 | Q2: 计划完成数 | R2: 实际开始日期(自动计算） | S2: 实际结束日期(自动计算） | T2: 实际完成数 (自动计算） | U2: 合格数量 (自动计算） | V2: 完成率 (自动计算） | W2: 合格率 (自动计算） | X2: 备注（异常情况、未按时完成原因） | Y2: 对应系统中计划编号 | Z2: 对应系统中计划状态 | AA2: 问题 | AB2: 提醒 | AC2: 中心反馈
A3: 1 | B3: 预试 | C3: 考核 | D3: 500kV | E3: 关键 | F3: 从科甲线 | G3: 进出段：#01-#03、#114-#118 中间段：#04-#113 | H3: 进出段：#01-#03、#114-#118 | I3: 8 | J3: 44986 | K3: 2023年3月31日 | L3: 否 | M3: 输电管理二所 | N3: 吴达 | O3: 甘永叶 | P3: 天河中心 | Q3: 8 | R3: 2023-03-22 08:28:00 | S3: 2023-03-22 12:39:00 | T3: 8 | U3: 8 | V3: 1 | W3: 1 | Y3: JH030120230112-011824 | Z3: 已完成 | AA3: 无 | AD3: =IF(J3="2023年01月","2023年01月01日",IF(J3="2023年02月","2023年02月01日",IF(J3="2023年3月","2023年3月1日",IF(J3="2023年4月","2023年4月1日",IF(J3="2023年5月","2023年5月1日",IF(J3="2023年6月","2023年6月1日",IF(J3="2023年7月","2023年7月1日",IF(J3="2023年8月","2023年8月1日",IF(J3="2023年9月","2023年9月1日",IF(J3="2023年10月","2023年10月1日",IF(J3="2023年11月","2023年11月1日",IF(J3="2023年12月","2023年12月1日")))))))))))) -> FALSE | AE3: =IF(K3="2023年01月","2023年01月31日",IF(K3="2023年02月","2023年02月28日",IF(K3="2023年3月","2023年3月31日",IF(K3="2023年4月","2023年4月30日",IF(K3="2023年5月","2023年5月31日",IF(K3="2023年6月","2023年6月30日",IF(K3="2023年7月","2023年7月31日",IF(K3="2023年8月","2023年8月31日",IF(K3="2023年9月","2023年9月30日",IF(K3="2023年10月","2023年10月31日",IF(K3="2023年11月","2023年11月30日",IF(K3="2023年12月","2023年12月31日")))))))))))) -> FALSE
A4: 2 | B4: 预试 | C4: 考核 | D4: 500kV | E4: 关键 | F4: 从科乙线 | G4: 进出段：#01-#03、#114-#118 中间段：#04-#113 | H4: 进出段：#01-#03、#114-#118 | I4: 8 | J4: 44986 | K4: 2023年3月31日 | L4: 否 | M4: 输电管理二所 | N4: 吴达 | O4: 甘永叶 | P4: 天河中心 | Q4: 8 | R4: 2023-03-22 08:28:00 | S4: 2023-03-22 12:39:00 | T4: 8 | U4: 8 | V4: 1 | W4: 1 | Y4: JH030120230112-011824 | Z4: 已完成 | AA4: 无 | AD4: =IF(J4="2023年01月","2023年01月01日",IF(J4="2023年02月","2023年02月01日",IF(J4="2023年3月","2023年3月1日",IF(J4="2023年4月","2023年4月1日",IF(J4="2023年5月","2023年5月1日",IF(J4="2023年6月","2023年6月1日",IF(J4="2023年7月","2023年7月1日",IF(J4="2023年8月","2023年8月1日",IF(J4="2023年9月","2023年9月1日",IF(J4="2023年10月","2023年10月1日",IF(J4="2023年11月","2023年11月1日",IF(J4="2023年12月","2023年12月1日")))))))))))) -> FALSE | AE4: =IF(K4="2023年01月","2023年01月31日",IF(K4="2023年02月","2023年02月28日",IF(K4="2023年3月","2023年3月31日",IF(K4="2023年4月","2023年4月30日",IF(K4="2023年5月","2023年5月31日",IF(K4="2023年6月","2023年6月30日",IF(K4="2023年7月","2023年7月31日",IF(K4="2023年8月","2023年8月31日",IF(K4="2023年9月","2023年9月30日",IF(K4="2023年10月","2023年10月31日",IF(K4="2023年11月","2023年11月30日",IF(K4="2023年12月","2023年12月31日")))))))))))) -> FALSE
A5: 3 | B5: 预试 | C5: 考核 | D5: 500kV | E5: 关键 | F5: 科木甲线 | G5: 进出段：#01-#05、#27-#29 中间段：#06-#26 | H5: 进出段：#01-#05、#27-#29 | I5: 8 | J5: 44986 | K5: 2023年3月31日 | L5: 否 | M5: 输电管理二所 | N5: 吴达 | O5: 甘永叶 | P5: 天河中心 | Q5: 8 | R5: 2023-03-22 08:37:00 | S5: 2023-03-22 12:37:00 | T5: 8 | U5: 8 | V5: 1 | W5: 1 | Y5: JH030120230112-011956 | Z5: 已完成 | AA5: 无 | AD5: =IF(J5="2023年01月","2023年01月01日",IF(J5="2023年02月","2023年02月01日",IF(J5="2023年3月","2023年3月1日",IF(J5="2023年4月","2023年4月1日",IF(J5="2023年5月","2023年5月1日",IF(J5="2023年6月","2023年6月1日",IF(J5="2023年7月","2023年7月1日",IF(J5="2023年8月","2023年8月1日",IF(J5="2023年9月","2023年9月1日",IF(J5="2023年10月","2023年10月1日",IF(J5="2023年11月","2023年11月1日",IF(J5="2023年12月","2023年12月1日")))))))))))) -> FALSE | AE5: =IF(K5="2023年01月","2023年01月31日",IF(K5="2023年02月","2023年02月28日",IF(K5="2023年3月","2023年3月31日",IF(K5="2023年4月","2023年4月30日",IF(K5="2023年5月","2023年5月31日",IF(K5="2023年6月","2023年6月30日",IF(K5="2023年7月","2023年7月31日",IF(K5="2023年8月","2023年8月31日",IF(K5="2023年9月","2023年9月30日",IF(K5="2023年10月","2023年10月31日",IF(K5="2023年11月","2023年11月30日",IF(K5="2023年12月","2023年12月31日")))))))))))) -> FALSE
A6: 4 | B6: 预试 | C6: 考核 | D6: 500kV | E6: 关键 | F6: 科木乙线 | G6: 进出段：#01-#05、#27-#29 中间段：#06-#26 | H6: 进出段：#01-#05、#27-#29 | I6: 8 | J6: 44986 | K6: 2023年3月31日 | L6: 否 | M6: 输电管理二所 | N6: 吴达 | O6: 甘永叶 | P6: 天河中心 | Q6: 8 | R6: 2023-03-22 08:37:00 | S6: 2023-03-22 12:37:00 | T6: 8 | U6: 8 | V6: 1 | W6: 1 | Y6: JH030120230112-011956 | Z6: 已完成 | AA6: 无 | AD6: =IF(J6="2023年01月","2023年01月01日",IF(J6="2023年02月","2023年02月01日",IF(J6="2023年3月","2023年3月1日",IF(J6="2023年4月","2023年4月1日",IF(J6="2023年5月","2023年5月1日",IF(J6="2023年6月","2023年6月1日",IF(J6="2023年7月","2023年7月1日",IF(J6="2023年8月","2023年8月1日",IF(J6="2023年9月","2023年9月1日",IF(J6="2023年10月","2023年10月1日",IF(J6="2023年11月","2023年11月1日",IF(J6="2023年12月","2023年12月1日")))))))))))) -> FALSE | AE6: =IF(K6="2023年01月","2023年01月31日",IF(K6="2023年02月","2023年02月28日",IF(K6="2023年3月","2023年3月31日",IF(K6="2023年4月","2023年4月30日",IF(K6="2023年5月","2023年5月31日",IF(K6="2023年6月","2023年6月30日",IF(K6="2023年7月","2023年7月31日",IF(K6="2023年8月","2023年8月31日",IF(K6="2023年9月","2023年9月30日",IF(K6="2023年10月","2023年10月31日",IF(K6="2023年11月","2023年11月30日",IF(K6="2023年12月","2023年12月31日")))))))))))) -> FALSE
A7: 5 | B7: 预试 | C7: 考核 | D7: 500kV | E7: 关键 | F7: 从木丙线 | G7: 进出段：#01-#03、#135-#137 中间段：#04-#134 | H7: 进出段：#01-#03、#135-#137 | I7: 6 | J7: 44986 | K7: 2023年3月31日 | L7: 否 | M7: 输电管理二所 | N7: 吴达 | O7: 朱常镇 | P7: 天河中心 | Q7: 6 | R7: 2023-04-13 08:45:00 | S7: 2023-04-13 16:14:00 | T7: 6 | U7: 6 | V7: 1 | W7: 1 | Y7: JH030120230112-011840 | Z7: 已完成 | AA7: =IF(Y7="无","未匹配到系统工单信息",IF(Z7="已完成","无",Z7)) -> 无 | AD7: =IF(J7="2023年01月","2023年01月01日",IF(J7="2023年02月","2023年02月01日",IF(J7="2023年3月","2023年3月1日",IF(J7="2023年4月","2023年4月1日",IF(J7="2023年5月","2023年5月1日",IF(J7="2023年6月","2023年6月1日",IF(J7="2023年7月","2023年7月1日",IF(J7="2023年8月","2023年8月1日",IF(J7="2023年9月","2023年9月1日",IF(J7="2023年10月","2023年10月1日",IF(J7="2023年11月","2023年11月1日",IF(J7="2023年12月","2023年12月1日")))))))))))) -> FALSE | AE7: =IF(K7="2023年01月","2023年01月31日",IF(K7="2023年02月","2023年02月28日",IF(K7="2023年3月","2023年3月31日",IF(K7="2023年4月","2023年4月30日",IF(K7="2023年5月","2023年5月31日",IF(K7="2023年6月","2023年6月30日",IF(K7="2023年7月","2023年7月31日",IF(K7="2023年8月","2023年8月31日",IF(K7="2023年9月","2023年9月30日",IF(K7="2023年10月","2023年10月31日",IF(K7="2023年11月","2023年11月30日",IF(K7="2023年12月","2023年12月31日")))))))))))) -> FALSE
A8: 6 | B8: 预试 | C8: 考核 | D8: 500kV | E8: 关键 | F8: 从木丁线 | G8: 进出段：#01-#03、#135-#137 中间段：#04-#134 | H8: 进出段：#01-#03、#135-#137 | I8: 6 | J8: 44986 | K8: 2023年3月31日 | L8: 否 | M8: 输电管理二所 | N8: 吴达 | O8: 朱常镇 | P8: 天河中心 | Q8: 6 | R8: 2023-04-13 08:45:00 | S8: 2023-04-13 16:14:00 | T8: 6 | U8: 6 | V8: 1 | W8: 1 | Y8: JH030120230112-011840 | Z8: 已完成 | AA8: =IF(Y8="无","未匹配到系统工单信息",IF(Z8="已完成","无",Z8)) -> 无 | AD8: =IF(J8="2023年01月","2023年01月01日",IF(J8="2023年02月","2023年02月01日",IF(J8="2023年3月","2023年3月1日",IF(J8="2023年4月","2023年4月1日",IF(J8="2023年5月","2023年5月1日",IF(J8="2023年6月","2023年6月1日",IF(J8="2023年7月","2023年7月1日",IF(J8="2023年8月","2023年8月1日",IF(J8="2023年9月","2023年9月1日",IF(J8="2023年10月","2023年10月1日",IF(J8="2023年11月","2023年11月1日",IF(J8="2023年12月","2023年12月1日")))))))))))) -> FALSE | AE8: =IF(K8="2023年01月","2023年01月31日",IF(K8="2023年02月","2023年02月28日",IF(K8="2023年3月","2023年3月31日",IF(K8="2023年4月","2023年4月30日",IF(K8="2023年5月","2023年5月31日",IF(K8="2023年6月","2023年6月30日",IF(K8="2023年7月","2023年7月31日",IF(K8="2023年8月","2023年8月31日",IF(K8="2023年9月","2023年9月30日",IF(K8="2023年10月","2023年10月31日",IF(K8="2023年11月","2023年11月30日",IF(K8="2023年12月","2023年12月31日")))))))))))) -> FALSE
A9: 7 | B9: 预试 | C9: 考核 | D9: 220kV | E9: 关键 | F9: 木村甲线 | G9: 进出段：#01-#03、#103-#105 中间段：#04-#102 | H9: 进出段：#01-#03、#103-#105 | I9: 6 | J9: 44986 | K9: 2023年3月31日 | L9: 否 | M9: 输电管理二所 | N9: 吴达 | O9: 梁乔云 | P9: 天河中心 | Q9: 6 | R9: 2023-03-03 08:50:00 | S9: 2023-03-03 14:50:00 | T9: 6 | U9: 6 | V9: 1 | W9: 1 | Y9: JH030120230113-010189 | Z9: 已完成 | AA9: 无 | AD9: =IF(J9="2023年01月","2023年01月01日",IF(J9="2023年02月","2023年02月01日",IF(J9="2023年3月","2023年3月1日",IF(J9="2023年4月","2023年4月1日",IF(J9="2023年5月","2023年5月1日",IF(J9="2023年6月","2023年6月1日",IF(J9="2023年7月","2023年7月1日",IF(J9="2023年8月","2023年8月1日",IF(J9="2023年9月","2023年9月1日",IF(J9="2023年10月","2023年10月1日",IF(J9="2023年11月","2023年11月1日",IF(J9="2023年12月","2023年12月1日")))))))))))) -> FALSE | AE9: =IF(K9="2023年01月","2023年01月31日",IF(K9="2023年02月","2023年02月28日",IF(K9="2023年3月","2023年3月31日",IF(K9="2023年4月","2023年4月30日",IF(K9="2023年5月","2023年5月31日",IF(K9="2023年6月","2023年6月30日",IF(K9="2023年7月","2023年7月31日",IF(K9="2023年8月","2023年8月31日",IF(K9="2023年9月","2023年9月30日",IF(K9="2023年10月","2023年10月31日",IF(K9="2023年11月","2023年11月30日",IF(K9="2023年12月","2023年12月31日")))))))))))) -> FALSE
A10: 8 | B10: 预试 | C10: 考核 | D10: 220kV | E10: 关键 | F10: 木村乙线 | G10: 进出段：#01-#03、#103-#105 中间段：#04-#102 | H10: 进出段：#01-#03、#103-#105 | I10: 6 | J10: 44986 | K10: 2023年3月31日 | L10: 否 | M10: 输电管理二所 | N10: 吴达 | O10: 梁乔云 | P10: 天河中心 | Q10: 6 | R10: 2023-03-03 08:50:00 | S10: 2023-03-03 14:50:00 | T10: 6 | U10: 6 | V10: 1 | W10: 1 | Y10: JH030120230113-010189 | Z10: 已完成 | AA10: 无 | AD10: =IF(J10="2023年01月","2023年01月01日",IF(J10="2023年02月","2023年02月01日",IF(J10="2023年3月","2023年3月1日",IF(J10="2023年4月","2023年4月1日",IF(J10="2023年5月","2023年5月1日",IF(J10="2023年6月","2023年6月1日",IF(J10="2023年7月","2023年7月1日",IF(J10="2023年8月","2023年8月1日",IF(J10="2023年9月","2023年9月1日",IF(J10="2023年10月","2023年10月1日",IF(J10="2023年11月","2023年11月1日",IF(J10="2023年12月","2023年12月1日")))))))))))) -> FALSE | AE10: =IF(K10="2023年01月","2023年01月31日",IF(K10="2023年02月","2023年02月28日",IF(K10="2023年3月","2023年3月31日",IF(K10="2023年4月","2023年4月30日",IF(K10="2023年5月","2023年5月31日",IF(K10="2023年6月","2023年6月30日",IF(K10="2023年7月","2023年7月31日",IF(K10="2023年8月","2023年8月31日",IF(K10="2023年9月","2023年9月30日",IF(K10="2023年10月","2023年10月31日",IF(K10="2023年11月","2023年11月30日",IF(K10="2023年12月","2023年12月31日")))))))))))) -> FALSE
A11: 9 | B11: 预试 | C11: 考核 | D11: 220kV | E11: 关键 | F11: 木犀甲线 | G11: 进出段：#01-#03、#50-#52 中间段：#04-#48 | H11: 进出段：#01-#03、#49-#52 | I11: 6 | J11: 44986 | K11: 2023年3月31日 | L11: 否 | M11: 输电管理二所 | N11: 吴达 | O11: 李文兴 | P11: 天河中心 | Q11: 6 | R11: 2023-03-20 08:55:00 | S11: 2023-03-20 12:45:00 | T11: 6 | U11: 6 | V11: 1 | W11: 1 | Y11: JH030120230116-005762 | Z11: 已完成 | AA11: 无 | AD11: =IF(J11="2023年01月","2023年01月01日",IF(J11="2023年02月","2023年02月01日",IF(J11="2023年3月","2023年3月1日",IF(J11="2023年4月","2023年4月1日",IF(J11="2023年5月","2023年5月1日",IF(J11="2023年6月","2023年6月1日",IF(J11="2023年7月","2023年7月1日",IF(J11="2023年8月","2023年8月1日",IF(J11="2023年9月","2023年9月1日",IF(J11="2023年10月","2023年10月1日",IF(J11="2023年11月","2023年11月1日",IF(J11="2023年12月","2023年12月1日")))))))))))) -> FALSE | AE11: =IF(K11="2023年01月","2023年01月31日",IF(K11="2023年02月","2023年02月28日",IF(K11="2023年3月","2023年3月31日",IF(K11="2023年4月","2023年4月30日",IF(K11="2023年5月","2023年5月31日",IF(K11="2023年6月","2023年6月30日",IF(K11="2023年7月","2023年7月31日",IF(K11="2023年8月","2023年8月31日",IF(K11="2023年9月","2023年9月30日",IF(K11="2023年10月","2023年10月31日",IF(K11="2023年11月","2023年11月30日",IF(K11="2023年12月","2023年12月31日")))))))))))) -> FALSE
A12: 10 | B12: 预试 | C12: 考核 | D12: 220kV | E12: 关键 | F12: 木犀乙线 | G12: 进出段：#01-#03、#50-#52 中间段：#04-#48 | H12: 进出段：#01-#03、#49-#52 | I12: 6 | J12: 44986 | K12: 2023年3月31日 | L12: 否 | M12: 输电管理二所 | N12: 吴达 | O12: 李文兴 | P12: 天河中心 | Q12: 6 | R12: 2023-03-20 08:55:00 | S12: 2023-03-20 12:45:00 | T12: 6 | U12: 6 | V12: 1 | W12: 1 | Y12: JH030120230116-005762 | Z12: 已完成 | AA12: 无 | AD12: =IF(J12="2023年01月","2023年01月01日",IF(J12="2023年02月","2023年02月01日",IF(J12="2023年3月","2023年3月1日",IF(J12="2023年4月","2023年4月1日",IF(J12="2023年5月","2023年5月1日",IF(J12="2023年6月","2023年6月1日",IF(J12="2023年7月","2023年7月1日",IF(J12="2023年8月","2023年8月1日",IF(J12="2023年9月","2023年9月1日",IF(J12="2023年10月","2023年10月1日",IF(J12="2023年11月","2023年11月1日",IF(J12="2023年12月","2023年12月1日")))))))))))) -> FALSE | AE12: =IF(K12="2023年01月","2023年01月31日",IF(K12="2023年02月","2023年02月28日",IF(K12="2023年3月","2023年3月31日",IF(K12="2023年4月","2023年4月30日",IF(K12="2023年5月","2023年5月31日",IF(K12="2023年6月","2023年6月30日",IF(K12="2023年7月","2023年7月31日",IF(K12="2023年8月","2023年8月31日",IF(K12="2023年9月","2023年9月30日",IF(K12="2023年10月","2023年10月31日",IF(K12="2023年11月","2023年11月30日",IF(K12="2023年12月","2023年12月31日")))))))))))) -> FALSE
A13: 11 | B13: 预试 | C13: 考核 | D13: 220kV | E13: 关键 | F13: 木麒甲线 | G13: 进出段：#01-#03、#50-#52 中间段：#04-#48 | H13: 进出段：#01-#03、#49-#52 | I13: 6 | J13: 44986 | K13: 2023年3月31日 | L13: 否 | M13: 输电管理二所 | N13: 吴达 | O13: 李文兴 | P13: 天河中心 | Q13: 6 | R13: 2023-03-20 08:55:00 | S13: 2023-03-20 12:45:00 | T13: 6 | U13: 6 | V13: 1 | W13: 1 | Y13: JH030120230116-005762 | Z13: 已完成 | AA13: 无 | AD13: =IF(J13="2023年01月","2023年01月01日",IF(J13="2023年02月","2023年02月01日",IF(J13="2023年3月","2023年3月1日",IF(J13="2023年4月","2023年4月1日",IF(J13="2023年5月","2023年5月1日",IF(J13="2023年6月","2023年6月1日",IF(J13="2023年7月","2023年7月1日",IF(J13="2023年8月","2023年8月1日",IF(J13="2023年9月","2023年9月1日",IF(J13="2023年10月","2023年10月1日",IF(J13="2023年11月","2023年11月1日",IF(J13="2023年12月","2023年12月1日")))))))))))) -> FALSE | AE13: =IF(K13="2023年01月","2023年01月31日",IF(K13="2023年02月","2023年02月28日",IF(K13="2023年3月","2023年3月31日",IF(K13="2023年4月","2023年4月30日",IF(K13="2023年5月","2023年5月31日",IF(K13="2023年6月","2023年6月30日",IF(K13="2023年7月","2023年7月31日",IF(K13="2023年8月","2023年8月31日",IF(K13="2023年9月","2023年9月30日",IF(K13="2023年10月","2023年10月31日",IF(K13="2023年11月","2023年11月30日",IF(K13="2023年12月","2023年12月31日")))))))))))) -> FALSE
A14: 12 | B14: 预试 | C14: 考核 | D14: 220kV | E14: 关键 | F14: 木麒乙线 | G14: 进出段：#01-#03、#50-#52 中间段：#04-#48 | H14: 进出段：#01-#03、#49-#52 | I14: 6 | J14: 44986 | K14: 2023年3月31日 | L14: 否 | M14: 输电管理二所 | N14: 吴达 | O14: 李文兴 | P14: 天河中心 | Q14: 6 | R14: 2023-03-20 08:55:00 | S14: 2023-03-20 12:45:00 | T14: 6 | U14: 6 | V14: 1 | W14: 1 | Y14: JH030120230116-005762 | Z14: 已完成 | AA14: 无 | AD14: =IF(J14="2023年01月","2023年01月01日",IF(J14="2023年02月","2023年02月01日",IF(J14="2023年3月","2023年3月1日",IF(J14="2023年4月","2023年4月1日",IF(J14="2023年5月","2023年5月1日",IF(J14="2023年6月","2023年6月1日",IF(J14="2023年7月","2023年7月1日",IF(J14="2023年8月","2023年8月1日",IF(J14="2023年9月","2023年9月1日",IF(J14="2023年10月","2023年10月1日",IF(J14="2023年11月","2023年11月1日",IF(J14="2023年12月","2023年12月1日")))))))))))) -> FALSE | AE14: =IF(K14="2023年01月","2023年01月31日",IF(K14="2023年02月","2023年02月28日",IF(K14="2023年3月","2023年3月31日",IF(K14="2023年4月","2023年4月30日",IF(K14="2023年5月","2023年5月31日",IF(K14="2023年6月","2023年6月30日",IF(K14="2023年7月","2023年7月31日",IF(K14="2023年8月","2023年8月31日",IF(K14="2023年9月","2023年9月30日",IF(K14="2023年10月","2023年10月31日",IF(K14="2023年11月","2023年11月30日",IF(K14="2023年12月","2023年12月31日")))))))))))) -> FALSE
A15: 13 | B15: 预试 | C15: 考核 | D15: 220kV | E15: 一般(7-9月为关键线路) | F15: 木凯甲线 | G15: 进出段：#01-#03、#119-#121 中间段：#04-#118 | H15: 进出段：#01-#03、#119-#121 | I15: 6 | J15: 44986 | K15: 2023年3月31日 | L15: 否 | M15: 输电管理二所 | N15: 吴达 | O15: 孔盛权 | P15: 天河中心 | Q15: 6 | R15: 2023-04-12 08:45:00 | S15: 2023-04-12 14:35:00 | T15: 6 | U15: 6 | V15: 100%% | W15: 100%% | Y15: JH030120230112-011998 | Z15: 已完成 | AD15: =IF(J15="2023年01月","2023年01月01日",IF(J15="2023年02月","2023年02月01日",IF(J15="2023年3月","2023年3月1日",IF(J15="2023年4月","2023年4月1日",IF(J15="2023年5月","2023年5月1日",IF(J15="2023年6月","2023年6月1日",IF(J15="2023年7月","2023年7月1日",IF(J15="2023年8月","2023年8月1日",IF(J15="2023年9月","2023年9月1日",IF(J15="2023年10月","2023年10月1日",IF(J15="2023年11月","2023年11月1日",IF(J15="2023年12月","2023年12月1日")))))))))))) -> FALSE | AE15: =IF(K15="2023年01月","2023年01月31日",IF(K15="2023年02月","2023年02月28日",IF(K15="2023年3月","2023年3月31日",IF(K15="2023年4月","2023年4月30日",IF(K15="2023年5月","2023年5月31日",IF(K15="2023年6月","2023年6月30日",IF(K15="2023年7月","2023年7月31日",IF(K15="2023年8月","2023年8月31日",IF(K15="2023年9月","2023年9月30日",IF(K15="2023年10月","2023年10月31日",IF(K15="2023年11月","2023年11月30日",IF(K15="2023年12月","2023年12月31日")))))))))))) -> FALSE
A16: 14 | B16: 预试 | C16: 考核 | D16: 220kV | E16: 一般(7-9月为关键线路) | F16: 木凯乙线 | G16: 进出段：#01-#03、#119-#121 中间段：#04-#118 | H16: 进出段：#01-#03、#119-#121 | I16: 6 | J16: 44986 | K16: 2023年3月31日 | L16: 否 | M16: 输电管理二所 | N16: 吴达 | O16: 孔盛权 | P16: 天河中心 | Q16: 6 | R16: 2023-04-12 08:45:00 | S16: 2023-04-12 14:35:00 | T16: 6 | U16: 6 | V16: 100%% | W16: 100%% | Y16: JH030120230112-011998 | Z16: 已完成 | AD16: =IF(J16="2023年01月","2023年01月01日",IF(J16="2023年02月","2023年02月01日",IF(J16="2023年3月","2023年3月1日",IF(J16="2023年4月","2023年4月1日",IF(J16="2023年5月","2023年5月1日",IF(J16="2023年6月","2023年6月1日",IF(J16="2023年7月","2023年7月1日",IF(J16="2023年8月","2023年8月1日",IF(J16="2023年9月","2023年9月1日",IF(J16="2023年10月","2023年10月1日",IF(J16="2023年11月","2023年11月1日",IF(J16="2023年12月","2023年12月1日")))))))))))) -> FALSE | AE16: =IF(K16="2023年01月","2023年01月31日",IF(K16="2023年02月","2023年02月28日",IF(K16="2023年3月","2023年3月31日",IF(K16="2023年4月","2023年4月30日",IF(K16="2023年5月","2023年5月31日",IF(K16="2023年6月","2023年6月30日",IF(K16="2023年7月","2023年7月31日",IF(K16="2023年8月","2023年8月31日",IF(K16="2023年9月","2023年9月30日",IF(K16="2023年10月","2023年10月31日",IF(K16="2023年11月","2023年11月30日",IF(K16="2023年12月","2023年12月31日")))))))))))) -> FALSE
A17: 15 | B17: 预试 | C17: 考核 | D17: 220kV | E17: 重要（7-9月） | F17: 木科甲线 | G17: 进出段：#01-#03、#51-#53 中间段：#04-#50 | H17: 中间段：#31-#50 | I17: 20 | J17: 45017 | K17: 2023年4月30日 | L17: 否 | M17: 输电管理二所 | N17: 吴达 | O17: 杜亮鸿 | P17: 天河中心 | Q17: 20 | R17: 2023-05-08 08:30:00 | S17: 2023-05-08 14:28:00 | T17: 20 | U17: 20 | V17: 1 | W17: 1 | Y17: JH030120230116-006454 | Z17: 已完成 | AD17: =IF(J17="2023年01月","2023年01月01日",IF(J17="2023年02月","2023年02月01日",IF(J17="2023年3月","2023年3月1日",IF(J17="2023年4月","2023年4月1日",IF(J17="2023年5月","2023年5月1日",IF(J17="2023年6月","2023年6月1日",IF(J17="2023年7月","2023年7月1日",IF(J17="2023年8月","2023年8月1日",IF(J17="2023年9月","2023年9月1日",IF(J17="2023年10月","2023年10月1日",IF(J17="2023年11月","2023年11月1日",IF(J17="2023年12月","2023年12月1日")))))))))))) -> FALSE | AE17: =IF(K17="2023年01月","2023年01月31日",IF(K17="2023年02月","2023年02月28日",IF(K17="2023年3月","2023年3月31日",IF(K17="2023年4月","2023年4月30日",IF(K17="2023年5月","2023年5月31日",IF(K17="2023年6月","2023年6月30日",IF(K17="2023年7月","2023年7月31日",IF(K17="2023年8月","2023年8月31日",IF(K17="2023年9月","2023年9月30日",IF(K17="2023年10月","2023年10月31日",IF(K17="2023年11月","2023年11月30日",IF(K17="2023年12月","2023年12月31日")))))))))))) -> FALSE
A18: 16 | B18: 预试 | C18: 考核 | D18: 220kV | E18: 重要（7-9月） | F18: 木科乙线 | G18: 进出段：#01-#03、#51-#53 中间段：#04-#50 | H18: 中间段：#31-#50 | I18: 20 | J18: 45017 | K18: 2023年4月30日 | L18: 否 | M18: 输电管理二所 | N18: 吴达 | O18: 杜亮鸿 | P18: 天河中心 | Q18: 20 | R18: 2023-05-08 08:30:00 | S18: 2023-05-08 14:28:00 | T18: 20 | U18: 20 | V18: 1 | W18: 1 | Y18: JH030120230116-006454 | Z18: 已完成 | AD18: =IF(J18="2023年01月","2023年01月01日",IF(J18="2023年02月","2023年02月01日",IF(J18="2023年3月","2023年3月1日",IF(J18="2023年4月","2023年4月1日",IF(J18="2023年5月","2023年5月1日",IF(J18="2023年6月","2023年6月1日",IF(J18="2023年7月","2023年7月1日",IF(J18="2023年8月","2023年8月1日",IF(J18="2023年9月","2023年9月1日",IF(J18="2023年10月","2023年10月1日",IF(J18="2023年11月","2023年11月1日",IF(J18="2023年12月","2023年12月1日")))))))))))) -> FALSE | AE18: =IF(K18="2023年01月","2023年01月31日",IF(K18="2023年02月","2023年02月28日",IF(K18="2023年3月","2023年3月31日",IF(K18="2023年4月","2023年4月30日",IF(K18="2023年5月","2023年5月31日",IF(K18="2023年6月","2023年6月30日",IF(K18="2023年7月","2023年7月31日",IF(K18="2023年8月","2023年8月31日",IF(K18="2023年9月","2023年9月30日",IF(K18="2023年10月","2023年10月31日",IF(K18="2023年11月","2023年11月30日",IF(K18="2023年12月","2023年12月31日")))))))))))) -> FALSE
A19: 17 | B19: 预试 | C19: 考核 | D19: 220kV | E19: 一般 | F19: 木棠甲线 | G19: 进出段：#01-#03、#82-#84 中间段：#04-#81 | H19: 中间段：#31-#60 | I19: 30 | J19: 45017 | K19: 2023年4月30日 | L19: 否 | M19: 输电管理二所 | N19: 吴达 | O19: 张耀光 | P19: 天河中心 | Q19: 30 | R19: 2023-04-17 08:52:00 | S19: 2023-04-17 12:20:00 | T19: 30 | U19: 30 | V19: 1 | W19: 1 | Y19: JH030120230116-006092 | Z19: 已完成 | AD19: =IF(J19="2023年01月","2023年01月01日",IF(J19="2023年02月","2023年02月01日",IF(J19="2023年3月","2023年3月1日",IF(J19="2023年4月","2023年4月1日",IF(J19="2023年5月","2023年5月1日",IF(J19="2023年6月","2023年6月1日",IF(J19="2023年7月","2023年7月1日",IF(J19="2023年8月","2023年8月1日",IF(J19="2023年9月","2023年9月1日",IF(J19="2023年10月","2023年10月1日",IF(J19="2023年11月","2023年11月1日",IF(J19="2023年12月","2023年12月1日")))))))))))) -> FALSE | AE19: =IF(K19="2023年01月","2023年01月31日",IF(K19="2023年02月","2023年02月28日",IF(K19="2023年3月","2023年3月31日",IF(K19="2023年4月","2023年4月30日",IF(K19="2023年5月","2023年5月31日",IF(K19="2023年6月","2023年6月30日",IF(K19="2023年7月","2023年7月31日",IF(K19="2023年8月","2023年8月31日",IF(K19="2023年9月","2023年9月30日",IF(K19="2023年10月","2023年10月31日",IF(K19="2023年11月","2023年11月30日",IF(K19="2023年12月","2023年12月31日")))))))))))) -> FALSE
