Workbook

Sheet 报告
B2: 报告：成功合并 44 个工作表，共 9869 行数据。
B4: 工作簿 | C4: 工作表 | D4: 合并状态 | E4: 合并后的位置
B5: 【附件】2.输电管理二所2024年预试检测计划（3月重要度修改-从化）.xlsx | C5: 报告 | D5: 成功 | E5: 报告 (2)'!B1:F49
B6: 【附件】2.输电管理二所2024年预试检测计划-按最新重要度调整-花都.xlsx | C6: 报告 | D6: 成功 | E6: 报告 (2)'!B50:F98
B7: 【附件】2.输电管理二所2024年预试检测计划-新-天河中心.xlsx | C7: 报告 | D7: 成功 | E7: 报告 (2)'!B99:F147
B8: 白云-【附件】2.输电管理二所2024年预试检测计划.xlsx | C8: 报告 | D8: 成功 | E8: 报告 (2)'!B148:F196
B9: 【附件】2.输电管理二所2024年预试检测计划（3月重要度修改-从化）.xlsx | C9: 1、架空线路红外检测 | D9: 成功 | E9: 1、架空线路红外检测'!B1:AA624
B10: 【附件】2.输电管理二所2024年预试检测计划-按最新重要度调整-花都.xlsx | C10: 1、架空线路红外检测 | D10: 成功 | E10: 1、架空线路红外检测'!B625:AA4670
B11: 【附件】2.输电管理二所2024年预试检测计划-新-天河中心.xlsx | C11: 1、架空线路红外检测 | D11: 成功 | E11: 1、架空线路红外检测'!B4671:AA5193
B12: 白云-【附件】2.输电管理二所2024年预试检测计划.xlsx | C12: 1、架空线路红外检测 | D12: 成功 | E12: 1、架空线路红外检测'!B5194:AA6765
B13: 【附件】2.输电管理二所2024年预试检测计划（3月重要度修改-从化）.xlsx | C13: 2、架空线路接地电阻测试 | D13: 成功 | E13: 2、架空线路接地电阻测试'!B1:Y29
B14: 【附件】2.输电管理二所2024年预试检测计划-按最新重要度调整-花都.xlsx | C14: 2、架空线路接地电阻测试 | D14: 成功 | E14: 2、架空线路接地电阻测试'!B30:Y117
B15: 【附件】2.输电管理二所2024年预试检测计划-新-天河中心.xlsx | C15: 2、架空线路接地电阻测试 | D15: 成功 | E15: 2、架空线路接地电阻测试'!B118:Y150
... B48: 白云-【附件】2.输电管理二所2024年预试检测计划.xlsx | C48: 8、非直埋式中间接头红外检测 | D48: 成功 | E48: 8、非直埋式中间接头红外检测'!B1:U144

Sheet 统计
C1: 1月份 | D1: 2月份 | E1: 3月份 | F1: 4月份 | G1: 5月份 | H1: 6月份 | I1: 7月份 | J1: 8月份 | K1: 9月份 | L1: 10月份 | M1: 11月份 | N1: 12月份
A2: 1、架空线路红外检测 | B2: 白云中心 | C2: =COUNTIFS('1、架空线路红外检测'!$R$4:$R$385,"白云中心",'1、架空线路红外检测'!$AG$4:$AG$385,"1月份已完成") -> 94 | D2: =COUNTIFS('1、架空线路红外检测'!$R$4:$R$385,"白云中心",'1、架空线路红外检测'!$AG$4:$AG$385,"2月份已完成") -> 12 | E2: =COUNTIFS('1、架空线路红外检测'!$R$4:$R$385,"白云中心",'1、架空线路红外检测'!$AG$4:$AG$385,"3月份已完成") -> 12 | F2: =COUNTIFS('1、架空线路红外检测'!$R$4:$R$385,"白云中心",'1、架空线路红外检测'!$AG$4:$AG$385,"4月份已完成") -> 5 | G2: =COUNTIFS('1、架空线路红外检测'!$R$4:$R$385,"白云中心",'1、架空线路红外检测'!$AG$4:$AG$385,"5月份已完成") -> 7 | H2: =COUNTIFS('1、架空线路红外检测'!$R$4:$R$385,"白云中心",'1、架空线路红外检测'!$AG$4:$AG$385,"6月份已完成") -> 0 | I2: =COUNTIFS('1、架空线路红外检测'!$R$4:$R$385,"白云中心",'1、架空线路红外检测'!$AG$4:$AG$385,"7月份已完成") -> 19 | J2: =COUNTIFS('1、架空线路红外检测'!$R$4:$R$385,"白云中心",'1、架空线路红外检测'!$AG$4:$AG$385,"8月份已完成") -> 4 | K2: =COUNTIFS('1、架空线路红外检测'!$R$4:$R$385,"白云中心",'1、架空线路红外检测'!$AG$4:$AG$385,"9月份已完成") -> 4 | L2: =COUNTIFS('1、架空线路红外检测'!$R$4:$R$385,"白云中心",'1、架空线路红外检测'!$AG$4:$AG$385,"10月份已完成") -> 0 | M2: =COUNTIFS('1、架空线路红外检测'!$R$4:$R$385,"白云中心",'1、架空线路红外检测'!$AG$4:$AG$385,"11月份已完成") -> 0 | N2: =COUNTIFS('1、架空线路红外检测'!$R$4:$R$385,"白云中心",'1、架空线路红外检测'!$AG$4:$AG$385,"12月份已完成") -> 0
B3: 从化中心 | C3: =COUNTIFS('1、架空线路红外检测'!$R$4:$R$385,"从化中心",'1、架空线路红外检测'!$AG$4:$AG$385,"1月份已完成") -> 40 | D3: =COUNTIFS('1、架空线路红外检测'!$R$4:$R$385,"从化中心",'1、架空线路红外检测'!$AG$4:$AG$385,"2月份已完成") -> 4 | E3: =COUNTIFS('1、架空线路红外检测'!$R$4:$R$385,"从化中心",'1、架空线路红外检测'!$AG$4:$AG$385,"3月份已完成") -> 3 | F3: =COUNTIFS('1、架空线路红外检测'!$R$4:$R$385,"从化中心",'1、架空线路红外检测'!$AG$4:$AG$385,"4月份已完成") -> 3 | G3: =COUNTIFS('1、架空线路红外检测'!$R$4:$R$385,"从化中心",'1、架空线路红外检测'!$AG$4:$AG$385,"5月份已完成") -> 0 | H3: =COUNTIFS('1、架空线路红外检测'!$R$4:$R$385,"从化中心",'1、架空线路红外检测'!$AG$4:$AG$385,"6月份已完成") -> 0 | I3: =COUNTIFS('1、架空线路红外检测'!$R$4:$R$385,"从化中心",'1、架空线路红外检测'!$AG$4:$AG$385,"7月份已完成") -> 3 | J3: =COUNTIFS('1、架空线路红外检测'!$R$4:$R$385,"从化中心",'1、架空线路红外检测'!$AG$4:$AG$385,"8月份已完成") -> 0 | K3: =COUNTIFS('1、架空线路红外检测'!$R$4:$R$385,"从化中心",'1、架空线路红外检测'!$AG$4:$AG$385,"9月份已完成") -> 1 | L3: =COUNTIFS('1、架空线路红外检测'!$R$4:$R$385,"从化中心",'1、架空线路红外检测'!$AG$4:$AG$385,"10月份已完成") -> 0 | M3: =COUNTIFS('1、架空线路红外检测'!$R$4:$R$385,"从化中心",'1、架空线路红外检测'!$AG$4:$AG$385,"11月份已完成") -> 0 | N3: =COUNTIFS('1、架空线路红外检测'!$R$4:$R$385,"从化中心",'1、架空线路红外检测'!$AG$4:$AG$385,"12月份已完成") -> 0
B4: 花都中心 | C4: =COUNTIFS('1、架空线路红外检测'!$R$4:$R$385,"花都中心",'1、架空线路红外检测'!$AG$4:$AG$385,"1月份已完成") -> 47 | D4: =COUNTIFS('1、架空线路红外检测'!$R$4:$R$385,"花都中心",'1、架空线路红外检测'!$AG$4:$AG$385,"2月份已完成") -> 23 | E4: =COUNTIFS('1、架空线路红外检测'!$R$4:$R$385,"花都中心",'1、架空线路红外检测'!$AG$4:$AG$385,"3月份已完成") -> 6 | F4: =COUNTIFS('1、架空线路红外检测'!$R$4:$R$385,"花都中心",'1、架空线路红外检测'!$AG$4:$AG$385,"4月份已完成") -> 5 | G4: =COUNTIFS('1、架空线路红外检测'!$R$4:$R$385,"花都中心",'1、架空线路红外检测'!$AG$4:$AG$385,"5月份已完成") -> 3 | H4: =COUNTIFS('1、架空线路红外检测'!$R$4:$R$385,"花都中心",'1、架空线路红外检测'!$AG$4:$AG$385,"6月份已完成") -> 20 | I4: =COUNTIFS('1、架空线路红外检测'!$R$4:$R$385,"花都中心",'1、架空线路红外检测'!$AG$4:$AG$385,"7月份已完成") -> 7 | J4: =COUNTIFS('1、架空线路红外检测'!$R$4:$R$385,"花都中心",'1、架空线路红外检测'!$AG$4:$AG$385,"8月份已完成") -> 3 | K4: =COUNTIFS('1、架空线路红外检测'!$R$4:$R$385,"花都中心",'1、架空线路红外检测'!$AG$4:$AG$385,"9月份已完成") -> 0 | L4: =COUNTIFS('1、架空线路红外检测'!$R$4:$R$385,"花都中心",'1、架空线路红外检测'!$AG$4:$AG$385,"10月份已完成") -> 0 | M4: =COUNTIFS('1、架空线路红外检测'!$R$4:$R$385,"花都中心",'1、架空线路红外检测'!$AG$4:$AG$385,"11月份已完成") -> 0 | N4: =COUNTIFS('1、架空线路红外检测'!$R$4:$R$385,"花都中心",'1、架空线路红外检测'!$AG$4:$AG$385,"12月份已完成") -> 0
B5: 天河中心 | C5: =COUNTIFS('1、架空线路红外检测'!$R$4:$R$385,"天河中心",'1、架空线路红外检测'!$AG$4:$AG$385,"1月份已完成") -> 29 | D5: =COUNTIFS('1、架空线路红外检测'!$R$4:$R$385,"天河中心",'1、架空线路红外检测'!$AG$4:$AG$385,"2月份已完成") -> 0 | E5: =COUNTIFS('1、架空线路红外检测'!$R$4:$R$385,"天河中心",'1、架空线路红外检测'!$AG$4:$AG$385,"3月份已完成") -> 3 | F5: =COUNTIFS('1、架空线路红外检测'!$R$4:$R$385,"天河中心",'1、架空线路红外检测'!$AG$4:$AG$385,"4月份已完成") -> 2 | G5: =COUNTIFS('1、架空线路红外检测'!$R$4:$R$385,"天河中心",'1、架空线路红外检测'!$AG$4:$AG$385,"5月份已完成") -> 0 | H5: =COUNTIFS('1、架空线路红外检测'!$R$4:$R$385,"天河中心",'1、架空线路红外检测'!$AG$4:$AG$385,"6月份已完成") -> 0 | I5: =COUNTIFS('1、架空线路红外检测'!$R$4:$R$385,"天河中心",'1、架空线路红外检测'!$AG$4:$AG$385,"7月份已完成") -> 18 | J5: =COUNTIFS('1、架空线路红外检测'!$R$4:$R$385,"天河中心",'1、架空线路红外检测'!$AG$4:$AG$385,"8月份已完成") -> 1 | K5: =COUNTIFS('1、架空线路红外检测'!$R$4:$R$385,"天河中心",'1、架空线路红外检测'!$AG$4:$AG$385,"9月份已完成") -> 0 | L5: =COUNTIFS('1、架空线路红外检测'!$R$4:$R$385,"天河中心",'1、架空线路红外检测'!$AG$4:$AG$385,"10月份已完成") -> 0 | M5: =COUNTIFS('1、架空线路红外检测'!$R$4:$R$385,"天河中心",'1、架空线路红外检测'!$AG$4:$AG$385,"11月份已完成") -> 0 | N5: =COUNTIFS('1、架空线路红外检测'!$R$4:$R$385,"天河中心",'1、架空线路红外检测'!$AG$4:$AG$385,"12月份已完成") -> 0
A6: 重要跨越区段测温 | B6: 白云中心 | C6: =COUNTIFS(重要跨越区段测温!$E$2:$E$935,"*白云*",重要跨越区段测温!$J$2:$J$935,"绿灯") -> 0 | D6: =COUNTIFS(重要跨越区段测温!$E$2:$E$935,"*白云*",重要跨越区段测温!$L$2:$L$935,"绿灯") -> 0 | E6: =COUNTIFS(重要跨越区段测温!$E$2:$E$935,"*白云*",重要跨越区段测温!$N$2:$N$935,"绿灯") -> 0 | F6: =COUNTIFS(重要跨越区段测温!$E$2:$E$935,"*白云*",重要跨越区段测温!$P$2:$P$935,"绿灯") -> 0 | G6: =COUNTIFS(重要跨越区段测温!$E$2:$E$935,"*白云*",重要跨越区段测温!$R$2:$R$935,"绿灯") -> 0 | H6: =COUNTIFS(重要跨越区段测温!$E$4:$E$935,"*白云*",重要跨越区段测温!$T$4:$T$935,"绿灯") -> 281 | I6: =COUNTIFS(重要跨越区段测温!$E$4:$E$935,"*白云*",重要跨越区段测温!$V$4:$V$935,"绿灯") -> 0 | J6: =COUNTIFS(重要跨越区段测温!$E$4:$E$935,"*白云*",重要跨越区段测温!$X$4:$X$935,"绿灯") -> 0 | K6: =COUNTIFS(重要跨越区段测温!$E$4:$E$935,"*白云*",重要跨越区段测温!$Z$4:$Z$935,"绿灯") -> 0 | L6: =COUNTIFS(重要跨越区段测温!$E$4:$E$935,"*白云*",重要跨越区段测温!$AB$4:$AB$935,"绿灯") -> 0 | M6: =COUNTIFS(重要跨越区段测温!$E$4:$E$935,"*白云*",重要跨越区段测温!$AD$4:$AD$935,"绿灯") -> 0 | N6: =COUNTIFS(重要跨越区段测温!$E$4:$E$935,"*白云*",重要跨越区段测温!$AF$4:$AF$935,"绿灯") -> 0
B7: 从化中心 | C7: =COUNTIFS(重要跨越区段测温!$E$2:$E$935,"*从化*",重要跨越区段测温!$J$2:$J$935,"绿灯") -> 0 | D7: =COUNTIFS(重要跨越区段测温!$E$2:$E$935,"*从化*",重要跨越区段测温!$L$2:$L$935,"绿灯") -> 0 | E7: =COUNTIFS(重要跨越区段测温!$E$2:$E$935,"*从化*",重要跨越区段测温!$N$2:$N$935,"绿灯") -> 0 | F7: =COUNTIFS(重要跨越区段测温!$E$2:$E$935,"*从化*",重要跨越区段测温!$P$2:$P$935,"绿灯") -> 0 | G7: =COUNTIFS(重要跨越区段测温!$E$2:$E$935,"*从化*",重要跨越区段测温!$R$2:$R$935,"绿灯") -> 0 | H7: =COUNTIFS(重要跨越区段测温!$E$4:$E$935,"*从化*",重要跨越区段测温!$T$4:$T$935,"绿灯") -> 140 | I7: =COUNTIFS(重要跨越区段测温!$E$4:$E$935,"*从化*",重要跨越区段测温!$V$4:$V$935,"绿灯") -> 0 | J7: =COUNTIFS(重要跨越区段测温!$E$4:$E$935,"*从化*",重要跨越区段测温!$X$4:$X$935,"绿灯") -> 0 | K7: =COUNTIFS(重要跨越区段测温!$E$4:$E$935,"*从化*",重要跨越区段测温!$Z$4:$Z$935,"绿灯") -> 0 | L7: =COUNTIFS(重要跨越区段测温!$E$4:$E$935,"*从化*",重要跨越区段测温!$AB$4:$AB$935,"绿灯") -> 0 | M7: =COUNTIFS(重要跨越区段测温!$E$4:$E$935,"*从化*",重要跨越区段测温!$AD$4:$AD$935,"绿灯") -> 0 | N7: =COUNTIFS(重要跨越区段测温!$E$4:$E$935,"*从化*",重要跨越区段测温!$AF$4:$AF$935,"绿灯") -> 0
B8: 花都中心 | C8: =COUNTIFS(重要跨越区段测温!$E$2:$E$935,"*花都*",重要跨越区段测温!$J$2:$J$935,"绿灯") -> 0 | D8: =COUNTIFS(重要跨越区段测温!$E$2:$E$935,"*花都*",重要跨越区段测温!$L$2:$L$935,"绿灯") -> 0 | E8: =COUNTIFS(重要跨越区段测温!$E$2:$E$935,"*花都*",重要跨越区段测温!$N$2:$N$935,"绿灯") -> 0 | F8: =COUNTIFS(重要跨越区段测温!$E$2:$E$935,"*花都*",重要跨越区段测温!$P$2:$P$935,"绿灯") -> 0 | G8: =COUNTIFS(重要跨越区段测温!$E$2:$E$935,"*花都*",重要跨越区段测温!$R$2:$R$935,"绿灯") -> 0 | H8: =COUNTIFS(重要跨越区段测温!$E$4:$E$935,"*花都*",重要跨越区段测温!$T$4:$T$935,"绿灯") -> 274 | I8: =COUNTIFS(重要跨越区段测温!$E$4:$E$935,"*花都*",重要跨越区段测温!$V$4:$V$935,"绿灯") -> 0 | J8: =COUNTIFS(重要跨越区段测温!$E$4:$E$935,"*花都*",重要跨越区段测温!$X$4:$X$935,"绿灯") -> 0 | K8: =COUNTIFS(重要跨越区段测温!$E$4:$E$935,"*花都*",重要跨越区段测温!$Z$4:$Z$935,"绿灯") -> 0 | L8: =COUNTIFS(重要跨越区段测温!$E$4:$E$935,"*花都*",重要跨越区段测温!$AB$4:$AB$935,"绿灯") -> 0 | M8: =COUNTIFS(重要跨越区段测温!$E$4:$E$935,"*花都*",重要跨越区段测温!$AD$4:$AD$935,"绿灯") -> 0 | N8: =COUNTIFS(重要跨越区段测温!$E$4:$E$935,"*花都*",重要跨越区段测温!$AF$4:$AF$935,"绿灯") -> 0
B9: 天河中心 | C9: =COUNTIFS(重要跨越区段测温!$E$2:$E$935,"*天河*",重要跨越区段测温!$J$2:$J$935,"绿灯") -> 0 | D9: =COUNTIFS(重要跨越区段测温!$E$2:$E$935,"*天河*",重要跨越区段测温!$L$2:$L$935,"绿灯") -> 0 | E9: =COUNTIFS(重要跨越区段测温!$E$2:$E$935,"*天河*",重要跨越区段测温!$N$2:$N$935,"绿灯") -> 0 | F9: =COUNTIFS(重要跨越区段测温!$E$2:$E$935,"*天河*",重要跨越区段测温!$P$2:$P$935,"绿灯") -> 0 | G9: =COUNTIFS(重要跨越区段测温!$E$2:$E$935,"*天河*",重要跨越区段测温!$R$2:$R$935,"绿灯") -> 0 | H9: =COUNTIFS(重要跨越区段测温!$E$4:$E$935,"*天河*",重要跨越区段测温!$T$4:$T$935,"绿灯") -> 145 | I9: =COUNTIFS(重要跨越区段测温!$E$4:$E$935,"*天河*",重要跨越区段测温!$V$4:$V$935,"绿灯") -> 0 | J9: =COUNTIFS(重要跨越区段测温!$E$4:$E$935,"*天河*",重要跨越区段测温!$X$4:$X$935,"绿灯") -> 0 | K9: =COUNTIFS(重要跨越区段测温!$E$4:$E$935,"*天河*",重要跨越区段测温!$Z$4:$Z$935,"绿灯") -> 0 | L9: =COUNTIFS(重要跨越区段测温!$E$4:$E$935,"*天河*",重要跨越区段测温!$AB$4:$AB$935,"绿灯") -> 0 | M9: =COUNTIFS(重要跨越区段测温!$E$4:$E$935,"*天河*",重要跨越区段测温!$AD$4:$AD$935,"绿灯") -> 0 | N9: =COUNTIFS(重要跨越区段测温!$E$4:$E$935,"*天河*",重要跨越区段测温!$AF$4:$AF$935,"绿灯") -> 0
A10: 2、架空线路接地电阻测试 | B10: 白云中心 | C10: =COUNTIFS('2、架空线路接地电阻测试'!$P$4:$P$250,"白云中心",'2、架空线路接地电阻测试'!$AE$4:$AE$250,"1月份已完成") -> 2 | D10: =COUNTIFS('2、架空线路接地电阻测试'!$P$4:$P$250,"白云中心",'2、架空线路接地电阻测试'!$AE$4:$AE$250,"2月份已完成") -> 10 | E10: =COUNTIFS('2、架空线路接地电阻测试'!$P$4:$P$250,"白云中心",'2、架空线路接地电阻测试'!$AE$4:$AE$250,"3月份已完成") -> 0 | F10: =COUNTIFS('2、架空线路接地电阻测试'!$P$4:$P$250,"白云中心",'2、架空线路接地电阻测试'!$AE$4:$AE$250,"4月份已完成") -> 23 | G10: =COUNTIFS('2、架空线路接地电阻测试'!$P$4:$P$250,"白云中心",'2、架空线路接地电阻测试'!$AE$4:$AE$250,"5月份已完成") -> 0 | H10: =COUNTIFS('2、架空线路接地电阻测试'!$P$4:$P$250,"白云中心",'2、架空线路接地电阻测试'!$AE$4:$AE$250,"6月份已完成") -> 0 | I10: =COUNTIFS('2、架空线路接地电阻测试'!$P$4:$P$250,"白云中心",'2、架空线路接地电阻测试'!$AE$4:$AE$250,"7月份已完成") -> 0 | J10: =COUNTIFS('2、架空线路接地电阻测试'!$P$4:$P$250,"白云中心",'2、架空线路接地电阻测试'!$AE$4:$AE$250,"8月份已完成") -> 0 | K10: =COUNTIFS('2、架空线路接地电阻测试'!$P$4:$P$250,"白云中心",'2、架空线路接地电阻测试'!$AE$4:$AE$250,"9月份已完成") -> 3 | L10: =COUNTIFS('2、架空线路接地电阻测试'!$P$4:$P$250,"白云中心",'2、架空线路接地电阻测试'!$AE$4:$AE$250,"10月份已完成") -> 5 | M10: =COUNTIFS('2、架空线路接地电阻测试'!$P$4:$P$250,"白云中心",'2、架空线路接地电阻测试'!$AE$4:$AE$250,"11月份已完成") -> 0 | N10: =COUNTIFS('2、架空线路接地电阻测试'!$P$4:$P$250,"白云中心",'2、架空线路接地电阻测试'!$AE$4:$AE$250,"12月份已完成") -> 0
B11: 从化中心 | C11: =COUNTIFS('2、架空线路接地电阻测试'!$P$4:$P$250,"从化中心",'2、架空线路接地电阻测试'!$AE$4:$AE$250,"1月份已完成") -> 0 | D11: =COUNTIFS('2、架空线路接地电阻测试'!$P$4:$P$250,"从化中心",'2、架空线路接地电阻测试'!$AE$4:$AE$250,"2月份已完成") -> 1 | E11: =COUNTIFS('2、架空线路接地电阻测试'!$P$4:$P$250,"从化中心",'2、架空线路接地电阻测试'!$AE$4:$AE$250,"3月份已完成") -> 0 | F11: =COUNTIFS('2、架空线路接地电阻测试'!$P$4:$P$250,"从化中心",'2、架空线路接地电阻测试'!$AE$4:$AE$250,"4月份已完成") -> 2 | G11: =COUNTIFS('2、架空线路接地电阻测试'!$P$4:$P$250,"从化中心",'2、架空线路接地电阻测试'!$AE$4:$AE$250,"5月份已完成") -> 0 | H11: =COUNTIFS('2、架空线路接地电阻测试'!$P$4:$P$250,"从化中心",'2、架空线路接地电阻测试'!$AE$4:$AE$250,"6月份已完成") -> 0 | I11: =COUNTIFS('2、架空线路接地电阻测试'!$P$4:$P$250,"从化中心",'2、架空线路接地电阻测试'!$AE$4:$AE$250,"7月份已完成") -> 0 | J11: =COUNTIFS('2、架空线路接地电阻测试'!$P$4:$P$250,"从化中心",'2、架空线路接地电阻测试'!$AE$4:$AE$250,"8月份已完成") -> 1 | K11: =COUNTIFS('2、架空线路接地电阻测试'!$P$4:$P$250,"从化中心",'2、架空线路接地电阻测试'!$AE$4:$AE$250,"9月份已完成") -> 11 | L11: =COUNTIFS('2、架空线路接地电阻测试'!$P$4:$P$250,"从化中心",'2、架空线路接地电阻测试'!$AE$4:$AE$250,"10月份已完成") -> 0 | M11: =COUNTIFS('2、架空线路接地电阻测试'!$P$4:$P$250,"从化中心",'2、架空线路接地电阻测试'!$AE$4:$AE$250,"11月份已完成") -> 0 | N11: =COUNTIFS('2、架空线路接地电阻测试'!$P$4:$P$250,"从化中心",'2、架空线路接地电阻测试'!$AE$4:$AE$250,"12月份已完成") -> 0
B12: 花都中心 | C12: =COUNTIFS('2、架空线路接地电阻测试'!$P$4:$P$250,"花都中心",'2、架空线路接地电阻测试'!$AE$4:$AE$250,"1月份已完成") -> 0 | D12: =COUNTIFS('2、架空线路接地电阻测试'!$P$4:$P$250,"花都中心",'2、架空线路接地电阻测试'!$AE$4:$AE$250,"2月份已完成") -> 0 | E12: =COUNTIFS('2、架空线路接地电阻测试'!$P$4:$P$250,"花都中心",'2、架空线路接地电阻测试'!$AE$4:$AE$250,"3月份已完成") -> 0 | F12: =COUNTIFS('2、架空线路接地电阻测试'!$P$4:$P$250,"花都中心",'2、架空线路接地电阻测试'!$AE$4:$AE$250,"4月份已完成") -> 0 | G12: =COUNTIFS('2、架空线路接地电阻测试'!$P$4:$P$250,"花都中心",'2、架空线路接地电阻测试'!$AE$4:$AE$250,"5月份已完成") -> 0 | H12: =COUNTIFS('2、架空线路接地电阻测试'!$P$4:$P$250,"花都中心",'2、架空线路接地电阻测试'!$AE$4:$AE$250,"6月份已完成") -> 0 | I12: =COUNTIFS('2、架空线路接地电阻测试'!$P$4:$P$250,"花都中心",'2、架空线路接地电阻测试'!$AE$4:$AE$250,"7月份已完成") -> 7 | J12: =COUNTIFS('2、架空线路接地电阻测试'!$P$4:$P$250,"花都中心",'2、架空线路接地电阻测试'!$AE$4:$AE$250,"8月份已完成") -> 4 | K12: =COUNTIFS('2、架空线路接地电阻测试'!$P$4:$P$250,"花都中心",'2、架空线路接地电阻测试'!$AE$4:$AE$250,"9月份已完成") -> 1 | L12: =COUNTIFS('2、架空线路接地电阻测试'!$P$4:$P$250,"花都中心",'2、架空线路接地电阻测试'!$AE$4:$AE$250,"10月份已完成") -> 5 | M12: =COUNTIFS('2、架空线路接地电阻测试'!$P$4:$P$250,"花都中心",'2、架空线路接地电阻测试'!$AE$4:$AE$250,"11月份已完成") -> 0 | N12: =COUNTIFS('2、架空线路接地电阻测试'!$P$4:$P$250,"花都中心",'2、架空线路接地电阻测试'!$AE$4:$AE$250,"12月份已完成") -> 0
B13: 天河中心 | C13: =COUNTIFS('2、架空线路接地电阻测试'!$P$4:$P$250,"天河中心",'2、架空线路接地电阻测试'!$AE$4:$AE$250,"1月份已完成") -> 0 | D13: =COUNTIFS('2、架空线路接地电阻测试'!$P$4:$P$250,"天河中心",'2、架空线路接地电阻测试'!$AE$4:$AE$250,"2月份已完成") -> 0 | E13: =COUNTIFS('2、架空线路接地电阻测试'!$P$4:$P$250,"天河中心",'2、架空线路接地电阻测试'!$AE$4:$AE$250,"3月份已完成") -> 0 | F13: =COUNTIFS('2、架空线路接地电阻测试'!$P$4:$P$250,"天河中心",'2、架空线路接地电阻测试'!$AE$4:$AE$250,"4月份已完成") -> 0 | G13: =COUNTIFS('2、架空线路接地电阻测试'!$P$4:$P$250,"天河中心",'2、架空线路接地电阻测试'!$AE$4:$AE$250,"5月份已完成") -> 0 | H13: =COUNTIFS('2、架空线路接地电阻测试'!$P$4:$P$250,"天河中心",'2、架空线路接地电阻测试'!$AE$4:$AE$250,"6月份已完成") -> 1 | I13: =COUNTIFS('2、架空线路接地电阻测试'!$P$4:$P$250,"天河中心",'2、架空线路接地电阻测试'!$AE$4:$AE$250,"7月份已完成") -> 2 | J13: =COUNTIFS('2、架空线路接地电阻测试'!$P$4:$P$250,"天河中心",'2、架空线路接地电阻测试'!$AE$4:$AE$250,"8月份已完成") -> 0 | K13: =COUNTIFS('2、架空线路接地电阻测试'!$P$4:$P$250,"天河中心",'2、架空线路接地电阻测试'!$AE$4:$AE$250,"9月份已完成") -> 0 | L13: =COUNTIFS('2、架空线路接地电阻测试'!$P$4:$P$250,"天河中心",'2、架空线路接地电阻测试'!$AE$4:$AE$250,"10月份已完成") -> 0 | M13: =COUNTIFS('2、架空线路接地电阻测试'!$P$4:$P$250,"天河中心",'2、架空线路接地电阻测试'!$AE$4:$AE$250,"11月份已完成") -> 0 | N13: =COUNTIFS('2、架空线路接地电阻测试'!$P$4:$P$250,"天河中心",'2、架空线路接地电阻测试'!$AE$4:$AE$250,"12月份已完成") -> 0
A14: 3、电缆线路交叉互联预试 | B14: 白云中心 | C14: =COUNTIFS('3、电缆线路交叉互联预试'!$M$4:$M$65,"白云中心",'3、电缆线路交叉互联预试'!$AJ$4:$AJ$65,"1月份已完成") -> 1 | D14: =COUNTIFS('3、电缆线路交叉互联预试'!$M$4:$M$65,"白云中心",'3、电缆线路交叉互联预试'!$AJ$4:$AJ$65,"2月份已完成") -> 1 | E14: =COUNTIFS('3、电缆线路交叉互联预试'!$M$4:$M$65,"白云中心",'3、电缆线路交叉互联预试'!$AJ$4:$AJ$65,"3月份已完成") -> 4 | F14: =COUNTIFS('3、电缆线路交叉互联预试'!$M$4:$M$65,"白云中心",'3、电缆线路交叉互联预试'!$AJ$4:$AJ$65,"4月份已完成") -> 4 | G14: =COUNTIFS('3、电缆线路交叉互联预试'!$M$4:$M$65,"白云中心",'3、电缆线路交叉互联预试'!$AJ$4:$AJ$65,"5月份已完成") -> 3 | H14: =COUNTIFS('3、电缆线路交叉互联预试'!$M$4:$M$65,"白云中心",'3、电缆线路交叉互联预试'!$AJ$4:$AJ$65,"6月份已完成") -> 1 | I14: =COUNTIFS('3、电缆线路交叉互联预试'!$M$4:$M$65,"白云中心",'3、电缆线路交叉互联预试'!$AJ$4:$AJ$65,"7月份已完成") -> 0 | J14: =COUNTIFS('3、电缆线路交叉互联预试'!$M$4:$M$65,"白云中心",'3、电缆线路交叉互联预试'!$AJ$4:$AJ$65,"8月份已完成") -> 2 | K14: =COUNTIFS('3、电缆线路交叉互联预试'!$M$4:$M$65,"白云中心",'3、电缆线路交叉互联预试'!$AJ$4:$AJ$65,"9月份已完成") -> 2 | L14: =COUNTIFS('3、电缆线路交叉互联预试'!$M$4:$M$65,"白云中心",'3、电缆线路交叉互联预试'!$AJ$4:$AJ$65,"10月份已完成") -> 1 | M14: =COUNTIFS('3、电缆线路交叉互联预试'!$M$4:$M$65,"白云中心",'3、电缆线路交叉互联预试'!$AJ$4:$AJ$65,"11月份已完成") -> 0 | N14: =COUNTIFS('3、电缆线路交叉互联预试'!$M$4:$M$65,"白云中心",'3、电缆线路交叉互联预试'!$AJ$4:$AJ$65,"12月份已完成") -> 0
B15: 从化中心 | C15: =COUNTIFS('3、电缆线路交叉互联预试'!$M$4:$M$65,"从化中心",'3、电缆线路交叉互联预试'!$AJ$4:$AJ$65,"1月份已完成") -> 0 | D15: =COUNTIFS('3、电缆线路交叉互联预试'!$M$4:$M$65,"从化中心",'3、电缆线路交叉互联预试'!$AJ$4:$AJ$65,"2月份已完成") -> 0 | E15: =COUNTIFS('3、电缆线路交叉互联预试'!$M$4:$M$65,"从化中心",'3、电缆线路交叉互联预试'!$AJ$4:$AJ$65,"3月份已完成") -> 0 | F15: =COUNTIFS('3、电缆线路交叉互联预试'!$M$4:$M$65,"从化中心",'3、电缆线路交叉互联预试'!$AJ$4:$AJ$65,"4月份已完成") -> 0 | G15: =COUNTIFS('3、电缆线路交叉互联预试'!$M$4:$M$65,"从化中心",'3、电缆线路交叉互联预试'!$AJ$4:$AJ$65,"5月份已完成") -> 0 | H15: =COUNTIFS('3、电缆线路交叉互联预试'!$M$4:$M$65,"从化中心",'3、电缆线路交叉互联预试'!$AJ$4:$AJ$65,"6月份已完成") -> 0 | I15: =COUNTIFS('3、电缆线路交叉互联预试'!$M$4:$M$65,"从化中心",'3、电缆线路交叉互联预试'!$AJ$4:$AJ$65,"7月份已完成") -> 0 | J15: =COUNTIFS('3、电缆线路交叉互联预试'!$M$4:$M$65,"从化中心",'3、电缆线路交叉互联预试'!$AJ$4:$AJ$65,"8月份已完成") -> 0 | K15: =COUNTIFS('3、电缆线路交叉互联预试'!$M$4:$M$65,"从化中心",'3、电缆线路交叉互联预试'!$AJ$4:$AJ$65,"9月份已完成") -> 0 | L15: =COUNTIFS('3、电缆线路交叉互联预试'!$M$4:$M$65,"从化中心",'3、电缆线路交叉互联预试'!$AJ$4:$AJ$65,"10月份已完成") -> 0 | M15: =COUNTIFS('3、电缆线路交叉互联预试'!$M$4:$M$65,"从化中心",'3、电缆线路交叉互联预试'!$AJ$4:$AJ$65,"11月份已完成") -> 0 | N15: =COUNTIFS('3、电缆线路交叉互联预试'!$M$4:$M$65,"从化中心",'3、电缆线路交叉互联预试'!$AJ$4:$AJ$65,"12月份已完成") -> 0
B16: 花都中心 | C16: =COUNTIFS('3、电缆线路交叉互联预试'!$M$4:$M$65,"花都中心",'3、电缆线路交叉互联预试'!$AJ$4:$AJ$65,"1月份已完成") -> 1 | D16: =COUNTIFS('3、电缆线路交叉互联预试'!$M$4:$M$65,"花都中心",'3、电缆线路交叉互联预试'!$AJ$4:$AJ$65,"2月份已完成") -> 0 | E16: =COUNTIFS('3、电缆线路交叉互联预试'!$M$4:$M$65,"花都中心",'3、电缆线路交叉互联预试'!$AJ$4:$AJ$65,"3月份已完成") -> 2 | F16: =COUNTIFS('3、电缆线路交叉互联预试'!$M$4:$M$65,"花都中心",'3、电缆线路交叉互联预试'!$AJ$4:$AJ$65,"4月份已完成") -> 1 | G16: =COUNTIFS('3、电缆线路交叉互联预试'!$M$4:$M$65,"花都中心",'3、电缆线路交叉互联预试'!$AJ$4:$AJ$65,"5月份已完成") -> 3 | H16: =COUNTIFS('3、电缆线路交叉互联预试'!$M$4:$M$65,"花都中心",'3、电缆线路交叉互联预试'!$AJ$4:$AJ$65,"6月份已完成") -> 0 | I16: =COUNTIFS('3、电缆线路交叉互联预试'!$M$4:$M$65,"花都中心",'3、电缆线路交叉互联预试'!$AJ$4:$AJ$65,"7月份已完成") -> 0 | J16: =COUNTIFS('3、电缆线路交叉互联预试'!$M$4:$M$65,"花都中心",'3、电缆线路交叉互联预试'!$AJ$4:$AJ$65,"8月份已完成") -> 1 | K16: =COUNTIFS('3、电缆线路交叉互联预试'!$M$4:$M$65,"花都中心",'3、电缆线路交叉互联预试'!$AJ$4:$AJ$65,"9月份已完成") -> 4 | L16: =COUNTIFS('3、电缆线路交叉互联预试'!$M$4:$M$65,"花都中心",'3、电缆线路交叉互联预试'!$AJ$4:$AJ$65,"10月份已完成") -> 3 | M16: =COUNTIFS('3、电缆线路交叉互联预试'!$M$4:$M$65,"花都中心",'3、电缆线路交叉互联预试'!$AJ$4:$AJ$65,"11月份已完成") -> 0 | N16: =COUNTIFS('3、电缆线路交叉互联预试'!$M$4:$M$65,"花都中心",'3、电缆线路交叉互联预试'!$AJ$4:$AJ$65,"12月份已完成") -> 0
B17: 天河中心 | C17: =COUNTIFS('3、电缆线路交叉互联预试'!$M$4:$M$65,"天河中心",'3、电缆线路交叉互联预试'!$AJ$4:$AJ$65,"1月份已完成") -> 3 | D17: =COUNTIFS('3、电缆线路交叉互联预试'!$M$4:$M$65,"天河中心",'3、电缆线路交叉互联预试'!$AJ$4:$AJ$65,"2月份已完成") -> 2 | E17: =COUNTIFS('3、电缆线路交叉互联预试'!$M$4:$M$65,"天河中心",'3、电缆线路交叉互联预试'!$AJ$4:$AJ$65,"3月份已完成") -> 4 | F17: =COUNTIFS('3、电缆线路交叉互联预试'!$M$4:$M$65,"天河中心",'3、电缆线路交叉互联预试'!$AJ$4:$AJ$65,"4月份已完成") -> 1 | G17: =COUNTIFS('3、电缆线路交叉互联预试'!$M$4:$M$65,"天河中心",'3、电缆线路交叉互联预试'!$AJ$4:$AJ$65,"5月份已完成") -> 1 | H17: =COUNTIFS('3、电缆线路交叉互联预试'!$M$4:$M$65,"天河中心",'3、电缆线路交叉互联预试'!$AJ$4:$AJ$65,"6月份已完成") -> 0 | I17: =COUNTIFS('3、电缆线路交叉互联预试'!$M$4:$M$65,"天河中心",'3、电缆线路交叉互联预试'!$AJ$4:$AJ$65,"7月份已完成") -> 0 | J17: =COUNTIFS('3、电缆线路交叉互联预试'!$M$4:$M$65,"天河中心",'3、电缆线路交叉互联预试'!$AJ$4:$AJ$65,"8月份已完成") -> 0 | K17: =COUNTIFS('3、电缆线路交叉互联预试'!$M$4:$M$65,"天河中心",'3、电缆线路交叉互联预试'!$AJ$4:$AJ$65,"9月份已完成") -> 0 | L17: =COUNTIFS('3、电缆线路交叉互联预试'!$M$4:$M$65,"天河中心",'3、电缆线路交叉互联预试'!$AJ$4:$AJ$65,"10月份已完成") -> 1 | M17: =COUNTIFS('3、电缆线路交叉互联预试'!$M$4:$M$65,"天河中心",'3、电缆线路交叉互联预试'!$AJ$4:$AJ$65,"11月份已完成") -> 0 | N17: =COUNTIFS('3、电缆线路交叉互联预试'!$M$4:$M$65,"天河中心",'3、电缆线路交叉互联预试'!$AJ$4:$AJ$65,"12月份已完成") -> 0
A18: 4、终端场避雷器试验 | B18: 白云中心 | C18: =COUNTIFS('4、终端场避雷器试验'!$N$4:$N$97,"白云中心",'4、终端场避雷器试验'!$AA$4:$AA$97,"1月份已完成") -> 1 | D18: =COUNTIFS('4、终端场避雷器试验'!$N$4:$N$97,"白云中心",'4、终端场避雷器试验'!$AA$4:$AA$97,"2月份已完成") -> 6 | E18: =COUNTIFS('4、终端场避雷器试验'!$N$4:$N$97,"白云中心",'4、终端场避雷器试验'!$AA$4:$AA$97,"3月份已完成") -> 15 | F18: =COUNTIFS('4、终端场避雷器试验'!$N$4:$N$97,"白云中心",'4、终端场避雷器试验'!$AA$4:$AA$97,"4月份已完成") -> 2 | G18: =COUNTIFS('4、终端场避雷器试验'!$N$4:$N$97,"白云中心",'4、终端场避雷器试验'!$AA$4:$AA$97,"5月份已完成") -> 1 | H18: =COUNTIFS('4、终端场避雷器试验'!$N$4:$N$97,"白云中心",'4、终端场避雷器试验'!$AA$4:$AA$97,"6月份已完成") -> 1 | I18: =COUNTIFS('4、终端场避雷器试验'!$N$4:$N$97,"白云中心",'4、终端场避雷器试验'!$AA$4:$AA$97,"7月份已完成") -> 0 | J18: =COUNTIFS('4、终端场避雷器试验'!$N$4:$N$97,"白云中心",'4、终端场避雷器试验'!$AA$4:$AA$97,"8月份已完成") -> 2 | K18: =COUNTIFS('4、终端场避雷器试验'!$N$4:$N$97,"白云中心",'4、终端场避雷器试验'!$AA$4:$AA$97,"9月份已完成") -> 2 | L18: =COUNTIFS('4、终端场避雷器试验'!$N$4:$N$97,"白云中心",'4、终端场避雷器试验'!$AA$4:$AA$97,"10月份已完成") -> 1 | M18: =COUNTIFS('4、终端场避雷器试验'!$N$4:$N$97,"白云中心",'4、终端场避雷器试验'!$AA$4:$AA$97,"11月份已完成") -> 0 | N18: =COUNTIFS('4、终端场避雷器试验'!$N$4:$N$97,"白云中心",'4、终端场避雷器试验'!$AA$4:$AA$97,"12月份已完成") -> 0
B19: 从化中心 | C19: =COUNTIFS('4、终端场避雷器试验'!$N$4:$N$97,"从化中心",'4、终端场避雷器试验'!$AA$4:$AA$97,"1月份已完成") -> 0 | D19: =COUNTIFS('4、终端场避雷器试验'!$N$4:$N$97,"从化中心",'4、终端场避雷器试验'!$AA$4:$AA$97,"2月份已完成") -> 0 | E19: =COUNTIFS('4、终端场避雷器试验'!$N$4:$N$97,"从化中心",'4、终端场避雷器试验'!$AA$4:$AA$97,"3月份已完成") -> 0 | F19: =COUNTIFS('4、终端场避雷器试验'!$N$4:$N$97,"从化中心",'4、终端场避雷器试验'!$AA$4:$AA$97,"4月份已完成") -> 0 | G19: =COUNTIFS('4、终端场避雷器试验'!$N$4:$N$97,"从化中心",'4、终端场避雷器试验'!$AA$4:$AA$97,"5月份已完成") -> 0 | H19: =COUNTIFS('4、终端场避雷器试验'!$N$4:$N$97,"从化中心",'4、终端场避雷器试验'!$AA$4:$AA$97,"6月份已完成") -> 0 | I19: =COUNTIFS('4、终端场避雷器试验'!$N$4:$N$97,"从化中心",'4、终端场避雷器试验'!$AA$4:$AA$97,"7月份已完成") -> 0 | J19: =COUNTIFS('4、终端场避雷器试验'!$N$4:$N$97,"从化中心",'4、终端场避雷器试验'!$AA$4:$AA$97,"8月份已完成") -> 0 | K19: =COUNTIFS('4、终端场避雷器试验'!$N$4:$N$97,"从化中心",'4、终端场避雷器试验'!$AA$4:$AA$97,"9月份已完成") -> 0 | L19: =COUNTIFS('4、终端场避雷器试验'!$N$4:$N$97,"从化中心",'4、终端场避雷器试验'!$AA$4:$AA$97,"10月份已完成") -> 0 | M19: =COUNTIFS('4、终端场避雷器试验'!$N$4:$N$97,"从化中心",'4、终端场避雷器试验'!$AA$4:$AA$97,"11月份已完成") -> 0 | N19: =COUNTIFS('4、终端场避雷器试验'!$N$4:$N$97,"从化中心",'4、终端场避雷器试验'!$AA$4:$AA$97,"12月份已完成") -> 0
B20: 花都中心 | C20: =COUNTIFS('4、终端场避雷器试验'!$N$4:$N$97,"花都中心",'4、终端场避雷器试验'!$AA$4:$AA$97,"1月份已完成") -> 1 | D20: =COUNTIFS('4、终端场避雷器试验'!$N$4:$N$97,"花都中心",'4、终端场避雷器试验'!$AA$4:$AA$97,"2月份已完成") -> 0 | E20: =COUNTIFS('4、终端场避雷器试验'!$N$4:$N$97,"花都中心",'4、终端场避雷器试验'!$AA$4:$AA$97,"3月份已完成") -> 9 | F20: =COUNTIFS('4、终端场避雷器试验'!$N$4:$N$97,"花都中心",'4、终端场避雷器试验'!$AA$4:$AA$97,"4月份已完成") -> 3 | G20: =COUNTIFS('4、终端场避雷器试验'!$N$4:$N$97,"花都中心",'4、终端场避雷器试验'!$AA$4:$AA$97,"5月份已完成") -> 1 | H20: =COUNTIFS('4、终端场避雷器试验'!$N$4:$N$97,"花都中心",'4、终端场避雷器试验'!$AA$4:$AA$97,"6月份已完成") -> 0 | I20: =COUNTIFS('4、终端场避雷器试验'!$N$4:$N$97,"花都中心",'4、终端场避雷器试验'!$AA$4:$AA$97,"7月份已完成") -> 0 | J20: =COUNTIFS('4、终端场避雷器试验'!$N$4:$N$97,"花都中心",'4、终端场避雷器试验'!$AA$4:$AA$97,"8月份已完成") -> 0 | K20: =COUNTIFS('4、终端场避雷器试验'!$N$4:$N$97,"花都中心",'4、终端场避雷器试验'!$AA$4:$AA$97,"9月份已完成") -> 2 | L20: =COUNTIFS('4、终端场避雷器试验'!$N$4:$N$97,"花都中心",'4、终端场避雷器试验'!$AA$4:$AA$97,"10月份已完成") -> 3 | M20: =COUNTIFS('4、终端场避雷器试验'!$N$4:$N$97,"花都中心",'4、终端场避雷器试验'!$AA$4:$AA$97,"11月份已完成") -> 0 | N20: =COUNTIFS('4、终端场避雷器试验'!$N$4:$N$97,"花都中心",'4、终端场避雷器试验'!$AA$4:$AA$97,"12月份已完成") -> 0
B21: 天河中心 | C21: =COUNTIFS('4、终端场避雷器试验'!$N$4:$N$97,"天河中心",'4、终端场避雷器试验'!$AA$4:$AA$97,"1月份已完成") -> 0 | D21: =COUNTIFS('4、终端场避雷器试验'!$N$4:$N$97,"天河中心",'4、终端场避雷器试验'!$AA$4:$AA$97,"2月份已完成") -> 0 | E21: =COUNTIFS('4、终端场避雷器试验'!$N$4:$N$97,"天河中心",'4、终端场避雷器试验'!$AA$4:$AA$97,"3月份已完成") -> 0 | F21: =COUNTIFS('4、终端场避雷器试验'!$N$4:$N$97,"天河中心",'4、终端场避雷器试验'!$AA$4:$AA$97,"4月份已完成") -> 2 | G21: =COUNTIFS('4、终端场避雷器试验'!$N$4:$N$97,"天河中心",'4、终端场避雷器试验'!$AA$4:$AA$97,"5月份已完成") -> 22 | H21: =COUNTIFS('4、终端场避雷器试验'!$N$4:$N$97,"天河中心",'4、终端场避雷器试验'!$AA$4:$AA$97,"6月份已完成") -> 0 | I21: =COUNTIFS('4、终端场避雷器试验'!$N$4:$N$97,"天河中心",'4、终端场避雷器试验'!$AA$4:$AA$97,"7月份已完成") -> 0 | J21: =COUNTIFS('4、终端场避雷器试验'!$N$4:$N$97,"天河中心",'4、终端场避雷器试验'!$AA$4:$AA$97,"8月份已完成") -> 0 | K21: =COUNTIFS('4、终端场避雷器试验'!$N$4:$N$97,"天河中心",'4、终端场避雷器试验'!$AA$4:$AA$97,"9月份已完成") -> 0 | L21: =COUNTIFS('4、终端场避雷器试验'!$N$4:$N$97,"天河中心",'4、终端场避雷器试验'!$AA$4:$AA$97,"10月份已完成") -> 1 | M21: =COUNTIFS('4、终端场避雷器试验'!$N$4:$N$97,"天河中心",'4、终端场避雷器试验'!$AA$4:$AA$97,"11月份已完成") -> 0 | N21: =COUNTIFS('4、终端场避雷器试验'!$N$4:$N$97,"天河中心",'4、终端场避雷器试验'!$AA$4:$AA$97,"12月份已完成") -> 0
A22: 5、电缆护套环流检测 | B22: 白云中心 | C22: =COUNTIFS('5、电缆护套环流检测'!$L$4:$L$815,"白云中心",'5、电缆护套环流检测'!$Y$4:$Y$815,"1月份已完成") -> 91 | D22: =COUNTIFS('5、电缆护套环流检测'!$L$4:$L$815,"白云中心",'5、电缆护套环流检测'!$Y$4:$Y$815,"2月份已完成") -> 5 | E22: =COUNTIFS('5、电缆护套环流检测'!$L$4:$L$815,"白云中心",'5、电缆护套环流检测'!$Y$4:$Y$815,"3月份已完成") -> 29 | F22: =COUNTIFS('5、电缆护套环流检测'!$L$4:$L$815,"白云中心",'5、电缆护套环流检测'!$Y$4:$Y$815,"4月份已完成") -> 9 | G22: =COUNTIFS('5、电缆护套环流检测'!$L$4:$L$815,"白云中心",'5、电缆护套环流检测'!$Y$4:$Y$815,"5月份已完成") -> 14 | H22: =COUNTIFS('5、电缆护套环流检测'!$L$4:$L$815,"白云中心",'5、电缆护套环流检测'!$Y$4:$Y$815,"6月份已完成") -> 20 | I22: =COUNTIFS('5、电缆护套环流检测'!$L$4:$L$815,"白云中心",'5、电缆护套环流检测'!$Y$4:$Y$815,"7月份已完成") -> 66 | J22: =COUNTIFS('5、电缆护套环流检测'!$L$4:$L$815,"白云中心",'5、电缆护套环流检测'!$Y$4:$Y$815,"8月份已完成") -> 7 | K22: =COUNTIFS('5、电缆护套环流检测'!$L$4:$L$815,"白云中心",'5、电缆护套环流检测'!$Y$4:$Y$815,"9月份已完成") -> 30 | L22: =COUNTIFS('5、电缆护套环流检测'!$L$4:$L$815,"白云中心",'5、电缆护套环流检测'!$Y$4:$Y$815,"10月份已完成") -> 16 | M22: =COUNTIFS('5、电缆护套环流检测'!$L$4:$L$815,"白云中心",'5、电缆护套环流检测'!$Y$4:$Y$815,"11月份已完成") -> 0 | N22: =COUNTIFS('5、电缆护套环流检测'!$L$4:$L$815,"白云中心",'5、电缆护套环流检测'!$Y$4:$Y$815,"12月份已完成") -> 0
B23: 从化中心 | C23: =COUNTIFS('5、电缆护套环流检测'!$L$4:$L$815,"从化中心",'5、电缆护套环流检测'!$Y$4:$Y$815,"1月份已完成") -> 0 | D23: =COUNTIFS('5、电缆护套环流检测'!$L$4:$L$815,"从化中心",'5、电缆护套环流检测'!$Y$4:$Y$815,"2月份已完成") -> 0 | E23: =COUNTIFS('5、电缆护套环流检测'!$L$4:$L$815,"从化中心",'5、电缆护套环流检测'!$Y$4:$Y$815,"3月份已完成") -> 0 | F23: =COUNTIFS('5、电缆护套环流检测'!$L$4:$L$815,"从化中心",'5、电缆护套环流检测'!$Y$4:$Y$815,"4月份已完成") -> 0 | G23: =COUNTIFS('5、电缆护套环流检测'!$L$4:$L$815,"从化中心",'5、电缆护套环流检测'!$Y$4:$Y$815,"5月份已完成") -> 6 | H23: =COUNTIFS('5、电缆护套环流检测'!$L$4:$L$815,"从化中心",'5、电缆护套环流检测'!$Y$4:$Y$815,"6月份已完成") -> 9 | I23: =COUNTIFS('5、电缆护套环流检测'!$L$4:$L$815,"从化中心",'5、电缆护套环流检测'!$Y$4:$Y$815,"7月份已完成") -> 0 | J23: =COUNTIFS('5、电缆护套环流检测'!$L$4:$L$815,"从化中心",'5、电缆护套环流检测'!$Y$4:$Y$815,"8月份已完成") -> 0 | K23: =COUNTIFS('5、电缆护套环流检测'!$L$4:$L$815,"从化中心",'5、电缆护套环流检测'!$Y$4:$Y$815,"9月份已完成") -> 0 | L23: =COUNTIFS('5、电缆护套环流检测'!$L$4:$L$815,"从化中心",'5、电缆护套环流检测'!$Y$4:$Y$815,"10月份已完成") -> 0 | M23: =COUNTIFS('5、电缆护套环流检测'!$L$4:$L$815,"从化中心",'5、电缆护套环流检测'!$Y$4:$Y$815,"11月份已完成") -> 0 | N23: =COUNTIFS('5、电缆护套环流检测'!$L$4:$L$815,"从化中心",'5、电缆护套环流检测'!$Y$4:$Y$815,"12月份已完成") -> 0
B24: 花都中心 | C24: =COUNTIFS('5、电缆护套环流检测'!$L$4:$L$815,"花都中心",'5、电缆护套环流检测'!$Y$4:$Y$815,"1月份已完成") -> 13 | D24: =COUNTIFS('5、电缆护套环流检测'!$L$4:$L$815,"花都中心",'5、电缆护套环流检测'!$Y$4:$Y$815,"2月份已完成") -> 8 | E24: =COUNTIFS('5、电缆护套环流检测'!$L$4:$L$815,"花都中心",'5、电缆护套环流检测'!$Y$4:$Y$815,"3月份已完成") -> 0 | F24: =COUNTIFS('5、电缆护套环流检测'!$L$4:$L$815,"花都中心",'5、电缆护套环流检测'!$Y$4:$Y$815,"4月份已完成") -> 21 | G24: =COUNTIFS('5、电缆护套环流检测'!$L$4:$L$815,"花都中心",'5、电缆护套环流检测'!$Y$4:$Y$815,"5月份已完成") -> 33 | H24: =COUNTIFS('5、电缆护套环流检测'!$L$4:$L$815,"花都中心",'5、电缆护套环流检测'!$Y$4:$Y$815,"6月份已完成") -> 5 | I24: =COUNTIFS('5、电缆护套环流检测'!$L$4:$L$815,"花都中心",'5、电缆护套环流检测'!$Y$4:$Y$815,"7月份已完成") -> 0 | J24: =COUNTIFS('5、电缆护套环流检测'!$L$4:$L$815,"花都中心",'5、电缆护套环流检测'!$Y$4:$Y$815,"8月份已完成") -> 6 | K24: =COUNTIFS('5、电缆护套环流检测'!$L$4:$L$815,"花都中心",'5、电缆护套环流检测'!$Y$4:$Y$815,"9月份已完成") -> 11 | L24: =COUNTIFS('5、电缆护套环流检测'!$L$4:$L$815,"花都中心",'5、电缆护套环流检测'!$Y$4:$Y$815,"10月份已完成") -> 10 | M24: =COUNTIFS('5、电缆护套环流检测'!$L$4:$L$815,"花都中心",'5、电缆护套环流检测'!$Y$4:$Y$815,"12月份已完成") -> 0 | N24: =COUNTIFS('5、电缆护套环流检测'!$L$4:$L$815,"花都中心",'5、电缆护套环流检测'!$Y$4:$Y$815,"12月份已完成") -> 0
B25: 天河中心 | C25: =COUNTIFS('5、电缆护套环流检测'!$L$4:$L$815,"天河中心",'5、电缆护套环流检测'!$Y$4:$Y$815,"1月份已完成") -> 61 | D25: =COUNTIFS('5、电缆护套环流检测'!$L$4:$L$815,"天河中心",'5、电缆护套环流检测'!$Y$4:$Y$815,"2月份已完成") -> 6 | E25: =COUNTIFS('5、电缆护套环流检测'!$L$4:$L$815,"天河中心",'5、电缆护套环流检测'!$Y$4:$Y$815,"3月份已完成") -> 42 | F25: =COUNTIFS('5、电缆护套环流检测'!$L$4:$L$815,"天河中心",'5、电缆护套环流检测'!$Y$4:$Y$815,"4月份已完成") -> 2 | G25: =COUNTIFS('5、电缆护套环流检测'!$L$4:$L$815,"天河中心",'5、电缆护套环流检测'!$Y$4:$Y$815,"5月份已完成") -> 42 | H25: =COUNTIFS('5、电缆护套环流检测'!$L$4:$L$815,"天河中心",'5、电缆护套环流检测'!$Y$4:$Y$815,"6月份已完成") -> 2 | I25: =COUNTIFS('5、电缆护套环流检测'!$L$4:$L$815,"天河中心",'5、电缆护套环流检测'!$Y$4:$Y$815,"7月份已完成") -> 64 | J25: =COUNTIFS('5、电缆护套环流检测'!$L$4:$L$815,"天河中心",'5、电缆护套环流检测'!$Y$4:$Y$815,"8月份已完成") -> 2 | K25: =COUNTIFS('5、电缆护套环流检测'!$L$4:$L$815,"天河中心",'5、电缆护套环流检测'!$Y$4:$Y$815,"9月份已完成") -> 38 | L25: =COUNTIFS('5、电缆护套环流检测'!$L$4:$L$815,"天河中心",'5、电缆护套环流检测'!$Y$4:$Y$815,"10月份已完成") -> 6 | M25: =COUNTIFS('5、电缆护套环流检测'!$L$4:$L$815,"天河中心",'5、电缆护套环流检测'!$Y$4:$Y$815,"11月份已完成") -> 0 | N25: =COUNTIFS('5、电缆护套环流检测'!$L$4:$L$815,"天河中心",'5、电缆护套环流检测'!$Y$4:$Y$815,"12月份已完成") -> 0
A26: 6、电缆终端红外检测 | B26: 白云中心 | C26: =COUNTIFS('6、电缆终端红外检测'!$L$4:$L$658,"白云中心",'6、电缆终端红外检测'!$Y$4:$Y$658,"1月份已完成") -> 68 | D26: =COUNTIFS('6、电缆终端红外检测'!$L$4:$L$658,"白云中心",'6、电缆终端红外检测'!$Y$4:$Y$658,"2月份已完成") -> 6 | E26: =COUNTIFS('6、电缆终端红外检测'!$L$4:$L$658,"白云中心",'6、电缆终端红外检测'!$Y$4:$Y$658,"3月份已完成") -> 20 | F26: =COUNTIFS('6、电缆终端红外检测'!$L$4:$L$658,"白云中心",'6、电缆终端红外检测'!$Y$4:$Y$658,"4月份已完成") -> 9 | G26: =COUNTIFS('6、电缆终端红外检测'!$L$4:$L$658,"白云中心",'6、电缆终端红外检测'!$Y$4:$Y$658,"5月份已完成") -> 11 | H26: =COUNTIFS('6、电缆终端红外检测'!$L$4:$L$658,"白云中心",'6、电缆终端红外检测'!$Y$4:$Y$658,"6月份已完成") -> 21 | I26: =COUNTIFS('6、电缆终端红外检测'!$L$4:$L$658,"白云中心",'6、电缆终端红外检测'!$Y$4:$Y$658,"7月份已完成") -> 45 | J26: =COUNTIFS('6、电缆终端红外检测'!$L$4:$L$658,"白云中心",'6、电缆终端红外检测'!$Y$4:$Y$658,"8月份已完成") -> 6 | K26: =COUNTIFS('6、电缆终端红外检测'!$L$4:$L$658,"白云中心",'6、电缆终端红外检测'!$Y$4:$Y$658,"9月份已完成") -> 18 | L26: =COUNTIFS('6、电缆终端红外检测'!$L$4:$L$658,"白云中心",'6、电缆终端红外检测'!$Y$4:$Y$658,"10月份已完成") -> 18 | M26: =COUNTIFS('6、电缆终端红外检测'!$L$4:$L$658,"白云中心",'6、电缆终端红外检测'!$Y$4:$Y$658,"11月份已完成") -> 0 | N26: =COUNTIFS('6、电缆终端红外检测'!$L$4:$L$658,"白云中心",'6、电缆终端红外检测'!$Y$4:$Y$658,"12月份已完成") -> 0
B27: 从化中心 | C27: =COUNTIFS('6、电缆终端红外检测'!$L$4:$L$658,"从化中心",'6、电缆终端红外检测'!$Y$4:$Y$658,"1月份已完成") -> 0 | D27: =COUNTIFS('6、电缆终端红外检测'!$L$4:$L$658,"从化中心",'6、电缆终端红外检测'!$Y$4:$Y$658,"2月份已完成") -> 0 | E27: =COUNTIFS('6、电缆终端红外检测'!$L$4:$L$658,"从化中心",'6、电缆终端红外检测'!$Y$4:$Y$658,"3月份已完成") -> 0 | F27: =COUNTIFS('6、电缆终端红外检测'!$L$4:$L$658,"从化中心",'6、电缆终端红外检测'!$Y$4:$Y$658,"4月份已完成") -> 0 | G27: =COUNTIFS('6、电缆终端红外检测'!$L$4:$L$658,"从化中心",'6、电缆终端红外检测'!$Y$4:$Y$658,"5月份已完成") -> 5 | H27: =COUNTIFS('6、电缆终端红外检测'!$L$4:$L$658,"从化中心",'6、电缆终端红外检测'!$Y$4:$Y$658,"6月份已完成") -> 9 | I27: =COUNTIFS('6、电缆终端红外检测'!$L$4:$L$658,"从化中心",'6、电缆终端红外检测'!$Y$4:$Y$658,"7月份已完成") -> 0 | J27: =COUNTIFS('6、电缆终端红外检测'!$L$4:$L$658,"从化中心",'6、电缆终端红外检测'!$Y$4:$Y$658,"8月份已完成") -> 0 | K27: =COUNTIFS('6、电缆终端红外检测'!$L$4:$L$658,"从化中心",'6、电缆终端红外检测'!$Y$4:$Y$658,"9月份已完成") -> 0 | L27: =COUNTIFS('6、电缆终端红外检测'!$L$4:$L$658,"从化中心",'6、电缆终端红外检测'!$Y$4:$Y$658,"10月份已完成") -> 0 | M27: =COUNTIFS('6、电缆终端红外检测'!$L$4:$L$658,"从化中心",'6、电缆终端红外检测'!$Y$4:$Y$658,"11月份已完成") -> 0 | N27: =COUNTIFS('6、电缆终端红外检测'!$L$4:$L$658,"从化中心",'6、电缆终端红外检测'!$Y$4:$Y$658,"1月份已完成") -> 0
B28: 花都中心 | C28: =COUNTIFS('6、电缆终端红外检测'!$L$4:$L$658,"花都中心",'6、电缆终端红外检测'!$Y$4:$Y$658,"1月份已完成") -> 18 | D28: =COUNTIFS('6、电缆终端红外检测'!$L$4:$L$658,"花都中心",'6、电缆终端红外检测'!$Y$4:$Y$658,"2月份已完成") -> 5 | E28: =COUNTIFS('6、电缆终端红外检测'!$L$4:$L$658,"花都中心",'6、电缆终端红外检测'!$Y$4:$Y$658,"3月份已完成") -> 0 | F28: =COUNTIFS('6、电缆终端红外检测'!$L$4:$L$658,"花都中心",'6、电缆终端红外检测'!$Y$4:$Y$658,"4月份已完成") -> 24 | G28: =COUNTIFS('6、电缆终端红外检测'!$L$4:$L$658,"花都中心",'6、电缆终端红外检测'!$Y$4:$Y$658,"5月份已完成") -> 31 | H28: =COUNTIFS('6、电缆终端红外检测'!$L$4:$L$658,"花都中心",'6、电缆终端红外检测'!$Y$4:$Y$658,"6月份已完成") -> 5 | I28: =COUNTIFS('6、电缆终端红外检测'!$L$4:$L$658,"花都中心",'6、电缆终端红外检测'!$Y$4:$Y$658,"7月份已完成") -> 0 | J28: =COUNTIFS('6、电缆终端红外检测'!$L$4:$L$658,"花都中心",'6、电缆终端红外检测'!$Y$4:$Y$658,"8月份已完成") -> 4 | K28: =COUNTIFS('6、电缆终端红外检测'!$L$4:$L$658,"花都中心",'6、电缆终端红外检测'!$Y$4:$Y$658,"9份已完成") -> 0 | L28: =COUNTIFS('6、电缆终端红外检测'!$L$4:$L$658,"花都中心",'6、电缆终端红外检测'!$Y$4:$Y$658,"10月份已完成") -> 9 | M28: =COUNTIFS('6、电缆终端红外检测'!$L$4:$L$658,"花都中心",'6、电缆终端红外检测'!$Y$4:$Y$658,"11月份已完成") -> 0 | N28: =COUNTIFS('6、电缆终端红外检测'!$L$4:$L$658,"花都中心",'6、电缆终端红外检测'!$Y$4:$Y$658,"12月份已完成") -> 0
B29: 天河中心 | C29: =COUNTIFS('6、电缆终端红外检测'!$L$4:$L$658,"天河中心",'6、电缆终端红外检测'!$Y$4:$Y$658,"1月份已完成") -> 31 | D29: =COUNTIFS('6、电缆终端红外检测'!$L$4:$L$658,"天河中心",'6、电缆终端红外检测'!$Y$4:$Y$658,"2月份已完成") -> 5 | E29: =COUNTIFS('6、电缆终端红外检测'!$L$4:$L$658,"天河中心",'6、电缆终端红外检测'!$Y$4:$Y$658,"3月份已完成") -> 28 | F29: =COUNTIFS('6、电缆终端红外检测'!$L$4:$L$658,"天河中心",'6、电缆终端红外检测'!$Y$4:$Y$658,"4月份已完成") -> 2 | G29: =COUNTIFS('6、电缆终端红外检测'!$L$4:$L$658,"天河中心",'6、电缆终端红外检测'!$Y$4:$Y$658,"5月份已完成") -> 29 | H29: =COUNTIFS('6、电缆终端红外检测'!$L$4:$L$658,"天河中心",'6、电缆终端红外检测'!$Y$4:$Y$658,"6月份已完成") -> 2 | I29: =COUNTIFS('6、电缆终端红外检测'!$L$4:$L$658,"天河中心",'6、电缆终端红外检测'!$Y$4:$Y$658,"7月份已完成") -> 37 | J29: =COUNTIFS('6、电缆终端红外检测'!$L$4:$L$658,"天河中心",'6、电缆终端红外检测'!$Y$4:$Y$658,"9月份已完成") -> 25 | K29: =COUNTIFS('6、电缆终端红外检测'!$L$4:$L$658,"天河中心",'6、电缆终端红外检测'!$Y$4:$Y$658,"9月份已完成") -> 25 | L29: =COUNTIFS('6、电缆终端红外检测'!$L$4:$L$658,"天河中心",'6、电缆终端红外检测'!$Y$4:$Y$658,"10月份已完成") -> 5 | M29: =COUNTIFS('6、电缆终端红外检测'!$L$4:$L$658,"天河中心",'6、电缆终端红外检测'!$Y$4:$Y$658,"11月份已完成") -> 0 | N29: =COUNTIFS('6、电缆终端红外检测'!$L$4:$L$658,"天河中心",'6、电缆终端红外检测'!$Y$4:$Y$658,"12月份已完成") -> 0
A30: 7、避雷器红外检测 | B30: 白云中心 | C30: =COUNTIFS('7、避雷器红外检测'!$L$4:$L$375,"白云中心",'7、避雷器红外检测'!$Y$4:$Y$375,"1月份已完成") -> 43 | D30: =COUNTIFS('7、避雷器红外检测'!$L$4:$L$375,"白云中心",'7、避雷器红外检测'!$Y$4:$Y$375,"2月份已完成") -> 6 | E30: =COUNTIFS('7、避雷器红外检测'!$L$4:$L$375,"白云中心",'7、避雷器红外检测'!$Y$4:$Y$375,"3月份已完成") -> 5 | F30: =COUNTIFS('7、避雷器红外检测'!$L$4:$L$375,"白云中心",'7、避雷器红外检测'!$Y$4:$Y$375,"4月份已完成") -> 7 | G30: =COUNTIFS('7、避雷器红外检测'!$L$4:$L$375,"白云中心",'7、避雷器红外检测'!$Y$4:$Y$375,"5月份已完成") -> 7 | H30: =COUNTIFS('7、避雷器红外检测'!$L$4:$L$375,"白云中心",'7、避雷器红外检测'!$Y$4:$Y$375,"6月份已完成") -> 11 | I30: =COUNTIFS('7、避雷器红外检测'!$L$4:$L$375,"白云中心",'7、避雷器红外检测'!$Y$4:$Y$375,"7月份已完成") -> 26 | J30: =COUNTIFS('7、避雷器红外检测'!$L$4:$L$375,"白云中心",'7、避雷器红外检测'!$Y$4:$Y$375,"8月份已完成") -> 6 | K30: =COUNTIFS('7、避雷器红外检测'!$L$4:$L$375,"白云中心",'7、避雷器红外检测'!$Y$4:$Y$375,"9月份已完成") -> 5 | L30: =COUNTIFS('7、避雷器红外检测'!$L$4:$L$375,"白云中心",'7、避雷器红外检测'!$Y$4:$Y$375,"10月份已完成") -> 15 | M30: =COUNTIFS('7、避雷器红外检测'!$L$4:$L$375,"白云中心",'7、避雷器红外检测'!$Y$4:$Y$375,"11月份已完成") -> 0 | N30: =COUNTIFS('7、避雷器红外检测'!$L$4:$L$375,"白云中心",'7、避雷器红外检测'!$Y$4:$Y$375,"12月份已完成") -> 0
B31: 从化中心 | C31: =COUNTIFS('7、避雷器红外检测'!$L$4:$L$375,"从化中心",'7、避雷器红外检测'!$Y$4:$Y$375,"1月份已完成") -> 1 | D31: =COUNTIFS('7、避雷器红外检测'!$L$4:$L$375,"从化中心",'7、避雷器红外检测'!$Y$4:$Y$375,"2月份已完成") -> 2 | E31: =COUNTIFS('7、避雷器红外检测'!$L$4:$L$375,"从化中心",'7、避雷器红外检测'!$Y$4:$Y$375,"3月份已完成") -> 0 | F31: =COUNTIFS('7、避雷器红外检测'!$L$4:$L$375,"从化中心",'7、避雷器红外检测'!$Y$4:$Y$375,"4月份已完成") -> 3 | G31: =COUNTIFS('7、避雷器红外检测'!$L$4:$L$375,"从化中心",'7、避雷器红外检测'!$Y$4:$Y$375,"5月份已完成") -> 0 | H31: =COUNTIFS('7、避雷器红外检测'!$L$4:$L$375,"从化中心",'7、避雷器红外检测'!$Y$4:$Y$375,"6月份已完成") -> 9 | I31: =COUNTIFS('7、避雷器红外检测'!$L$4:$L$375,"从化中心",'7、避雷器红外检测'!$Y$4:$Y$375,"7月份已完成") -> 0 | J31: =COUNTIFS('7、避雷器红外检测'!$L$4:$L$375,"从化中心",'7、避雷器红外检测'!$Y$4:$Y$375,"8月份已完成") -> 0 | K31: =COUNTIFS('7、避雷器红外检测'!$L$4:$L$375,"从化中心",'7、避雷器红外检测'!$Y$4:$Y$375,"9月份已完成") -> 0 | L31: =COUNTIFS('7、避雷器红外检测'!$L$4:$L$375,"从化中心",'7、避雷器红外检测'!$Y$4:$Y$375,"10月份已完成") -> 0 | M31: =COUNTIFS('7、避雷器红外检测'!$L$4:$L$375,"从化中心",'7、避雷器红外检测'!$Y$4:$Y$375,"11月份已完成") -> 0 | N31: =COUNTIFS('7、避雷器红外检测'!$L$4:$L$375,"从化中心",'7、避雷器红外检测'!$Y$4:$Y$375,"12月份已完成") -> 0
B32: 花都中心 | C32: =COUNTIFS('7、避雷器红外检测'!$L$4:$L$375,"花都中心",'7、避雷器红外检测'!$Y$4:$Y$375,"1月份已完成") -> 4 | D32: =COUNTIFS('7、避雷器红外检测'!$L$4:$L$375,"花都中心",'7、避雷器红外检测'!$Y$4:$Y$375,"2月份已完成") -> 1 | E32: =COUNTIFS('7、避雷器红外检测'!$L$4:$L$375,"花都中心",'7、避雷器红外检测'!$Y$4:$Y$375,"3月份已完成") -> 8 | F32: =COUNTIFS('7、避雷器红外检测'!$L$4:$L$375,"花都中心",'7、避雷器红外检测'!$Y$4:$Y$375,"4月份已完成") -> 13 | G32: =COUNTIFS('7、避雷器红外检测'!$L$4:$L$375,"花都中心",'7、避雷器红外检测'!$Y$4:$Y$375,"5月份已完成") -> 22 | H32: =COUNTIFS('7、避雷器红外检测'!$L$4:$L$375,"花都中心",'7、避雷器红外检测'!$Y$4:$Y$375,"6月份已完成") -> 1 | I32: =COUNTIFS('7、避雷器红外检测'!$L$4:$L$375,"花都中心",'7、避雷器红外检测'!$Y$4:$Y$375,"7月份已完成") -> 0 | J32: =COUNTIFS('7、避雷器红外检测'!$L$4:$L$375,"花都中心",'7、避雷器红外检测'!$Y$4:$Y$375,"8月份已完成") -> 1 | K32: =COUNTIFS('7、避雷器红外检测'!$L$4:$L$375,"花都中心",'7、避雷器红外检测'!$Y$4:$Y$375,"9月份已完成") -> 15 | L32: =COUNTIFS('7、避雷器红外检测'!$L$4:$L$375,"花都中心",'7、避雷器红外检测'!$Y$4:$Y$375,"10月份已完成") -> 1 | M32: =COUNTIFS('7、避雷器红外检测'!$L$4:$L$375,"花都中心",'7、避雷器红外检测'!$Y$4:$Y$375,"11月份已完成") -> 0 | N32: =COUNTIFS('7、避雷器红外检测'!$L$4:$L$375,"花都中心",'7、避雷器红外检测'!$Y$4:$Y$375,"12月份已完成") -> 0
B33: 天河中心 | C33: =COUNTIFS('7、避雷器红外检测'!$L$4:$L$375,"天河中心",'7、避雷器红外检测'!$Y$4:$Y$375,"1月份已完成") -> 11 | D33: =COUNTIFS('7、避雷器红外检测'!$L$4:$L$375,"天河中心",'7、避雷器红外检测'!$Y$4:$Y$375,"2月份已完成") -> 5 | E33: =COUNTIFS('7、避雷器红外检测'!$L$4:$L$375,"天河中心",'7、避雷器红外检测'!$Y$4:$Y$375,"3月份已完成") -> 14 | F33: =COUNTIFS('7、避雷器红外检测'!$L$4:$L$375,"天河中心",'7、避雷器红外检测'!$Y$4:$Y$375,"4月份已完成") -> 2 | G33: =COUNTIFS('7、避雷器红外检测'!$L$4:$L$375,"天河中心",'7、避雷器红外检测'!$Y$4:$Y$375,"5月份已完成") -> 12 | H33: =COUNTIFS('7、避雷器红外检测'!$L$4:$L$375,"天河中心",'7、避雷器红外检测'!$Y$4:$Y$375,"6月份已完成") -> 2 | I33: =COUNTIFS('7、避雷器红外检测'!$L$4:$L$375,"天河中心",'7、避雷器红外检测'!$Y$4:$Y$375,"7月份已完成") -> 18 | J33: =COUNTIFS('7、避雷器红外检测'!$L$4:$L$375,"天河中心",'7、避雷器红外检测'!$Y$4:$Y$375,"8月份已完成") -> 2 | K33: =COUNTIFS('7、避雷器红外检测'!$L$4:$L$375,"天河中心",'7、避雷器红外检测'!$Y$4:$Y$375,"9月份已完成") -> 12 | L33: =COUNTIFS('7、避雷器红外检测'!$L$4:$L$375,"天河中心",'7、避雷器红外检测'!$Y$4:$Y$375,"10月份已完成") -> 4 | M33: =COUNTIFS('7、避雷器红外检测'!$L$4:$L$375,"天河中心",'7、避雷器红外检测'!$Y$4:$Y$375,"11月份已完成") -> 0 | N33: =COUNTIFS('7、避雷器红外检测'!$L$4:$L$375,"天河中心",'7、避雷器红外检测'!$Y$4:$Y$375,"12月份已完成") -> 0
A34: 8、非直埋式中间接头红外检测 | B34: 白云中心 | C34: =COUNTIFS('8、非直埋式中间接头红外检测 '!$L$4:$L$505,"白云中心",'8、非直埋式中间接头红外检测 '!$Y$4:$Y$505,"1月份已完成") -> 5 | D34: =COUNTIFS('8、非直埋式中间接头红外检测 '!$L$4:$L$505,"白云中心",'8、非直埋式中间接头红外检测 '!$Y$4:$Y$505,"2月份已完成") -> 26 | E34: =COUNTIFS('8、非直埋式中间接头红外检测 '!$L$4:$L$505,"白云中心",'8、非直埋式中间接头红外检测 '!$Y$4:$Y$505,"3月份已完成") -> 6 | F34: =COUNTIFS('8、非直埋式中间接头红外检测 '!$L$4:$L$505,"白云中心",'8、非直埋式中间接头红外检测 '!$Y$4:$Y$505,"4月份已完成") -> 16 | G34: =COUNTIFS('8、非直埋式中间接头红外检测 '!$L$4:$L$505,"白云中心",'8、非直埋式中间接头红外检测 '!$Y$4:$Y$505,"5月份已完成") -> 1 | H34: =COUNTIFS('8、非直埋式中间接头红外检测 '!$L$4:$L$505,"白云中心",'8、非直埋式中间接头红外检测 '!$Y$4:$Y$505,"6月份已完成") -> 13 | I34: =COUNTIFS('8、非直埋式中间接头红外检测 '!$L$4:$L$505,"白云中心",'8、非直埋式中间接头红外检测 '!$Y$4:$Y$505,"7月份已完成") -> 5 | J34: =COUNTIFS('8、非直埋式中间接头红外检测 '!$L$4:$L$505,"白云中心",'8、非直埋式中间接头红外检测 '!$Y$4:$Y$505,"8月份已完成") -> 33 | K34: =COUNTIFS('8、非直埋式中间接头红外检测 '!$L$4:$L$505,"白云中心",'8、非直埋式中间接头红外检测 '!$Y$4:$Y$505,"9月份已完成") -> 3 | L34: =COUNTIFS('8、非直埋式中间接头红外检测 '!$L$4:$L$505,"白云中心",'8、非直埋式中间接头红外检测 '!$Y$4:$Y$505,"10月份已完成") -> 13 | M34: =COUNTIFS('8、非直埋式中间接头红外检测 '!$L$4:$L$505,"白云中心",'8、非直埋式中间接头红外检测 '!$Y$4:$Y$505,"11月份已完成") -> 0 | N34: =COUNTIFS('8、非直埋式中间接头红外检测 '!$L$4:$L$505,"白云中心",'8、非直埋式中间接头红外检测 '!$Y$4:$Y$505,"12月份已完成") -> 0
B35: 从化中心 | C35: =COUNTIFS('8、非直埋式中间接头红外检测 '!$L$4:$L$505,"从化中心",'8、非直埋式中间接头红外检测 '!$Y$4:$Y$505,"1月份已完成") -> 0 | D35: =COUNTIFS('8、非直埋式中间接头红外检测 '!$L$4:$L$505,"从化中心",'8、非直埋式中间接头红外检测 '!$Y$4:$Y$505,"2月份已完成") -> 0 | E35: =COUNTIFS('8、非直埋式中间接头红外检测 '!$L$4:$L$505,"从化中心",'8、非直埋式中间接头红外检测 '!$Y$4:$Y$505,"3月份已完成") -> 0 | F35: =COUNTIFS('8、非直埋式中间接头红外检测 '!$L$4:$L$505,"从化中心",'8、非直埋式中间接头红外检测 '!$Y$4:$Y$505,"4月份已完成") -> 0 | G35: =COUNTIFS('8、非直埋式中间接头红外检测 '!$L$4:$L$505,"从化中心",'8、非直埋式中间接头红外检测 '!$Y$4:$Y$505,"5月份已完成") -> 0 | H35: =COUNTIFS('8、非直埋式中间接头红外检测 '!$L$4:$L$505,"从化中心",'8、非直埋式中间接头红外检测 '!$Y$4:$Y$505,"6月份已完成") -> 0 | I35: =COUNTIFS('8、非直埋式中间接头红外检测 '!$L$4:$L$505,"从化中心",'8、非直埋式中间接头红外检测 '!$Y$4:$Y$505,"7月份已完成") -> 0 | J35: =COUNTIFS('8、非直埋式中间接头红外检测 '!$L$4:$L$505,"从化中心",'8、非直埋式中间接头红外检测 '!$Y$4:$Y$505,"8月份已完成") -> 0 | K35: =COUNTIFS('8、非直埋式中间接头红外检测 '!$L$4:$L$505,"从化中心",'8、非直埋式中间接头红外检测 '!$Y$4:$Y$505,"9月份已完成") -> 0 | L35: =COUNTIFS('8、非直埋式中间接头红外检测 '!$L$4:$L$505,"从化中心",'8、非直埋式中间接头红外检测 '!$Y$4:$Y$505,"10月份已完成") -> 0 | M35: =COUNTIFS('8、非直埋式中间接头红外检测 '!$L$4:$L$505,"从化中心",'8、非直埋式中间接头红外检测 '!$Y$4:$Y$505,"11月份已完成") -> 0 | N35: =COUNTIFS('8、非直埋式中间接头红外检测 '!$L$4:$L$505,"从化中心",'8、非直埋式中间接头红外检测 '!$Y$4:$Y$505,"12月份已完成") -> 0
B36: 花都中心 | C36: =COUNTIFS('8、非直埋式中间接头红外检测 '!$L$4:$L$505,"花都中心",'8、非直埋式中间接头红外检测 '!$Y$4:$Y$505,"1月份已完成") -> 13 | D36: =COUNTIFS('8、非直埋式中间接头红外检测 '!$L$4:$L$505,"花都中心",'8、非直埋式中间接头红外检测 '!$Y$4:$Y$505,"2月份已完成") -> 2 | E36: =COUNTIFS('8、非直埋式中间接头红外检测 '!$L$4:$L$505,"花都中心",'8、非直埋式中间接头红外检测 '!$Y$4:$Y$505,"3月份已完成") -> 0 | F36: =COUNTIFS('8、非直埋式中间接头红外检测 '!$L$4:$L$505,"花都中心",'8、非直埋式中间接头红外检测 '!$Y$4:$Y$505,"4月份已完成") -> 2 | G36: =COUNTIFS('8、非直埋式中间接头红外检测 '!$L$4:$L$505,"花都中心",'8、非直埋式中间接头红外检测 '!$Y$4:$Y$505,"5月份已完成") -> 6 | H36: =COUNTIFS('8、非直埋式中间接头红外检测 '!$L$4:$L$505,"花都中心",'8、非直埋式中间接头红外检测 '!$Y$4:$Y$505,"6月份已完成") -> 16 | I36: =COUNTIFS('8、非直埋式中间接头红外检测 '!$L$4:$L$505,"花都中心",'8、非直埋式中间接头红外检测 '!$Y$4:$Y$505,"7月份已完成") -> 0 | J36: =COUNTIFS('8、非直埋式中间接头红外检测 '!$L$4:$L$505,"花都中心",'8、非直埋式中间接头红外检测 '!$Y$4:$Y$505,"8月份已完成") -> 13 | K36: =COUNTIFS('8、非直埋式中间接头红外检测 '!$L$4:$L$505,"花都中心",'8、非直埋式中间接头红外检测 '!$Y$4:$Y$505,"9月份已完成") -> 0 | L36: =COUNTIFS('8、非直埋式中间接头红外检测 '!$L$4:$L$505,"花都中心",'8、非直埋式中间接头红外检测 '!$Y$4:$Y$505,"10月份已完成") -> 7 | M36: =COUNTIFS('8、非直埋式中间接头红外检测 '!$L$4:$L$505,"花都中心",'8、非直埋式中间接头红外检测 '!$Y$4:$Y$505,"11月份已完成") -> 0 | N36: =COUNTIFS('8、非直埋式中间接头红外检测 '!$L$4:$L$505,"花都中心",'8、非直埋式中间接头红外检测 '!$Y$4:$Y$505,"12月份已完成") -> 0
B37: 天河中心 | C37: =COUNTIFS('8、非直埋式中间接头红外检测 '!$L$4:$L$505,"天河中心",'8、非直埋式中间接头红外检测 '!$Y$4:$Y$505,"1月份已完成") -> 0 | D37: =COUNTIFS('8、非直埋式中间接头红外检测 '!$L$4:$L$505,"天河中心",'8、非直埋式中间接头红外检测 '!$Y$4:$Y$505,"2月份已完成") -> 86 | E37: =COUNTIFS('8、非直埋式中间接头红外检测 '!$L$4:$L$505,"天河中心",'8、非直埋式中间接头红外检测 '!$Y$4:$Y$505,"3月份已完成") -> 0 | F37: =COUNTIFS('8、非直埋式中间接头红外检测 '!$L$4:$L$505,"天河中心",'8、非直埋式中间接头红外检测 '!$Y$4:$Y$505,"4月份已完成") -> 24 | G37: =COUNTIFS('8、非直埋式中间接头红外检测 '!$L$4:$L$505,"天河中心",'8、非直埋式中间接头红外检测 '!$Y$4:$Y$505,"5月份已完成") -> 10 | H37: =COUNTIFS('8、非直埋式中间接头红外检测 '!$L$4:$L$505,"天河中心",'8、非直埋式中间接头红外检测 '!$Y$4:$Y$505,"6月份已完成") -> 24 | I37: =COUNTIFS('8、非直埋式中间接头红外检测 '!$L$4:$L$505,"天河中心",'8、非直埋式中间接头红外检测 '!$Y$4:$Y$505,"7月份已完成") -> 0 | J37: =COUNTIFS('8、非直埋式中间接头红外检测 '!$L$4:$L$505,"天河中心",'8、非直埋式中间接头红外检测 '!$Y$4:$Y$505,"8月份已完成") -> 76 | K37: =COUNTIFS('8、非直埋式中间接头红外检测 '!$L$4:$L$505,"天河中心",'8、非直埋式中间接头红外检测 '!$Y$4:$Y$505,"9月份已完成") -> 0 | L37: =COUNTIFS('8、非直埋式中间接头红外检测 '!$L$4:$L$505,"天河中心",'8、非直埋式中间接头红外检测 '!$Y$4:$Y$505,"10月份已完成") -> 25 | M37: =COUNTIFS('8、非直埋式中间接头红外检测 '!$L$4:$L$505,"天河中心",'8、非直埋式中间接头红外检测 '!$Y$4:$Y$505,"11月份已完成") -> 0 | N37: =COUNTIFS('8、非直埋式中间接头红外检测 '!$L$4:$L$505,"天河中心",'8、非直埋式中间接头红外检测 '!$Y$4:$Y$505,"12月份已完成") -> 0

Sheet 1、架空线路红外检测
A1: 输电管理二所2024年人机协同预试检测计划（关键和重要线路1年2测，一般和关注线路1年1测，重要交跨段1月1次）
T2: =IFERROR(VLOOKUP("*"&$F2&"*",#REF!,20,FALSE),IFERROR(VLOOKUP("*"&$F2&"*",#REF!,19,FALSE),"无")) -> 无 | U2: =IFERROR(VLOOKUP("*"&$F2&"*",#REF!,21,FALSE),IFERROR(VLOOKUP("*"&$F2&"*",#REF!,20,FALSE),"无")) -> 无 | V2: =IF(OR(U2=0,U2="无"),"",S2) | W2: =V2 | X2: =IFERROR(IF(V2/S2>0,V2/S2,""),"") | Y2: =IFERROR(W2/V2,"") | AA2: =IFERROR(VLOOKUP("*"&$F2&"*",#REF!,5,FALSE),IFERROR(VLOOKUP("*"&$F2&"*",#REF!,4,FALSE),"无")) -> 无 | AB2: =IFERROR(VLOOKUP("*"&$F2&"*",#REF!,3,FALSE),IFERROR(VLOOKUP("*"&$F2&"*",#REF!,2,FALSE),"无")) -> 无
A3: 序号 | B3: 工作类型 | C3: 计划类型 | D3: 电压等级 | E3: 线路重要度 | F3: 线路名称 | G3: 作业来源 | H3: 设备设施名称 | I3: 复合绝缘子：杆塔数量（基） | J3: 绝缘子数量（串） | K3: 导地线：杆塔数量（基） | L3: 计划开始日期 | M3: 计划结束日期 | N3: 是否停电 | O3: 责任单位 | P3: 中心负责人 | Q3: 线路专责人 | R3: 责任中心 | S3: 计划完成数 | T3: 实际开始日期 | U3: 实际结束日期 | V3: 实际完成数 | W3: 合格数量 | X3: 完成率 | Y3: 合格率 | Z3: 备注（未能按时完成原因） | AA3: 计划编号 | AB3: 线路名 | AC3: 工作内容和地点 | AD3: 符合线路段 | AE3: 杆塔数 | AF3: 完成情况 | AG3: 实际结束时间字符串筛选（仅用于统计）
A4: 1560 | B4: 预试 | C4: 考核 | D4: 500kV | E4: 关键 | F4: 蓄北线 | G4: 运维策略 | H4: 全线 | I4: 20 | J4: 103 | K4: 81 | L4: 45383 | M4: 45412 | N4: 否 | O4: 输电管理二所 | P4: 董少波 | Q4: 王年光 | R4: 从化中心 | S4: =SUM(I4:K4) -> 204 | T4: 2024-01-18 09:07:41 2024-01-12 09:00:00 2024-01-12 09:00:00 2024-01-08 09:24:20 2024-01-10 09:24:33 2024-01-09 09:15:00 2024-01-08 09:00:00 2024-02-26 08:31:00 2024-02-21 09:00:00 2024-02-21 09:00:00 2024-02-22 09:00:00 2024-02-19 09:00:00 2024-02-05 09:00:00 2024-02-06 09:00:00 2024-02-05 09:00:00 2024-02-04 09:00:00 2024-03-15 09:25:00 2024-03-25 09:22:00 2024-03-14 09:02:00 2024-03-01 08:51:00 2024-03-20 08:43:00 2024-03-20 09:39:00 2024-03-18 08:35:00 2024-03-12 08:48:00 2024-03-28 09:30:00 2024-03-21 10:09:19 2024-03-21 10:09:19 2024-03-18 09:58:25 2024-03-20 10:00:12 2024-03-20 11:01:31 2024-03-20 10:00:12 2024-03-20 11:01:31 2024-03-18 09:58:25 2024-03-19 09:39:54 2024-03-18 09:58:25 2024-03-13 09:50:14 2024-03-14 10:55:04 2024-03-14 10:55:04 2024-03-13 09:50:14 2024-03-15 10:16:25 2024-03-15 10:16:25 2024-03-11 15:57:51 2024-03-11 15:57:50 2024-03-01 08:42:00 2024-03-01 09:41:00 2024-04-30 08:50:00 2024-04-29 09:30:00 2024-04-09 09:15:00 2024-04-01 09:15:00 2024-04-01 09:21:00 2024-04-26 09:10:00 2024-04-23 09:34:00 2024-04-03 09:15:00 2024-04-01 09:20:00 2024-04-08 09:45:00 2024-04-03 09:00:00 2024-05-28 02:34:57 2024-05-31 09:15:00 2024-05-31 09:00:00 2024-05-27 09:00:00 2024-05-27 09:00:00 2024-05-27 10:00:00 2024-05-27 09:33:08 2024-05-27 09:32:28 2024-05-16 09:06:00 2024-05-08 09:00:00 2024-06-14 12:24:49 2024-06-14 10:42:36 2024-06-14 11:05:06 2024-06-14 12:03:45 2024-06-05 12:08:00 2024-06-05 10:04:37 2024-06-05 09:42:15 2024-06-04 12:06:03 2024-06-04 11:26:47 2024-06-04 10:08:15 2024-06-04 11:00:10 2024-06-28 09:26:00 2024-06-28 09:22:00 2024-06-28 09:17:00 2024-06-28 09:30:00 2024-06-26 09:28:00 2024-06-05 11:46:06 2024-06-20 09:06:00 2024-06-20 09:06:00 2024-06-14 09:08:00 2024-06-04 09:00:00 2024-06-05 09:00:00 | U4: 45309.5 | AA4: SCWH0301231224025680 SCWH0301240112000011 SCWH0301231225128252 SCWH0301231224025672 SCWH0301240110000845 SCWH0301240108013206 SCWH0301240108000571 SCWH0301240105015333 SCWH0301240105015332 SCWH0301240105015328 SCWH0301240105015329 SCWH0301240123042531 SCWH0301240123042533 SCWH0301240105015324 SCWH0301240105015319 SCWH0301240105015325 SCWH0301240222290932 SCWH0301240222290937 SCWH0301240108012938 SCWH0301240108012937 SCWH0301240108012928 SCWH0301240108012935 SCWH0301240108012931 SCWH0301240108012934 SCWH0301240108012930 SCWH0301240321000419 SCWH0301240321000373 SCWH0301240318003719 SCWH0301240320000950 SCWH0301240320000640 SCWH0301240320000930 SCWH0301240320000853 SCWH0301240109001246 SCWH0301240319000154 SCWH0301240222290929 SCWH0301240314008249 SCWH0301240314008248 SCWH0301240313008249 SCWH0301240313008245 SCWH0301240315012859 SCWH0301240315001421 SCWH0301240313007865 SCWH0301240109001507 SCWH0301240108012925 SCWH0301240108012932 SCWH0301240108001058 SCWH0301240108001062 SCWH0301240105017060 SCWH0301240108001057 SCWH0301240108001056 SCWH0301240108001067 SCWH0301240109009309 SCWH0301240323000697 SCWH0301240323000698 SCWH0301240108001066 SCWH0301240108001063 SCWH0301240422034042 SCWH0301240108012187 SCWH0301240108012186 SCWH0301240108012180 SCWH0301240108012185 SCWH0301240108012181 SCWH0301240108012191 SCWH0301240108012192 SCWH0301240108012184 SCWH0301240422034043 SCWH0301240109001294 SCWH0301240108012221 SCWH0301240105010007 SCWH0301240108001991 SCWH0301240108002172 SCWH0301240108001500 SCWH0301240109001773 SCWH0301240108002469 SCWH0301240108001499 SCWH0301240108012204 SCWH0301240109001952 SCWH0301240105010379 SCWH0301240105010631 SCWH0301240521015255 SCWH0301240105011017 SCWH0301240109001504 SCWH0301240521015256 SCWH0301240105010926 SCWH0301240105010925 SCWH0301240105010924 SCWH0301240521015254 SCWH0301240105011020 | AB4: 蓄北线 | AC4: 500kV蓄北线线路特殊巡维：一点一册无人机巡视：500kV蓄北线#139-#140（2024年1月） 500kV蓄北线导线连接位置红外测温：500kV蓄北线#101-#102塔右地线，#105-#106塔三相接头测温 500kV蓄北线导线连接处红外测温：重要交叉跨越红外测温：500kV蓄北线#98-#99塔段(2024年1月) ；接头红外测温：#99-#100塔B相 500kV蓄北线导线连接位置红外测温：500kV蓄北线#98-#99塔段、#111-#112塔段、#114-#115塔段、120-#121、#136-#137塔段每月定检测温作业（2024年1月） 500kV蓄北线导线连接位置红外测温：500kV蓄北线#141-#142塔B、C相#145-#146塔B相、#148-#149塔B、C相、#151-#152塔A相及右地线，#152-#153塔B、C相测温接头测温 500kV蓄北线导线连接位置红外测温：500kV蓄北线#130-#131塔B、C相及右地线，#134-#135塔A相、右地线#136-#137塔B、C相，#137-#138塔右地线测温接头测温 500kV蓄北线导线连接位置红外测温：500kV蓄北线#116-#117塔右地线，#118-#119塔C相测温接头测温 500kV蓄北线导线连接位置红外测温：500kV蓄北线#8-#9重要交叉跨越红外测温（2024年2月） 500kV蓄北线导线连接位置红外测温：500kV蓄北线#223-#224、#228-#229重要交叉跨越红外测温（2024年2月） 500kV蓄北线导线连接位置红外测温：500kV蓄北线#198-#199、#214-#215重要交叉跨越红外测温（2024年2月） 500kV蓄北线导线连接位置红外测温：500kV蓄北线#186-#187、#187+1-#188、#188-#189、#192-#193重要交叉跨越红外测温（2024年2月） 500kV蓄北线线路特殊巡维：一点一册无人机巡视：500kV蓄北线#139-#140（2024年2月） 500kV蓄北线导线连接位置红外测温：500kV蓄北线#98-#99塔段、#111-#112塔段、#114-#115塔段、120-#121、#136-#137塔段每月定检测温作业（2024年2月） 500kV蓄北线导线连接位置红外测温：500kV蓄北线#136-#137、#139-#140、#159-#160重要交叉跨越红外测温（2024年2月） 500kV蓄北线导线连接位置红外测温：500kV蓄北线#98-#99重要交叉跨越红外测温（2024年2月） 500kV蓄北线导线连接位置红外测温：500kV蓄北线#111-#112、#114-#115、#120-#121、#124-#125重要交叉跨越红外测温（2024年2月） 500kV蓄北线导线连接位置红外测温：500kV蓄北线#98-#99塔段、#111-#112塔段、#114-#115塔段、120-#121、#136-#137塔段每月定检测温作业（2024年3月） 500kV蓄北线、110kV森温线、110kV森温线宝珠乙支线导线连接位置红外测温：500kV蓄北线#77塔段、#174-#175塔段；110kV森温线#50-#51塔段；110kV森温线宝珠乙支线#44-#45塔段半张力预绞丝周期化定检测温作业（2024年3月） 500kV蓄北线导线连接位置红外测温：500kV蓄北线#8-#9重要交叉跨越红外测温（2024年3月） 500kV蓄北线导线连接位置红外测温：500kV蓄北线#223-#224、#228-#229重要交叉跨越红外测温（2024年3月） 500kV蓄北线导线连接位置红外测温：500kV蓄北线#192-#193重要交叉跨越红外测温（2024年3月） 500kV蓄北线、35kV良吕线导线连接位置红外测温：500kV蓄北线#186-#187、#187+1-#188、#188-#189塔段、35kV良吕线#10-#11、#19-#20、#21-#22、#32-#33重要交叉跨越红外测温（2024年3月） 500kV蓄北线导线连接位置红外测温：500kV蓄北线#136-#137、#159-#160重要交叉跨越红外测温（2024年3月） 500kV蓄北线导线连接位置红外测温：500kV蓄北线#198-#199、#214-#215重要交叉跨越红外测温（2024年3月） 500kV蓄北线、110kV流森线、110kV森良甲线、110kV森养甲线桃莲甲支线导线连接位置红外测温：500kV蓄北线#139-#140、110kV流森线#14-#15、110kV森良甲线#09-#10、110kV森养甲线桃莲甲支线#05-#06重要交叉跨越红外测温（2024年3月） 500kV蓄北线无人机精细化巡线：机巡线路巡视（1-3月精细化）：（Ⅱ级）500kV蓄北线#105-#106 500kV蓄北线无人机精细化巡线：机巡线路巡视（1-3月测温）：（Ⅱ级）500kV蓄北线#105-#106 500kV蓄北线无人机精细化巡线：（Ⅱ级）500kV蓄北线#131-#142塔段红外测温 500kV蓄北线无人机精细化巡线：机巡线路巡视（1-3月精细化）：（Ⅱ级）500kV蓄北线#181-#198 500kV蓄北线无人机精细化巡线：机巡线路巡视（1-3月精细化）：（Ⅱ级）500kV蓄北线#161-#180 500kV蓄北线无人机精细化巡线：机巡线路巡视（1-3月测温）：（Ⅱ级）500kV蓄北线#181-#198 500kV蓄北线无人机精细化巡线：机巡线路巡视（1-3月测温）：（Ⅱ级）500kV蓄北线#161-#180 500kV蓄北线无人机精细化巡视：机巡线路巡视（1-3月精细化）：（Ⅱ级）500kV蓄北线#131-#142塔段； 500kV蓄北线无人机精细化巡线：机巡线路巡视（1-3月精细化测温）：（Ⅱ级）500kV蓄北线#142-#160 500kV蓄北线线路特殊巡维：一点一册无人机巡视：500kV蓄北线#139-#140（2024年3月） 500kV蓄能AB线、500kV蓄北线无人机精细化巡线：机巡线路巡视（1-3月测温）：（Ⅱ级）500kV蓄北线#01-#13、500kV蓄能AB线#01-#08 500kV蓄北线无人机精细化巡视：机巡线路巡视（1-3月测温）：（Ⅱ级）500kV蓄北线#74-#75 500kV蓄北线无人机精细化巡线：机巡线路巡视（1-3月精细化测温）：（Ⅱ级）500kV蓄北线#74-#75 500kV蓄能AB线、500kV蓄北线无人机精细化巡线：机巡线路巡视（1-3月精细化测温）：（Ⅱ级）500kV蓄北线#01-#13、500kV蓄能AB线#01-#08 500kV蓄北线无人机精细化巡线：机巡线路巡视（1-3月精细化测温）：（Ⅱ级）500kV蓄北线#107-#130塔段 500kV蓄北线无人机精细化巡线：机巡线路巡视（1-3月精细化）：（Ⅱ级）500kV蓄北线#107-#130塔段 500kV蓄北线无人机精细化巡线：机巡线路巡视（1-3月精细化测温）：（Ⅱ级）500kV蓄北线#74-#104、#171-#175 500kV蓄北线无人机精细化巡线：机巡线路巡视（1-3月精细化）：（Ⅱ级）500kV蓄北线#74-#104、#171-#175 500kV蓄北线导线连接位置红外测温：500kV蓄北线#98-#99重要交叉跨越红外测温（2024年3月） 500kV蓄北线导线连接位置红外测温：500kV蓄北线#111-#112、#114-#115、#120-#121、#124-#125重要交叉跨越红外测温（2024年3月） 500kV蓄北线导线连接位置红外测温：500kV蓄北线#8-#9重要交叉跨越红外测温（2024年4月） 500kV蓄北线导线连接位置红外测温：500kV蓄北线#223-#224、#228-#229重要交叉跨越红外测温（2024年4月） 500kV蓄北线导线连接位置红外测温：500kV蓄北线#172-#173、#173-#174重要交叉跨越红外测温（2024年6月） 500kV蓄北线导线连接位置红外测温：500kV蓄北线#114-#115、#120-#121,#124-#125重要交叉跨越红外测温（2024年4月） 500kV蓄北线导线连接位置红外测温：500kV蓄北线#88-#89、#98-#99重要交叉跨越红外测温（2024年4月） 500kV蓄北线导线连接位置红外测温：500kV蓄北线#198-#199、#199-#199+1、#200-#201、#211-#212、#214-#215重要交叉跨越红外测温（2024年4月） 500kV蓄北线导线连接位置红外测温：合成绝缘子（避雷器）红外测温：接续管红外测温：500kV蓄北线#01-#13、#74-229塔段（2024年1月-6月） 500kV蓄北线线路特殊巡维：一点一册无人机巡视：500kV蓄北线#139-#140（2024年4月） 500kV蓄北线导线连接位置红外测温：500kV蓄北线#88-#89、#98-#99塔段、#111-#112塔段、#114-#115塔段、120-#121、#124-#125塔段每月定检测温作业（2024年4月） 500kV蓄北线导线连接位置红外测温：500kV蓄北线#172-#173、#173-#174、#186-#187、#187+1-#188、#188-#189、#192-#193、#194-#195塔段重要交叉跨越红外测温（2024年4月） 500kV蓄北线导线连接位置红外测温：500kV蓄北线#136-#137、#159-#160、#139-#140、#172-#173、#173-#174重要交叉跨越红外测温（2024年4月） 500kV蓄北线线路特殊巡维：一点一册无人机巡视：500kV蓄北线#139-#140（2024年5月） 500kV蓄北线导线连接位置红外测温：500kV蓄北线#98-#99重要交叉跨越红外测温（2024年5月） 500kV蓄北线导线连接位置红外测温：500kV蓄北线#111-#112、#114-#115、#120-#121、#124-#125重要交叉跨越红外测温（2024年5月） 500kV蓄北线导线连接位置红外测温：500kV蓄北线#186-#187、#187+1-#188、#188-#189塔段重要交叉跨越红外测温（2024年5月） 500kV蓄北线导线连接位置红外测温：500kV蓄北线#192-#193重要交叉跨越红外测温（2024年5月） 500kV蓄北线导线连接位置红外测温：500kV蓄北线#136-#137、#139-#140、#159-#160重要交叉跨越红外测温（2024年5月） 500kV蓄北线导线连接位置红外测温：500kV蓄北线#223-#224、#228-#229重要交叉跨越红外测温（2024年5月） 500kV蓄北线导线连接位置红外测温：500kV蓄北线#198-#199、#214-#215重要交叉跨越红外测温（2024年5月） 500kV蓄北线导线连接位置红外测温：500kV蓄北线#8-#9重要交叉跨越红外测温（2024年5月） 500kV蓄北线导线连接位置红外测温：500kV蓄北线#98-#99、#105-#106、 #111-#112、#114-#115、#120-#121,#124-#125、#136-#137、#139-#140塔段每月定检测温作业（2024年5月） 500kV蓄北线导线连接位置红外测温：500kV蓄北线#186-#187重要交叉跨越红外测温（2024年6月） 500kV蓄北线导线连接位置红外测温：500kV蓄北线#194-#195重要交叉跨越红外测温（2024年6月） 500kV蓄北线导线连接位置红外测温：500kV蓄北线#192-#193重要交叉跨越红外测温（2024年6月） 500kV蓄北线导线连接位置红外测温：500kV蓄北线#188-#189重要交叉跨越红外测温（2024年6月） 500kV蓄北线导线连接位置红外测温：500kV蓄北线#136-#137重要交叉跨越红外测温（2024年6月） 500kV蓄北线导线连接位置红外测温：500kV蓄北线#124-#125重要交叉跨越红外测温（2024年6月） 500kV蓄北线导线连接位置红外测温：500kV蓄北线#120-#121重要交叉跨越红外测温（2024年6月） 500kV蓄北线导线连接位置红外测温：500kV蓄北线#114-#115重要交叉跨越红外测温（2024年6月） 500kV蓄北线导线连接位置红外测温：500kV蓄北线#111-#112重要交叉跨越红外测温（2024年6月） 500kV蓄北线导线连接位置红外测温：500kV蓄北线#98-#99重要交叉跨越红外测温（2024年6月） 500kV蓄北线导线连接位置红外测温：500kV蓄北线#105-#106重要交叉跨越红外测温（2024年6月） 500kV蓄北线导线连接位置红外测温：500kV蓄北线#194-#195、#198-#199重要交叉跨越红外测温（2024年6月） 500kV蓄北线导线连接位置红外测温：500kV蓄北线#214-#215、#187+1-#188、#188-#189塔段重要交叉跨越红外测温（2024年6月） 500kV蓄北线、110kV森温线、110kV森温线宝珠乙支线导线连接位置红外测温：500kV蓄北线#77塔段、#174-#175塔段；110kV森温线#50-#51塔段；110kV森温线宝珠乙支线#44-#45塔段半张力预绞丝周期化定检测温作业（2024年6月） 500kV蓄北线导线连接位置红外测温：500kV蓄北线#8-#9重要交叉跨越红外测温（2024年6月） 500kV蓄北线无人机巡视、测量作业：机巡线路巡视（4-6月点云测量）：（Ⅱ级）500kV蓄北线#01-#229；（外委实施） 500kV蓄北线线路特殊巡维：一点一册无人机巡视：500kV蓄北线#139-#140（2024年6月） 500kV蓄北线导线连接位置红外测温：500kV蓄北线#223-#224、#228-#229重要交叉跨越红外测温（2024年6月） 500kV蓄北线导线连接位置红外测温：500kV蓄北线#198-#199、#214-#215重要交叉跨越红外测温（2024年6月） 500kV蓄北线导线连接位置红外测温：500kV蓄北线#186-#187、#187+1-#188、#188-#189、#192-#193、（#194-#195三月一巡）重要交叉跨越红外测温（2024年6月） 500kV蓄北线导线连接位置红外测温：500kV蓄北线#98-#99塔段、#111-#112塔段、#114-#115塔段、120-#121、#124-#125塔段每月定检测温作业（2024年6月） 500kV蓄北线导线连接位置红外测温：500kV蓄北线#136-#137、#139-#140、#159-#160重要交叉跨越红外测温（2024年6月） | AD4: #159-#160 #139-#140 #136-#137 #124-#125 #114-#115 #111-#112 #98-#99 #194-#195 #192-#193 #188-#189 #186-#187 #214-#215 #198-#199 #228-#229 #223-#224 #139-#140 #01-#229 #44-#45 #50-#51 #174-#175 #188-#189 #214-#215 #198-#199 #194-#195 #105-#106 #98-#99 #111-#112 #114-#115 #120-#121 #124-#125 #136-#137 #188-#189 #192-#193 #194-#195 #186-#187 | AF4: 已完成 | AG4: 1月份已完成
A5: 1562 | B5: 预试 | C5: 考核 | D5: 500kV | E5: 关键 | F5: 蓄北线 | G5: 运维策略 | H5: 全线 | I5: 20 | J5: 103 | K5: 35 | L5: 45536 | M5: 45565 | N5: 否 | O5: 输电管理二所 | P5: 董少波 | Q5: 王年光 | R5: 从化中心 | S5: =SUM(I5:K5) -> 158 | T5: 2024-07-30 09:00:00 2024-07-29 08:41:00 2024-07-16 09:52:20 2024-07-18 09:22:41 2024-07-18 09:23:08 2024-07-08 09:00:00 2024-07-08 09:00:00 2024-07-03 09:00:00 2024-07-03 09:00:00 2024-07-02 09:00:00 2024-07-04 09:00:00 2024-08-12 10:25:39 2024-08-06 10:53:12 2024-08-09 09:30:48 2024-08-16 09:45:33 2024-08-09 11:35:03 2024-08-09 09:30:00 2024-08-06 09:19:00 2024-08-06 09:09:00 2024-08-06 09:30:00 2024-08-05 09:35:00 2024-08-06 09:08:00 2024-08-05 09:30:47 2024-08-05 09:36:00 2024-08-01 09:45:00 2024-09-27 09:24:00 2024-09-09 10:45:19 2024-09-11 10:15:46 2024-09-25 09:00:00 2024-09-25 09:05:00 2024-09-10 09:20:00 2024-09-23 09:21:00 2024-09-13 08:30:00 2024-09-03 09:15:00 2024-09-03 09:30:00 2024-09-04 09:30:00 2024-09-03 09:30:00 2024-09-02 12:23:07 2024-09-02 11:34:24 2024-09-02 09:30:00 2024-09-02 09:30:00 2024-10-08 08:30:00 2024-10-24 09:15:00 2024-10-08 09:11:00 2024-10-11 09:15:00 2024-10-12 09:08:00 2024-10-15 09:00:00 2024-10-15 09:02:00 2024-10-08 09:09:00 2024-10-09 09:12:00 2024-10-10 08:50:00 2024-10-11 09:20:00 2024-10-09 09:00:00 | U5: 45503.574 | AA5: SCWH0301240622000854 SCWH0301240108012293 SCWH0301240622000850 SCWH0301240108012285 SCWH0301240108012288 SCWH0301240108012295 SCWH0301240108012292 SCWH0301240108012286 SCWH0301240108012290 SCWH0301240108012294 SCWH0301240105011268 SCWH0301240812005782 SCWH0301240812005789 SCWH0301240813000451 SCWH0301240815000656 SCWH0301240814000408 SCWH0301240721000216 SCWH0301240108012575 SCWH0301240108012580 SCWH0301240108012573 SCWH0301240108012578 SCWH0301240108012584 SCWH0301240721000212 SCWH0301240108012579 SCWH0301240108012586 SCWH0301240820000608 SCWH0301240109001502 SCWH0301240830010848 SCWH0301240109009282 SCWH0301240906008106 SCWH0301240105011267 SCWH0301240105011275 SCWH0301240823000242 SCWH0301240105011270 SCWH0301240820001445 SCWH0301240105011274 SCWH0301240105011272 SCWH0301240820000604 SCWH0301240109001330 SCWH0301240820000609 SCWH0301240105011266 SCWH0301240922009072 SCWH0301240108012623 SCWH0301240108012614 SCWH0301240108012612 SCWH0301240108012619 SCWH0301240108012613 SCWH0301240108012615 SCWH0301240930101682 SCWH0301240930101673 SCWH0301240930101678 SCWH0301240930101671 SCWH0301240930101684 | AB5: 蓄北线 | AC5: 500kV蓄北线导线连接位置红外测温：500kV蓄北线#98-#99塔段、#111-#112塔段、#114-#115塔段、120-#121、#124-#125塔段每月定检测温作业（2024年7月） 110kV从明森线;500kV蓄北线导线连接位置红外测温：500kV蓄北线#8-#9塔段、110kV从明森线#47-#48塔段重要交叉跨越红外测温（2024年7月） 500kV蓄北线线路特殊巡维：一点一册无人机巡视：500kV蓄北线#139-#140（2024年7月） 500kV蓄北线导线连接位置红外测温：500kV蓄北线#198-#199、#199-#199+1、#200-#201、#211-#212、#214-#215重要交叉跨越红外测温（2024年7月） 500kV蓄北线导线连接位置红外测温：500kV蓄北线#223-#224、#228-#229重要交叉跨越红外测温（2024年7月） 500kV蓄北线导线连接位置红外测温：500kV蓄北线#186-#187、#187+1-#188、#188-#189塔段重要交叉跨越红外测温（2024年7月） 500kV蓄北线导线连接位置红外测温：500kV蓄北线#192-#193、#194-#195重要交叉跨越红外测温（2024年7月） 500kV蓄北线导线连接位置红外测温：500kV蓄北线#136-#137、#159-#160、#139-#140重要交叉跨越红外测温（2024年7月） 500kV蓄北线导线连接位置红外测温：500kV蓄北线#105-#106、#111-#112、#114-#115、#120-#121、#124-#125重要交叉跨越红外测温（2024年7月） 500kV蓄北线导线连接位置红外测温：500kV蓄北线#88-#89、#98-#99重要交叉跨越红外测温（2024年7月） 500kV蓄北线导线连接位置红外测温：500kV蓄北线#172-#173、#173-#174重要交叉跨越红外测温（2024年7月） 500kV蓄北线无人机精细化巡线：机巡线路巡视（精细化、红外）：500kV蓄北线#74-#90 500kV蓄北线无人机精细化巡线：机巡线路巡视（精细化、红外）：500kV蓄北线#186-#197 500kV蓄北线无人机精细化巡线：机巡线路巡视（精细化、红外）：500kV蓄北线#91-#124 500kV蓄北线无人机精细化巡线：机巡线路巡视（精细化、红外）：500kV蓄北线#129-#142 500kV蓄北线无人机精细化巡线：机巡线路巡视（精细化、红外）：500kV蓄北线#125-#128 500kV蓄北线导线连接位置红外测温：500kV蓄北线#111-#112塔段、#114-#115塔段、120-#121、#124-#125塔段重要交叉跨越红外测温（2024年8月） 500kV蓄北线导线连接位置红外测温：500kV蓄北线#192-#193重要交叉跨越红外测温（2024年8月） 500kV蓄北线导线连接位置红外测温：500kV蓄北线#198-#199、#214-#215重要交叉跨越红外测温（2024年8月） 500kV蓄北线导线连接位置红外测温：500kV蓄北线#186-#187、#187+1-#188、#188-#189塔段重要交叉跨越红外测温（2024年8月） 500kV蓄北线导线连接位置红外测温：500kV蓄北线#136-#137、#139-#140、#159-#160重要交叉跨越红外测温（2024年8月） 500kV蓄北线导线连接位置红外测温：500kV蓄北线#223-#224、#228-#229重要交叉跨越红外测温（2024年8月） 500kV蓄北线线路特殊巡维：一点一册无人机巡视：500kV蓄北线#139-#140（2024年8月） 500kV蓄北线导线连接位置红外测温：500kV蓄北线#8-#9重要交叉跨越红外测温（2024年8月） 500kV蓄北线导线连接位置红外测温：500kV蓄北线#98-#99、#111-#112、#114-#115、#120-#121、#124-#125重要交叉跨越红外测温（2024年8月） 500kV蓄北线、110kV森温线、110kV森温线宝珠乙支线导线连接位置红外测温：500kV蓄北线#77塔段、#174-#175塔段；110kV森温线#50-#51塔段；110kV森温线宝珠乙支线#44-#45塔段半张力预绞丝周期化定检测温作业（2024年9月） 500kV蓄北线无人机精细化巡线：机巡线路巡视（7-9月精细化）：（Ⅱ级）500kV蓄北线#176 -#184； 500kV蓄北线无人机精细化巡线：机巡线路巡视（精细化、红外）：500kV蓄北线#165 -#176 500kV蓄北线导线连接位置红外测温：合成绝缘子（避雷器）红外测温：接续管红外测温：500kV蓄北线#01-#13、#74-229塔段（2024年7月-12月） 500kV蓄北线 驳接头航线规划：500kV蓄北线#74-#105接头测温、无人机线路规划 500kV蓄北线导线连接位置红外测温：500kV蓄北线#98-#99重要交叉跨越红外测温（2024年9月） 500kV蓄北线导线连接位置红外测温：500kV蓄北线#8-#9重要交叉跨越红外测温（2024年9月） 500kV蓄北线无人机精细化巡线：机巡线路巡视（精细化、红外）：500kV蓄北线#142-#164 500kV蓄北线导线连接位置红外测温：500kV蓄北线#198-#199、#214-#215重要交叉跨越红外测温（2024年9月） 500kV蓄北线导线连接位置红外测温：500kV蓄北线#192-#193塔段重要交叉跨越红外测温（2024年9月） 500kV蓄北线导线连接位置红外测温：500kV蓄北线#223-#224、#228-#229重要交叉跨越红外测温（2024年9月） 500kV蓄北线导线连接位置红外测温：500kV蓄北线#186-#187、#187+1-#188、#188-#189塔段重要交叉跨越红外测温（2024年9月） 500kV蓄北线线路特殊巡维：一点一册无人机巡视：500kV蓄北线#139-#140（2024年9月） 500kV蓄能AB联络线、500kV蓄北线无人机精细化巡线：机巡线路巡视（7-9月精细化）：（Ⅱ级）500kV蓄能AB联络线#01-#08；500kV蓄北线#01-#13 500kV蓄北线导线连接位置红外测温：500kV蓄北线#98-#99塔段、#111-#112塔段、#114-#115塔段、120-#121、#124-#125塔段每月定检测温作业（2024年9月） 500kV蓄北线导线连接位置红外测温：500kV蓄北线#136-#137、#139-#140、重要交叉跨越红外测温（2024年9月） 500kV蓄北线线路特殊巡维：一点一册无人机巡视：500kV蓄北线#139-#140（2024年10月） 500kV蓄北线导线连接位置红外测温：500kV蓄北线#8-#9重要交叉跨越红外测温（2024年10月） 500kV蓄北线导线连接位置红外测温：500kV蓄北线#98-#99重要交叉跨越红外测温（2024年10月） 500kV蓄北线导线连接位置红外测温：500kV蓄北线#192-#193、#194-#195重要交叉跨越红外测温（2024年10月） 500kV蓄北线导线连接位置红外测温：500kV蓄北线#186-#187、#187+1-#188、#188-#189塔段重要交叉跨越红外测温（2024年10月） 500kV蓄北线导线连接位置红外测温：500kV蓄北线#223-#224、#228-#229重要交叉跨越红外测温（2024年10月） 500kV蓄北线导线连接位置红外测温：500kV蓄北线#198-#199、#199-#199+1、#200-#201、#211-#212、#214-#215重要交叉跨越红外测温（2024年10月） 500kV蓄北线驳接头航线规划：500kV蓄北线#73-#100接头测温、无人机线路规划 500kV蓄北线驳接头航线规划：500kV蓄北线#111-#130塔段接头测温、无人机线路规划 500kV蓄北线驳接头航线规划：500kV蓄北线#130-#160接头测温、无人机线路规划 500kV蓄北线驳接头无人机航线规划：500kV蓄北线#151-#198接头测温、无人机线路规划 500kV蓄北线驳接头航线规划：500kV蓄北线##179-#182塔段接头测温、无人机线路规划 | AD5: #179-#182 #151-#198 #130-#160 #111-#130 #73-#100 #214-#215 #211-#212 #200-#201 #199-#199 #198-#199 #228-#229 #223-#224 #188-#189 #186-#187 #194-#195 #192-#193 #98-#99 #139-#140 | AF5: 已完成 | AG5: 7月份已完成
A6: 1580 | B6: 预试 | C6: 考核 | D6: 500kV | E6: 关键 | F6: 蓄能AB联络线 | G6: 运维策略 | H6: 全线 | I6: 4 | J6: 24 | K6: 4 | L6: 45383 | M6: 45412 | N6: 否 | O6: 输电管理二所 | P6: 董少波 | Q6: 王年光 | R6: 从化中心 | S6: =SUM(I6:K6) -> 32 | T6: 2024-04-23 09:15:00 2024-06-24 09:10:00 | U6: 45408.545 | AA6: SCWH0301240109009311 SCWH0301240109001248 | AB6: 蓄能AB联络线 | AC6: 500kV蓄能AB联络线导线连接位置红外测温：合成绝缘子（避雷器）红外测温：接续管红外测温：500kV蓄能AB联络线#01-#8塔段（2024年1月-6月） 500kV蓄能AB联络线无人机巡视、测量作业：机巡线路巡视（4-6月点云测量）：（Ⅱ级）500kV蓄能AB联络线#01-#08；（外委实施） | AD6: #01-#08 | AF6: 已完成 | AG6: 4月份已完成
A7: 1581 | B7: 预试 | C7: 考核 | D7: 500kV | E7: 关键 | F7: 蓄能AB联络线 | G7: 运维策略 | H7: 全线 | I7: 4 | J7: 24 | K7: 4 | L7: 45536 | M7: 45565 | N7: 否 | O7: 输电管理二所 | P7: 董少波 | Q7: 王年光 | R7: 从化中心 | S7: =SUM(I7:K7) -> 32 | T7: 2024-09-27 09:00:00 2024-09-02 11:34:24 | U7: 45562.519 | AA7: SCWH0301240109009312 SCWH0301240109001330 | AB7: 蓄能AB联络线 | AC7: 500kV蓄能AB联络线导线连接位置红外测温：合成绝缘子（避雷器）红外测温：接续管红外测温：500kV蓄能AB联络线#01-#8塔段（2024年7月-12月） 500kV蓄能AB联络线、500kV蓄北线无人机精细化巡线：机巡线路巡视（7-9月精细化）：（Ⅱ级）500kV蓄能AB联络线#01-#08；500kV蓄北线#01-#13 | AD7: #01-#13 #01-#08 | AF7: 已完成 | AG7: 9月份已完成
