Workbook

Sheet 1、架空线路红外检测
A1: 广供电输二〔2025〕1号附件2
A2: 输电管理二所2025年架空线路红外检测计划（关键和重要线路1年2测，一般和关注线路1年1测，重要交跨段3月1次，重要交叉跨越有隐患的隐患区段1月1次）
A3: 序号 | B3: 工作类型 | C3: 计划类型 | D3: 电压等级 | E3: 线路重要度 | F3: 线路名称 | G3: 作业来源 | H3: 设备设施名称 | I3: 复合绝缘子：杆塔数量（基） | J3: 绝缘子数量（串） | K3: 导地线：杆塔数量（基） | L3: 作业方式 | M3: 计划开始日期 | N3: 计划结束日期 | O3: 是否停电 | P3: 责任单位 | Q3: 中心负责人 | R3: 线路专责人 | S3: 责任中心 | T3: 计划完成数 | U3: 实际开始日期 | V3: 实际结束日期 | W3: 实际完成数 | X3: 合格数量 | Y3: 完成率 | Z3: 合格率 | AA3: 备注（未能按时完成原因） | AB3: 计划编号 | AC3: 工作地点和内容 | AD3: 完成情况 | AE3: 完成月份 | AF3: 计划临期提醒
A4: 1 | B4: 预试 | C4: 考核 | D4: 220kV | E4: 重要（5-9月）、其余时段关注 | F4: 北茶甲线 | G4: 运维策略 | H4: 全线 | I4: 21 | J4: 123 | K4: 28 | L4: 人工（#01-#32）机巡（其他） | M4: 2025-06-01 | N4: 2025-06-30 | O4: 否 | P4: 输电管理二所 | Q4: 蔡昊晖 | R4: 邓茂村 | S4: 白云中心 | T4: 49
A5: 2 | B5: 预试 | C5: 考核 | D5: 220kV | E5: 重要（5-9月）、其余时段关注 | F5: 北茶甲线 | G5: 运维策略 | H5: 全线 | I5: 21 | J5: 123 | K5: 28 | L5: 人工（#01-#32）机巡（其他） | M5: 2025-09-01 | N5: 2025-09-30 | O5: 否 | P5: 输电管理二所 | Q5: 蔡昊晖 | R5: 邓茂村 | S5: 白云中心 | T5: 49
A6: 3 | B6: 预试 | C6: 考核 | D6: 220kV | E6: 重要（5-9月）、其余时段关注 | F6: 北茶乙线 | G6: 运维策略 | H6: 全线 | I6: 21 | J6: 123 | K6: 28 | L6: 人工（#01-#32）机巡（其他） | M6: 2025-06-01 | N6: 2025-06-30 | O6: 否 | P6: 输电管理二所 | Q6: 蔡昊晖 | R6: 邓茂村 | S6: 白云中心 | T6: 49
A7: 4 | B7: 预试 | C7: 考核 | D7: 220kV | E7: 重要（5-9月）、其余时段关注 | F7: 北茶乙线 | G7: 运维策略 | H7: 全线 | I7: 21 | J7: 123 | K7: 28 | L7: 人工（#01-#32）机巡（其他） | M7: 2025-09-01 | N7: 2025-09-30 | O7: 否 | P7: 输电管理二所 | Q7: 蔡昊晖 | R7: 邓茂村 | S7: 白云中心 | T7: 49
A8: 5 | B8: 预试 | C8: 考核 | D8: 220kV | E8: 重要（5-9月）、其余时段关注 | F8: 北嘉甲线 | G8: 运维策略 | H8: 全线 | I8: 20 | J8: 117 | K8: 10 | L8: 人工（#01-#29）机巡（其他） | M8: 2025-06-01 | N8: 2025-06-30 | O8: 否 | P8: 输电管理二所 | Q8: 蔡昊晖 | R8: 梁伟照 | S8: 白云中心 | T8: 30
A9: 6 | B9: 预试 | C9: 考核 | D9: 220kV | E9: 重要（5-9月）、其余时段关注 | F9: 北嘉甲线 | G9: 运维策略 | H9: 全线 | I9: 20 | J9: 117 | K9: 10 | L9: 人工（#01-#29）机巡（其他） | M9: 2025-09-01 | N9: 2025-09-01 | O9: 否 | P9: 输电管理二所 | Q9: 蔡昊晖 | R9: 梁伟照 | S9: 白云中心 | T9: 30
A10: 7 | B10: 预试 | C10: 考核 | D10: 220kV | E10: 重要（5-9月）、其余时段关注 | F10: 北嘉乙线 | G10: 运维策略 | H10: 全线 | I10: 20 | J10: 117 | K10: 10 | L10: 人工（#01-#29）机巡（其他） | M10: 2025-06-01 | N10: 2025-06-30 | O10: 否 | P10: 输电管理二所 | Q10: 蔡昊晖 | R10: 梁伟照 | S10: 白云中心 | T10: 30
A11: 8 | B11: 预试 | C11: 考核 | D11: 220kV | E11: 重要（5-9月）、其余时段关注 | F11: 北嘉乙线 | G11: 运维策略 | H11: 全线 | I11: 20 | J11: 117 | K11: 10 | L11: 人工（#01-#29）机巡（其他） | M11: 2025-09-01 | N11: 2025-09-01 | O11: 否 | P11: 输电管理二所 | Q11: 蔡昊晖 | R11: 梁伟照 | S11: 白云中心 | T11: 30
A12: 9 | B12: 预试 | C12: 考核 | D12: 500kV | E12: 关键 | F12: 北增甲线 | G12: 运维策略 | H12: #01-#62 | I12: 13 | J12: 42 | K12: 29 | L12: 人工（#01-#32）机巡（其他） | M12: 2025-06-01 | N12: 2025-06-30 | O12: 否 | P12: 输电管理二所 | Q12: 蔡昊晖 | R12: 潘永洪 | S12: 白云中心 | T12: 42
A13: 10 | B13: 预试 | C13: 考核 | D13: 500kV | E13: 关键 | F13: 北增甲线 | G13: 运维策略 | H13: #01-#62 | I13: 13 | J13: 42 | K13: 29 | L13: 人工（#01-#32）机巡（其他） | M13: 2025-09-01 | N13: 2025-09-01 | O13: 否 | P13: 输电管理二所 | Q13: 蔡昊晖 | R13: 潘永洪 | S13: 白云中心 | T13: 42
A14: 11 | B14: 预试 | C14: 考核 | D14: 500kV | E14: 关键 | F14: 北增乙线 | G14: 运维策略 | H14: #01-#58 | I14: 15 | J14: 48 | K14: 30 | L14: 人工（#01-#30）机巡（其他） | M14: 2025-06-01 | N14: 2025-06-30 | O14: 否 | P14: 输电管理二所 | Q14: 蔡昊晖 | R14: 潘永洪 | S14: 白云中心 | T14: 45
A15: 12 | B15: 预试 | C15: 考核 | D15: 500kV | E15: 关键 | F15: 北增乙线 | G15: 运维策略 | H15: #01-#58 | I15: 15 | J15: 48 | K15: 30 | L15: 人工（#01-#30）机巡（其他） | M15: 2025-09-01 | N15: 2025-09-01 | O15: 否 | P15: 输电管理二所 | Q15: 蔡昊晖 | R15: 潘永洪 | S15: 白云中心 | T15: 45
... A97: 340 | B97: 预试 | C97: 考核 | D97: 500kV | E97: 关键 | F97: 北花乙线 | G97: 运维策略 | H97: 全线 | I97: 10 | J97: 62 | K97: 24 | L97: 人工（#01-#10）机巡（其他） | M97: 2025-08-01 | N97: 2025-08-01 | O97: 否 | P97: 输电管理二所 | Q97: 蔡昊晖 | R97: 甘雄强 | S97: 白云中心 | T97: 24
A98: 353 | B98: 预试 | C98: 考核 | D98: 220kV | E98: 重要（5-9月）、其余时段一般 | F98: 北郭甲线 | G98: 运维策略 | H98: 全线 | I98: / | J98: / | K98: 35 | L98: 人工（#01-#05）机巡（其他） | M98: 2025-06-01 | N98: 2025-06-01 | O98: 否 | P98: 输电管理二所 | Q98: 蔡昊晖 | R98: 戴国斌 | S98: 白云中心 | T98: 35
A99: 354 | B99: 预试 | C99: 考核 | D99: 220kV | E99: 重要（5-9月）、其余时段一般 | F99: 北郭甲线 | G99: 运维策略 | H99: 全线 | I99: / | J99: / | K99: 35 | L99: 人工（#01-#05）机巡（其他） | M99: 2025-09-01 | N99: 2025-09-01 | O99: 否 | P99: 输电管理二所 | Q99: 蔡昊晖 | R99: 戴国斌 | S99: 白云中心 | T99: 35
A100: 367 | B100: 预试 | C100: 考核 | D100: 220kV | E100: 重要（5-9月）、其余时段一般 | F100: 北郭乙线 | G100: 运维策略 | H100: 全线 | I100: / | J100: / | K100: 35 | L100: 人工（#01-#05）机巡（其他） | M100: 2025-06-01 | N100: 2025-06-01 | O100: 否 | P100: 输电管理二所 | Q100: 蔡昊晖 | R100: 戴国斌 | S100: 白云中心 | T100: 35
A101: 368 | B101: 预试 | C101: 考核 | D101: 220kV | E101: 重要（5-9月）、其余时段一般 | F101: 北郭乙线 | G101: 运维策略 | H101: 全线 | I101: / | J101: / | K101: 35 | L101: 人工（#01-#05）机巡（其他） | M101: 2025-09-01 | N101: 2025-09-01 | O101: 否 | P101: 输电管理二所 | Q101: 蔡昊晖 | R101: 戴国斌 | S101: 白云中心 | T101: 35
A102: 373 | B102: 预试 | C102: 考核 | D102: 220kV | E102: 重要（5-9月）、其余时段一般 | F102: 北石甲线 | G102: 运维策略 | H102: 全线 | I102: 10 | J102: 66 | K102: 84 | L102: 人工（#01-#09）机巡（其他） | M102: 2025-06-01 | N102: 2025-06-01 | O102: 否 | P102: 输电管理二所 | Q102: 蔡昊晖 | R102: 戴国斌 曾宇 | S102: 白云中心 | T102: 84
A103: 374 | B103: 预试 | C103: 考核 | D103: 220kV | E103: 重要（5-9月）、其余时段一般 | F103: 北石甲线 | G103: 运维策略 | H103: 全线 | I103: 10 | J103: 66 | K103: 84 | L103: 人工（#01-#09）机巡（其他） | M103: 2025-09-01 | N103: 2025-09-01 | O103: 否 | P103: 输电管理二所 | Q103: 蔡昊晖 | R103: 戴国斌 曾宇 | S103: 白云中心 | T103: 84
A104: 379 | B104: 预试 | C104: 考核 | D104: 220kV | E104: 重要（5-9月）、其余时段一般 | F104: 北石乙线 | G104: 运维策略 | H104: 全线 | I104: 10 | J104: 66 | K104: 83 | L104: 人工（#01-#09）机巡（其他） | M104: 2025-06-01 | N104: 2025-06-01 | O104: 否 | P104: 输电管理二所 | Q104: 蔡昊晖 | R104: 戴国斌 曾宇 | S104: 白云中心 | T104: 83
A105: 380 | B105: 预试 | C105: 考核 | D105: 220kV | E105: 重要（5-9月）、其余时段一般 | F105: 北石乙线 | G105: 运维策略 | H105: 全线 | I105: 10 | J105: 66 | K105: 83 | L105: 人工（#01-#09）机巡（其他） | M105: 2025-09-01 | N105: 2025-09-01 | O105: 否 | P105: 输电管理二所 | Q105: 蔡昊晖 | R105: 戴国斌 曾宇 | S105: 白云中心 | T105: 83
A106: 385 | B106: 预试 | C106: 考核 | D106: 220kV | E106: 重要（5-9月）、其余时段关注 | F106: 北浔甲线 | G106: 运维策略 | H106: 全线 | I106: 48 | J106: 288 | K106: 80 | L106: 人工（#01-#10）机巡（其他） | M106: 2025-06-01 | N106: 2025-06-01 | O106: 否 | P106: 输电管理二所 | Q106: 蔡昊晖 | R106: 戴国斌 曾宇 | S106: 白云中心 | T106: 80
A107: 386 | B107: 预试 | C107: 考核 | D107: 220kV | E107: 重要（5-9月）、其余时段关注 | F107: 北浔甲线 | G107: 运维策略 | H107: 全线 | I107: 48 | J107: 288 | K107: 80 | L107: 人工（#01-#10）机巡（其他） | M107: 2025-09-01 | N107: 2025-09-01 | O107: 否 | P107: 输电管理二所 | Q107: 蔡昊晖 | R107: 戴国斌 曾宇 | S107: 白云中心 | T107: 80
A108: 391 | B108: 预试 | C108: 考核 | D108: 220kV | E108: 重要（5-9月）、其余时段关注 | F108: 北浔乙线 | G108: 运维策略 | H108: 全线 | I108: 48 | J108: 288 | K108: 80 | L108: 人工（#01-#10）机巡（其他） | M108: 2025-06-01 | N108: 2025-06-01 | O108: 否 | P108: 输电管理二所 | Q108: 蔡昊晖 | R108: 戴国斌 曾宇 | S108: 白云中心 | T108: 80
A109: 392 | B109: 预试 | C109: 考核 | D109: 220kV | E109: 重要（5-9月）、其余时段关注 | F109: 北浔乙线 | G109: 运维策略 | H109: 全线 | I109: 48 | J109: 288 | K109: 80 | L109: 人工（#01-#10）机巡（其他） | M109: 2025-09-01 | N109: 2025-09-01 | O109: 否 | P109: 输电管理二所 | Q109: 蔡昊晖 | R109: 戴国斌 曾宇 | S109: 白云中心 | T109: 80
A110: 393 | B110: 预试 | C110: 考核 | D110: 110kV | E110: 关键 | F110: 芳花增甲线 | G110: 运维策略 | H110: 全线 | I110: 5 | J110: 30 | K110: 22 | L110: 机巡（其他） | M110: 2025-02-01 | N110: 2025-02-01 | O110: 否 | P110: 输电管理二所 | Q110: 蔡昊晖 | R110: 林杰 | S110: 白云中心 | T110: 22
A111: 394 | B111: 预试 | C111: 考核 | D111: 110kV | E111: 关键 | F111: 芳花增甲线 | G111: 运维策略 | H111: 全线 | I111: 5 | J111: 30 | K111: 22 | L111: 机巡（其他） | M111: 2025-10-01 | N111: 2025-10-01 | O111: 否 | P111: 输电管理二所 | Q111: 蔡昊晖 | R111: 林杰 | S111: 白云中心 | T111: 22
A112: 399 | B112: 预试 | C112: 考核 | D112: 110kV | E112: 关键 | F112: 芳花增甲线冲口甲支线 | G112: 运维策略 | H112: 全线 | I112: 6 | J112: 18 | K112: 12 | L112: 机巡（其他） | M112: 2025-02-01 | N112: 2025-02-01 | O112: 否 | P112: 输电管理二所 | Q112: 蔡昊晖 | R112: 林杰 | S112: 白云中心 | T112: 12
A113: 400 | B113: 预试 | C113: 考核 | D113: 110kV | E113: 关键 | F113: 芳花增甲线冲口甲支线 | G113: 运维策略 | H113: 全线 | I113: 6 | J113: 18 | K113: 12 | L113: 机巡（其他） | M113: 2025-10-01 | N113: 2025-10-01 | O113: 否 | P113: 输电管理二所 | Q113: 蔡昊晖 | R113: 林杰 | S113: 白云中心 | T113: 12
... A126: 445 | B126: 预试 | C126: 考核 | D126: 110kV | E126: 重要 | F126: 蚌江线 | G126: 运维策略 | H126: 全线 | I126: 5 | J126: 24 | K126: 9 | L126: 人工（#01-#14）机巡（其他） | M126: 2025-09-01 | N126: 2025-09-01 | O126: 否 | P126: 输电管理二所 | Q126: 蔡昊晖 | R126: 姚河新 | S126: 白云中心 | T126: 9
A127: 450 | B127: 预试 | C127: 考核 | D127: 110kV | E127: 重要 | F127: 郭北泉线 | G127: 运维策略 | H127: 全线 | I127: / | J127: / | K127: 23 | L127: 机巡（其他） | M127: 2025-05-01 | N127: 2025-05-01 | O127: 否 | P127: 输电管理二所 | Q127: 蔡昊晖 | R127: 姚河新 | S127: 白云中心 | T127: 23
A128: 451 | B128: 预试 | C128: 考核 | D128: 110kV | E128: 重要 | F128: 郭北泉线 | G128: 运维策略 | H128: 全线 | I128: / | J128: / | K128: 23 | L128: 机巡（其他） | M128: 2025-09-01 | N128: 2025-09-01 | O128: 否 | P128: 输电管理二所 | Q128: 蔡昊晖 | R128: 姚河新 | S128: 白云中心 | T128: 23
A129: 456 | B129: 预试 | C129: 考核 | D129: 220kV | E129: 关注 | F129: 花罗甲线 | G129: 运维策略 | H129: 全线 | I129: 19 | J129: 114 | K129: 17 | L129: 机巡（其他） | M129: 2025-03-01 | N129: 2025-03-01 | O129: 否 | P129: 输电管理二所 | Q129: 蔡昊晖 | R129: 马万里 | S129: 白云中心 | T129: 17
A130: 461 | B130: 预试 | C130: 考核 | D130: 220kV | E130: 一般 | F130: 花泮线 | G130: 运维策略 | H130: 全线 | I130: 25 | J130: 180 | K130: 19 | L130: 机巡（其他） | M130: 2025-03-01 | N130: 2025-03-01 | O130: 否 | P130: 输电管理二所 | Q130: 蔡昊晖 | R130: 马万里 | S130: 白云中心 | T130: 19
A131: 466 | B131: 预试 | C131: 考核 | D131: 110kV | E131: 关注 | F131: 花山彩甲线 | G131: 运维策略 | H131: 全线 | I131: 3 | J131: 18 | K131: 14 | L131: 机巡（其他） | M131: 2025-03-01 | N131: 2025-03-01 | O131: 否 | P131: 输电管理二所 | Q131: 蔡昊晖 | R131: 马万里 | S131: 白云中心 | T131: 14
A132: 471 | B132: 预试 | C132: 考核 | D132: 110kV | E132: 关注 | F132: 花山彩乙线 | G132: 运维策略 | H132: 全线 | I132: 3 | J132: 18 | K132: 14 | L132: 机巡（其他） | M132: 2025-03-01 | N132: 2025-03-01 | O132: 否 | P132: 输电管理二所 | Q132: 蔡昊晖 | R132: 马万里 | S132: 白云中心 | T132: 14
A133: 472 | B133: 预试 | C133: 考核 | D133: 110kV | E133: 关键 | F133: 花桃甲线 | G133: 运维策略 | H133: 全线 | I133: 4 | J133: 18 | K133: 8 | L133: 机巡（其他） | M133: 2025-03-01 | N133: 2025-03-01 | O133: 否 | P133: 输电管理二所 | Q133: 蔡昊晖 | R133: 林杰 | S133: 白云中心 | T133: 8
...

Sheet 1、架空线路红外检测（重要交跨管控要求）
A1: 输电管理二所2025年架空线路红外检测计划（关键和重要线路1年2测，一般和关注线路1年1测，重要交跨段3月1次，重要交叉跨越有隐患的隐患区段1月1次）
A2: 序号 | B2: 工作类型 | C2: 计划类型 | D2: 电压等级 | E2: 线路重要度 | F2: 线路名称 | G2: 作业来源 | H2: 设备设施名称 | I2: 复合绝缘子：杆塔数量（基） | J2: 绝缘子数量（串） | K2: 导地线：杆塔数量（基） | L2: 作业方式 | M2: 计划开始日期 | N2: 计划结束日期 | O2: 是否停电 | P2: 责任单位 | Q2: 中心负责人 | R2: 线路专责人 | S2: 责任中心 | T2: 计划完成数 | U2: 实际开始日期 | V2: 实际结束日期 | W2: 实际完成数 | X2: 合格数量 | Y2: 完成率 | Z2: 合格率 | AA2: 备注（未能按时完成原因） | AB2: 计划编号 | AC2: 工作地点和内容 | AD2: 完成情况 | AE2: 完成月份 | AF2: 计划临期提醒
A3: 91 | B3: 预试 | C3: 考核 | D3: 220kV | E3: 一般 | F3: 北界甲线 | G3: 重要交跨管控要求 | H3: 铁路:#05-#06;河流:#10-#11;公路:#36-#37,#15-#16,#02-#03,#03-#04,#08-#09; | I3: / | J3: / | K3: 14 | L3: 人工（#05-#06,#02-#03,#03-#04,#08-#09,#15-#16,#10-#11）机巡（其他） | M3: 45717 | N3: 45747 | O3: 否 | P3: 输电管理二所 | Q3: 蔡昊晖 | R3: 邓茂村 | S3: 白云中心 | T3: 14
A4: 92 | B4: 预试 | C4: 考核 | D4: 220kV | E4: 一般 | F4: 北界乙线 | G4: 重要交跨管控要求 | H4: 铁路:#05-#06;河流:#10-#11;公路:#36-#37,#15-#16,#08-#09,#02-#03,#03-#04; | I4: / | J4: / | K4: 14 | L4: 人工（#05-#06,#02-#03,#03-#04,#08-#09,#15-#16,#10-#11）机巡（其他） | M4: 45717 | N4: 45747 | O4: 否 | P4: 输电管理二所 | Q4: 蔡昊晖 | R4: 邓茂村 | S4: 白云中心 | T4: 14
A5: 93 | B5: 预试 | C5: 考核 | D5: 220kV | E5: 一般 | F5: 界汉甲线 | G5: 重要交跨管控要求 | H5: 铁路:#22-#23;公路:#18-#19; | I5: / | J5: / | K5: 4 | L5: 机巡（其他） | M5: 45717 | N5: 45747 | O5: 否 | P5: 输电管理二所 | Q5: 蔡昊晖 | R5: 邓茂村 | S5: 白云中心 | T5: 4
A6: 94 | B6: 预试 | C6: 考核 | D6: 220kV | E6: 一般 | F6: 界汉乙线 | G6: 重要交跨管控要求 | H6: 铁路:#22-#23;公路:#18-#19; | I6: / | J6: / | K6: 4 | L6: 机巡（其他） | M6: 45717 | N6: 45747 | O6: 否 | P6: 输电管理二所 | Q6: 蔡昊晖 | R6: 邓茂村 | S6: 白云中心 | T6: 4
A7: 95 | B7: 预试 | C7: 考核 | D7: 220kV | E7: 一般 | F7: 北蚌甲线 | G7: 重要交跨管控要求 | H7: 公路:#03-#04; | I7: / | J7: / | K7: 2 | L7: 人工（#03-#04）机巡（其他） | M7: 45717 | N7: 45747 | O7: 否 | P7: 输电管理二所 | Q7: 蔡昊晖 | R7: 梁伟照 | S7: 白云中心 | T7: 2
A8: 96 | B8: 预试 | C8: 考核 | D8: 220kV | E8: 一般 | F8: 北蚌乙线 | G8: 重要交跨管控要求 | H8: 公路:#02-#03; | I8: / | J8: / | K8: 2 | L8: 人工（#02-#03）机巡（其他） | M8: 45717 | N8: 45747 | O8: 否 | P8: 输电管理二所 | Q8: 蔡昊晖 | R8: 梁伟照 | S8: 白云中心 | T8: 2
A9: 97 | B9: 预试 | C9: 考核 | D9: 110kV | E9: 关注 | F9: 茶观乙线 | G9: 重要交跨管控要求 | H9: 铁路:#22-#23;公路:#28-#29,#49-#50,#22-#23; | I9: / | J9: / | K9: 8 | L9: 人工（#49-#50）机巡（其他） | M9: 45717 | N9: 45747 | O9: 否 | P9: 输电管理二所 | Q9: 蔡昊晖 | R9: 黄灿明 | S9: 白云中心 | T9: 8
A10: 98 | B10: 预试 | C10: 考核 | D10: 110kV | E10: 重要（5-9月）、其余时段关注 | F10: 嘉观临线 | G10: 重要交跨管控要求 | H10: 铁路:#90-#91,#28-#29,#106-#107;公路:#110-#111,#77-#78,#28-#29,#83-#84,#92-#93,#65-#66,#31-#32,#16-#17; | I10: / | J10: / | K10: 22 | L10: 人工（#28-#29、#16-#17、#31-#32、#65-#66）机巡（其他） | M10: 45717 | N10: 45747 | O10: 否 | P10: 输电管理二所 | Q10: 蔡昊晖 | R10: 张春勇 | S10: 白云中心 | T10: 22
A11: 99 | B11: 预试 | C11: 考核 | D11: 110kV | E11: 重要（5-9月）、其余时段关注 | F11: 嘉观临线元洲乙支线 | G11: 重要交跨管控要求 | H11: 铁路:#02-#03;河流:#05-#06;公路:#02-#03; | I11: / | J11: / | K11: 6 | L11: 人工（#02-#03,#05-#06）机巡（其他） | M11: 45717 | N11: 45747 | O11: 否 | P11: 输电管理二所 | Q11: 蔡昊晖 | R11: 谭颂华 | S11: 白云中心 | T11: 6
A12: 100 | B12: 预试 | C12: 考核 | D12: 110kV | E12: 关注 | F12: 茶园甲线 | G12: 重要交跨管控要求 | H12: 公路:#19-#20; | I12: / | J12: / | K12: 2 | L12: 人工（#19-#20）机巡（其他） | M12: 45717 | N12: 45747 | O12: 否 | P12: 输电管理二所 | Q12: 蔡昊晖 | R12: 徐龙 | S12: 白云中心 | T12: 2
A13: 101 | B13: 预试 | C13: 考核 | D13: 110kV | E13: 关注 | F13: 茶园乙线 | G13: 重要交跨管控要求 | H13: 公路:#19-#20; | I13: / | J13: / | K13: 2 | L13: 人工（#19-#20）机巡（其他） | M13: 45717 | N13: 45747 | O13: 否 | P13: 输电管理二所 | Q13: 蔡昊晖 | R13: 刘子瑜 | S13: 白云中心 | T13: 2
A14: 102 | B14: 预试 | C14: 考核 | D14: 110kV | E14: 重要（5-9月）、其余时段一般 | F14: 嘉梨线 | G14: 重要交跨管控要求 | H14: 公路:#03-#04; | I14: / | J14: / | K14: 2 | L14: 人工（#03-#04）机巡（其他） | M14: 45717 | N14: 45747 | O14: 否 | P14: 输电管理二所 | Q14: 蔡昊晖 | R14: 陈其来 | S14: 白云中心 | T14: 2
... A43: 131 | B43: 预试 | C43: 考核 | D43: 110kV | E43: 重要（5-9月）、其余时段关注 | F43: 汉钟乙线 | G43: 重要交跨管控要求 | H43: 铁路:#11-#12; | I43: / | J43: / | K43: 2 | L43: 机巡（其他） | M43: 45717 | N43: 45747 | O43: 否 | P43: 输电管理二所 | Q43: 蔡昊晖 | R43: 张春勇 | S43: 白云中心 | T43: 2
A44: 132 | B44: 预试 | C44: 考核 | D44: 500kV | E44: 关键 | F44: 蓄北线 | G44: 重要交跨管控要求 | H44: 铁路：#186-#187，#228-#229；公路：#187+1-188、#188-#189、#192-#193、#198-#199、#214-#215、#223-#224；河流：#216-#217 | I44: 0 | J44: 0 | K44: 18 | L44: 人工（#198-#199、#214-#215、#223-#224、#228-#229）机巡（其他） | M44: 45717 | N44: 45747 | O44: 否 | P44: 输电管理二所 | Q44: 蔡昊晖 | R44: 容志松 | S44: 白云中心 | T44: 18
A45: 133 | B45: 预试 | C45: 考核 | D45: 220kV | E45: 一般 | F45: 北界甲线 | G45: 重要交跨管控要求 | H45: 铁路:#05-#06;河流:#10-#11;公路:#36-#37,#15-#16,#02-#03,#03-#04,#08-#09; | I45: / | J45: / | K45: 14 | L45: 人工（#05-#06,#02-#03,#03-#04,#08-#09,#15-#16,#10-#11）机巡（其他） | M45: 45809 | N45: 45838 | O45: 否 | P45: 输电管理二所 | Q45: 蔡昊晖 | R45: 邓茂村 | S45: 白云中心 | T45: 14
A46: 134 | B46: 预试 | C46: 考核 | D46: 220kV | E46: 一般 | F46: 北界乙线 | G46: 重要交跨管控要求 | H46: 铁路:#05-#06;河流:#10-#11;公路:#36-#37,#15-#16,#08-#09,#02-#03,#03-#04; | I46: / | J46: / | K46: 14 | L46: 人工（#05-#06,#02-#03,#03-#04,#08-#09,#15-#16,#10-#11）机巡（其他） | M46: 45809 | N46: 45838 | O46: 否 | P46: 输电管理二所 | Q46: 蔡昊晖 | R46: 邓茂村 | S46: 白云中心 | T46: 14
A47: 135 | B47: 预试 | C47: 考核 | D47: 220kV | E47: 一般 | F47: 界汉甲线 | G47: 重要交跨管控要求 | H47: 铁路:#22-#23;公路:#18-#19; | I47: / | J47: / | K47: 4 | L47: 机巡（其他） | M47: 45809 | N47: 45838 | O47: 否 | P47: 输电管理二所 | Q47: 蔡昊晖 | R47: 邓茂村 | S47: 白云中心 | T47: 4
A48: 136 | B48: 预试 | C48: 考核 | D48: 220kV | E48: 一般 | F48: 界汉乙线 | G48: 重要交跨管控要求 | H48: 铁路:#22-#23;公路:#18-#19; | I48: / | J48: / | K48: 4 | L48: 机巡（其他） | M48: 45809 | N48: 45838 | O48: 否 | P48: 输电管理二所 | Q48: 蔡昊晖 | R48: 邓茂村 | S48: 白云中心 | T48: 4
A49: 137 | B49: 预试 | C49: 考核 | D49: 220kV | E49: 一般 | F49: 北蚌甲线 | G49: 重要交跨管控要求 | H49: 公路:#03-#04; | I49: / | J49: / | K49: 2 | L49: 人工（#03-#04）机巡（其他） | M49: 45809 | N49: 45838 | O49: 否 | P49: 输电管理二所 | Q49: 蔡昊晖 | R49: 梁伟照 | S49: 白云中心 | T49: 2
A50: 138 | B50: 预试 | C50: 考核 | D50: 220kV | E50: 一般 | F50: 北蚌乙线 | G50: 重要交跨管控要求 | H50: 公路:#02-#03; | I50: / | J50: / | K50: 2 | L50: 人工（#02-#03）机巡（其他） | M50: 45809 | N50: 45838 | O50: 否 | P50: 输电管理二所 | Q50: 蔡昊晖 | R50: 梁伟照 | S50: 白云中心 | T50: 2
A51: 139 | B51: 预试 | C51: 考核 | D51: 110kV | E51: 关注 | F51: 茶观乙线 | G51: 重要交跨管控要求 | H51: 铁路:#22-#23;公路:#28-#29,#49-#50,#22-#23; | I51: / | J51: / | K51: 8 | L51: 人工（#49-#50）机巡（其他） | M51: 45809 | N51: 45838 | O51: 否 | P51: 输电管理二所 | Q51: 蔡昊晖 | R51: 黄灿明 | S51: 白云中心 | T51: 8
A52: 140 | B52: 预试 | C52: 考核 | D52: 110kV | E52: 重要（5-9月）、其余时段关注 | F52: 嘉观临线 | G52: 重要交跨管控要求 | H52: 铁路:#90-#91,#28-#29,#106-#107;公路:#110-#111,#77-#78,#28-#29,#83-#84,#92-#93,#65-#66,#31-#32,#16-#17; | I52: / | J52: / | K52: 22 | L52: 人工（#28-#29、#16-#17、#31-#32、#65-#66）机巡（其他） | M52: 45809 | N52: 45838 | O52: 否 | P52: 输电管理二所 | Q52: 蔡昊晖 | R52: 张春勇 | S52: 白云中心 | T52: 22
A53: 141 | B53: 预试 | C53: 考核 | D53: 110kV | E53: 重要（5-9月）、其余时段关注 | F53: 嘉观临线元洲乙支线 | G53: 重要交跨管控要求 | H53: 铁路:#02-#03;河流:#05-#06;公路:#02-#03; | I53: / | J53: / | K53: 6 | L53: 人工（#02-#03,#05-#06）机巡（其他） | M53: 45809 | N53: 45838 | O53: 否 | P53: 输电管理二所 | Q53: 蔡昊晖 | R53: 谭颂华 | S53: 白云中心 | T53: 6
A54: 142 | B54: 预试 | C54: 考核 | D54: 110kV | E54: 关注 | F54: 茶园甲线 | G54: 重要交跨管控要求 | H54: 公路:#19-#20; | I54: / | J54: / | K54: 2 | L54: 人工（#19-#20）机巡（其他） | M54: 45809 | N54: 45838 | O54: 否 | P54: 输电管理二所 | Q54: 蔡昊晖 | R54: 徐龙 | S54: 白云中心 | T54: 2
A55: 143 | B55: 预试 | C55: 考核 | D55: 110kV | E55: 关注 | F55: 茶园乙线 | G55: 重要交跨管控要求 | H55: 公路:#19-#20; | I55: / | J55: / | K55: 2 | L55: 人工（#19-#20）机巡（其他） | M55: 45809 | N55: 45838 | O55: 否 | P55: 输电管理二所 | Q55: 蔡昊晖 | R55: 刘子瑜 | S55: 白云中心 | T55: 2
A56: 144 | B56: 预试 | C56: 考核 | D56: 110kV | E56: 重要（5-9月）、其余时段一般 | F56: 嘉梨线 | G56: 重要交跨管控要求 | H56: 公路:#03-#04; | I56: / | J56: / | K56: 2 | L56: 人工（#03-#04）机巡（其他） | M56: 45809 | N56: 45838 | O56: 否 | P56: 输电管理二所 | Q56: 蔡昊晖 | R56: 陈其来 | S56: 白云中心 | T56: 2
... A85: 173 | B85: 预试 | C85: 考核 | D85: 110kV | E85: 重要（5-9月）、其余时段关注 | F85: 汉钟乙线 | G85: 重要交跨管控要求 | H85: 铁路:#11-#12; | I85: / | J85: / | K85: 2 | L85: 机巡（其他） | M85: 45809 | N85: 45838 | O85: 否 | P85: 输电管理二所 | Q85: 蔡昊晖 | R85: 张春勇 | S85: 白云中心 | T85: 2
A86: 174 | B86: 预试 | C86: 考核 | D86: 500kV | E86: 关键 | F86: 蓄北线 | G86: 重要交跨管控要求 | H86: 铁路：#186-#187，#228-#229；公路：#187+1-188、#188-#189、#192-#193、#198-#199、#214-#215、#223-#224；河流：#216-#217 | I86: 0 | J86: 0 | K86: 18 | L86: 人工（#198-#199、#214-#215、#223-#224、#228-#229）机巡（其他） | M86: 45809 | N86: 45838 | O86: 否 | P86: 输电管理二所 | Q86: 蔡昊晖 | R86: 容志松 | S86: 白云中心 | T86: 18
A87: 175 | B87: 预试 | C87: 考核 | D87: 220kV | E87: 一般 | F87: 北界甲线 | G87: 重要交跨管控要求 | H87: 铁路:#05-#06;河流:#10-#11;公路:#36-#37,#15-#16,#02-#03,#03-#04,#08-#09; | I87: / | J87: / | K87: 14 | L87: 人工（#05-#06,#02-#03,#03-#04,#08-#09,#15-#16,#10-#11）机巡（其他） | M87: 45901 | N87: 45930 | O87: 否 | P87: 输电管理二所 | Q87: 蔡昊晖 | R87: 邓茂村 | S87: 白云中心 | T87: 14
A88: 176 | B88: 预试 | C88: 考核 | D88: 220kV | E88: 一般 | F88: 北界乙线 | G88: 重要交跨管控要求 | H88: 铁路:#05-#06;河流:#10-#11;公路:#36-#37,#15-#16,#08-#09,#02-#03,#03-#04; | I88: / | J88: / | K88: 14 | L88: 人工（#05-#06,#02-#03,#03-#04,#08-#09,#15-#16,#10-#11）机巡（其他） | M88: 45901 | N88: 45930 | O88: 否 | P88: 输电管理二所 | Q88: 蔡昊晖 | R88: 邓茂村 | S88: 白云中心 | T88: 14
A89: 177 | B89: 预试 | C89: 考核 | D89: 220kV | E89: 一般 | F89: 界汉甲线 | G89: 重要交跨管控要求 | H89: 铁路:#22-#23;公路:#18-#19; | I89: / | J89: / | K89: 4 | L89: 机巡（其他） | M89: 45901 | N89: 45930 | O89: 否 | P89: 输电管理二所 | Q89: 蔡昊晖 | R89: 邓茂村 | S89: 白云中心 | T89: 4
A90: 178 | B90: 预试 | C90: 考核 | D90: 220kV | E90: 一般 | F90: 界汉乙线 | G90: 重要交跨管控要求 | H90: 铁路:#22-#23;公路:#18-#19; | I90: / | J90: / | K90: 4 | L90: 机巡（其他） | M90: 45901 | N90: 45930 | O90: 否 | P90: 输电管理二所 | Q90: 蔡昊晖 | R90: 邓茂村 | S90: 白云中心 | T90: 4
A91: 179 | B91: 预试 | C91: 考核 | D91: 220kV | E91: 一般 | F91: 北蚌甲线 | G91: 重要交跨管控要求 | H91: 公路:#03-#04; | I91: / | J91: / | K91: 2 | L91: 人工（#03-#04）机巡（其他） | M91: 45901 | N91: 45930 | O91: 否 | P91: 输电管理二所 | Q91: 蔡昊晖 | R91: 梁伟照 | S91: 白云中心 | T91: 2
A92: 180 | B92: 预试 | C92: 考核 | D92: 220kV | E92: 一般 | F92: 北蚌乙线 | G92: 重要交跨管控要求 | H92: 公路:#02-#03; | I92: / | J92: / | K92: 2 | L92: 人工（#02-#03）机巡（其他） | M92: 45901 | N92: 45930 | O92: 否 | P92: 输电管理二所 | Q92: 蔡昊晖 | R92: 梁伟照 | S92: 白云中心 | T92: 2
A93: 181 | B93: 预试 | C93: 考核 | D93: 110kV | E93: 关注 | F93: 茶观乙线 | G93: 重要交跨管控要求 | H93: 铁路:#22-#23;公路:#28-#29,#49-#50,#22-#23; | I93: / | J93: / | K93: 8 | L93: 人工（#49-#50）机巡（其他） | M93: 45901 | N93: 45930 | O93: 否 | P93: 输电管理二所 | Q93: 蔡昊晖 | R93: 黄灿明 | S93: 白云中心 | T93: 8
A94: 182 | B94: 预试 | C94: 考核 | D94: 110kV | E94: 重要（5-9月）、其余时段关注 | F94: 嘉观临线 | G94: 重要交跨管控要求 | H94: 铁路:#90-#91,#28-#29,#106-#107;公路:#110-#111,#77-#78,#28-#29,#83-#84,#92-#93,#65-#66,#31-#32,#16-#17; | I94: / | J94: / | K94: 22 | L94: 人工（#28-#29、#16-#17、#31-#32、#65-#66）机巡（其他） | M94: 45901 | N94: 45930 | O94: 否 | P94: 输电管理二所 | Q94: 蔡昊晖 | R94: 张春勇 | S94: 白云中心 | T94: 22
A95: 183 | B95: 预试 | C95: 考核 | D95: 110kV | E95: 重要（5-9月）、其余时段关注 | F95: 嘉观临线元洲乙支线 | G95: 重要交跨管控要求 | H95: 铁路:#02-#03;河流:#05-#06;公路:#02-#03; | I95: / | J95: / | K95: 6 | L95: 人工（#02-#03,#05-#06）机巡（其他） | M95: 45901 | N95: 45930 | O95: 否 | P95: 输电管理二所 | Q95: 蔡昊晖 | R95: 谭颂华 | S95: 白云中心 | T95: 6
A96: 184 | B96: 预试 | C96: 考核 | D96: 110kV | E96: 关注 | F96: 茶园甲线 | G96: 重要交跨管控要求 | H96: 公路:#19-#20; | I96: / | J96: / | K96: 2 | L96: 人工（#19-#20）机巡（其他） | M96: 45901 | N96: 45930 | O96: 否 | P96: 输电管理二所 | Q96: 蔡昊晖 | R96: 徐龙 | S96: 白云中心 | T96: 2
...

Sheet 2、架空线路接地电阻测试
A1: 输电管理二所2025年接地电阻测试计划
A2: 序号 | B2: 工作类型 | C2: 计划类型 | D2: 电压等级 | E2: 线路重要度 | F2: 线路名称 | G2: 线路段 | H2: 杆塔数量（基） | I2: 计划开始日期 | J2: 计划结束日期 | K2: 是否停电 | L2: 责任单位 | M2: 中心负责人 | N2: 线路专责人 | O2: 责任中心 | P2: 计划完成数 | Q2: 实际开始日期 | R2: 实际结束日期 | S2: 实际完成数 | T2: 合格数量 | U2: 完成率 | V2: 合格率 | W2: 备注（未能按时完成原因） | X2: 所有线路段 | Y2: 待完成线路段 | Z2: 已完成线路段 | AA2: 工作地点和内容 | AB2: 计划编号 | AC2: 完成情况 | AD2: 完成月份 | AE2: 计划临期提醒
A3: 1 | B3: 预试 | C3: 考核 | D3: 220kV | E3: 重要（5-9月）、其余时段关注 | F3: 北茶甲线 | G3: 进出线段：#01-#03；中间段：#11-#54 | H3: 47 | I3: 2025-10-01 | J3: 2025-10-30 | K3: 否 | L3: 输电管理二所 | M3: 蔡昊晖 | N3: 邓茂村 | O3: 白云中心 | P3: 47 | X3: ['#01', '#02', '#03', '#11', '#12', '#13', '#14', '#15', '#16', '#17', '#18', '#19', '#20', '#21', '#22', '#23', '#24', '#25', '#26', '#27', '#28', '#29', '#30', '#31', '#32', '#33', '#34', '#35', '#36', '#37', '#38', '#39', '#40', '#41', '#42', '#43', '#44', '#45', '#46', '#47', '#48', '#49', '#50', '#51', '#52', '#53', '#54'] | Y3: ['#01', '#02', '#03', '#11', '#12', '#13', '#14', '#15', '#16', '#17', '#18', '#19', '#20', '#21', '#22', '#23', '#24', '#25', '#26', '#27', '#28', '#29', '#30', '#31', '#32', '#33', '#34', '#35', '#36', '#37', '#38', '#39', '#40', '#41', '#42', '#43', '#44', '#45', '#46', '#47', '#48', '#49', '#50', '#51', '#52', '#53', '#54']
A4: 2 | B4: 预试 | C4: 考核 | D4: 220kV | E4: 重要（5-9月）、其余时段关注 | F4: 北茶乙线 | G4: 进出线段：#01-#03；中间段：#11-#54 | H4: 47 | I4: 2025-10-01 | J4: 2025-10-30 | K4: 否 | L4: 输电管理二所 | M4: 蔡昊晖 | N4: 邓茂村 | O4: 白云中心 | P4: 47 | X4: ['#01', '#02', '#03', '#11', '#12', '#13', '#14', '#15', '#16', '#17', '#18', '#19', '#20', '#21', '#22', '#23', '#24', '#25', '#26', '#27', '#28', '#29', '#30', '#31', '#32', '#33', '#34', '#35', '#36', '#37', '#38', '#39', '#40', '#41', '#42', '#43', '#44', '#45', '#46', '#47', '#48', '#49', '#50', '#51', '#52', '#53', '#54'] | Y4: ['#01', '#02', '#03', '#11', '#12', '#13', '#14', '#15', '#16', '#17', '#18', '#19', '#20', '#21', '#22', '#23', '#24', '#25', '#26', '#27', '#28', '#29', '#30', '#31', '#32', '#33', '#34', '#35', '#36', '#37', '#38', '#39', '#40', '#41', '#42', '#43', '#44', '#45', '#46', '#47', '#48', '#49', '#50', '#51', '#52', '#53', '#54']
A5: 3 | B5: 预试 | C5: 考核 | D5: 220kV | E5: 重要（5-9月）、其余时段关注 | F5: 北嘉甲线 | G5: 进出线段：#27-#29；中间段：#17-#26 | H5: 13 | I5: 2025-10-01 | J5: 2025-10-30 | K5: 否 | L5: 输电管理二所 | M5: 蔡昊晖 | N5: 梁伟照 | O5: 白云中心 | P5: 13 | X5: ['#27', '#28', '#29', '#17', '#18', '#19', '#20', '#21', '#22', '#23', '#24', '#25', '#26'] | Y5: ['#27', '#28', '#29', '#17', '#18', '#19', '#20', '#21', '#22', '#23', '#24', '#25', '#26']
A6: 4 | B6: 预试 | C6: 考核 | D6: 220kV | E6: 重要（5-9月）、其余时段关注 | F6: 北嘉乙线 | G6: 进出线段：#27-#29；中间段：#17-#26 | H6: 13 | I6: 2025-10-01 | J6: 2025-10-30 | K6: 否 | L6: 输电管理二所 | M6: 蔡昊晖 | N6: 梁伟照 | O6: 白云中心 | P6: 13 | X6: ['#27', '#28', '#29', '#17', '#18', '#19', '#20', '#21', '#22', '#23', '#24', '#25', '#26'] | Y6: ['#27', '#28', '#29', '#17', '#18', '#19', '#20', '#21', '#22', '#23', '#24', '#25', '#26']
A7: 5 | B7: 预试 | C7: 考核 | D7: 500kV | E7: 关键 | F7: 北增甲线 | G7: 进出线段：#01-#03；中间段：#04-#62 | H7: 62 | I7: 2025-10-01 | J7: 2025-10-30 | K7: 否 | L7: 输电管理二所 | M7: 蔡昊晖 | N7: 潘永洪 | O7: 白云中心 | P7: 62 | X7: ['#01', '#02', '#03', '#04', '#05', '#06', '#07', '#08', '#09', '#10', '#11', '#12', '#13', '#14', '#15', '#16', '#17', '#18', '#19', '#20', '#21', '#22', '#23', '#24', '#25', '#26', '#27', '#28', '#29', '#30', '#31', '#32', '#33', '#34', '#35', '#36', '#37', '#38', '#39', '#40', '#41', '#42', '#43', '#44', '#45', '#46', '#47', '#48', '#49', '#50', '#51', '#52', '#53', '#54', '#55', '#56', '#57', '#58', '#59', '#60', '#61', '#62'] | Y7: ['#01', '#02', '#03', '#04', '#05', '#06', '#07', '#08', '#09', '#10', '#11', '#12', '#13', '#14', '#15', '#16', '#17', '#18', '#19', '#20', '#21', '#22', '#23', '#24', '#25', '#26', '#27', '#28', '#29', '#30', '#31', '#32', '#33', '#34', '#35', '#36', '#37', '#38', '#39', '#40', '#41', '#42', '#43', '#44', '#45', '#46', '#47', '#48', '#49', '#50', '#51', '#52', '#53', '#54', '#55', '#56', '#57', '#58', '#59', '#60', '#61', '#62']
A8: 6 | B8: 预试 | C8: 考核 | D8: 500kV | E8: 关键 | F8: 北增乙线 | G8: 进出线段：#01-#03；中间段：#04-#58 | H8: 58 | I8: 2025-10-01 | J8: 2025-10-30 | K8: 否 | L8: 输电管理二所 | M8: 蔡昊晖 | N8: 潘永洪 | O8: 白云中心 | P8: 58 | X8: ['#01', '#02', '#03', '#04', '#05', '#06', '#07', '#08', '#09', '#10', '#11', '#12', '#13', '#14', '#15', '#16', '#17', '#18', '#19', '#20', '#21', '#22', '#23', '#24', '#25', '#26', '#27', '#28', '#29', '#30', '#31', '#32', '#33', '#34', '#35', '#36', '#37', '#38', '#39', '#40', '#41', '#42', '#43', '#44', '#45', '#46', '#47', '#48', '#49', '#50', '#51', '#52', '#53', '#54', '#55', '#56', '#57', '#58'] | Y8: ['#01', '#02', '#03', '#04', '#05', '#06', '#07', '#08', '#09', '#10', '#11', '#12', '#13', '#14', '#15', '#16', '#17', '#18', '#19', '#20', '#21', '#22', '#23', '#24', '#25', '#26', '#27', '#28', '#29', '#30', '#31', '#32', '#33', '#34', '#35', '#36', '#37', '#38', '#39', '#40', '#41', '#42', '#43', '#44', '#45', '#46', '#47', '#48', '#49', '#50', '#51', '#52', '#53', '#54', '#55', '#56', '#57', '#58']
A9: 7 | B9: 预试 | C9: 考核 | D9: 110kV | E9: 重要 | F9: 茶纲线 | G9: 进出线段：#01-#03；中间段：#04-#61 | H9: 58 | I9: 2025-10-01 | J9: 2025-10-30 | K9: 否 | L9: 输电管理二所 | M9: 蔡昊晖 | N9: 黄灿明 | O9: 白云中心 | P9: 58 | X9: ['#01', '#02', '#03', '#04', '#05', '#06', '#07', '#08', '#09', '#10', '#11', '#12', '#13', '#14', '#15', '#16', '#17', '#18', '#19', '#20', '#21', '#22', '#23', '#24', '#25', '#26', '#27', '#28', '#29', '#30', '#31', '#32', '#33', '#34', '#35', '#36', '#37', '#38', '#39', '#40', '#41', '#42', '#43', '#44', '#45', '#46', '#47', '#48', '#49', '#50', '#51', '#52', '#53', '#54', '#55', '#56', '#57', '#58', '#59', '#60', '#61'] | Y9: ['#01', '#02', '#03', '#04', '#05', '#06', '#07', '#08', '#09', '#10', '#11', '#12', '#13', '#14', '#15', '#16', '#17', '#18', '#19', '#20', '#21', '#22', '#23', '#24', '#25', '#26', '#27', '#28', '#29', '#30', '#31', '#32', '#33', '#34', '#35', '#36', '#37', '#38', '#39', '#40', '#41', '#42', '#43', '#44', '#45', '#46', '#47', '#48', '#49', '#50', '#51', '#52', '#53', '#54', '#55', '#56', '#57', '#58', '#59', '#60', '#61']
A10: 8 | B10: 预试 | C10: 考核 | D10: 110kV | E10: 重要（5-9月）、其余时段关注 | F10: 汉钟乙线 | G10: 中间段：#09-#14 | H10: 6 | I10: 2025-10-01 | J10: 2025-10-30 | K10: 否 | L10: 输电管理二所 | M10: 蔡昊晖 | N10: 张春勇 | O10: 白云中心 | P10: 6 | X10: ['#09', '#10', '#11', '#12', '#13', '#14'] | Y10: ['#09', '#10', '#11', '#12', '#13', '#14']
A11: 9 | B11: 预试 | C11: 考核 | D11: 110kV | E11: 重要（5-9月）、其余时段关注 | F11: 汉钟线 | G11: 中间段：#09-#14 | H11: 6 | I11: 2025-10-01 | J11: 2025-10-30 | K11: 否 | L11: 输电管理二所 | M11: 蔡昊晖 | N11: 张春勇 | O11: 白云中心 | P11: 6 | X11: ['#09', '#10', '#11', '#12', '#13', '#14'] | Y11: ['#09', '#10', '#11', '#12', '#13', '#14']
A12: 10 | B12: 预试 | C12: 考核 | D12: 110kV | E12: 关注 | F12: 茶汉甲线 | G12: 中间段：#11-#71 | H12: 71 | I12: 2025-10-01 | J12: 2025-10-30 | K12: 否 | L12: 输电管理二所 | M12: 蔡昊晖 | N12: 黄灿明 | O12: 白云中心 | P12: 71 | X12: ['#11', '#12', '#13', '#14', '#15', '#16', '#17', '#18', '#19', '#20', '#21', '#22', '#23', '#24', '#25', '#26', '#27', '#28', '#29', '#30', '#31', '#32', '#33', '#34', '#35', '#36', '#37', '#38', '#39', '#40', '#41', '#42', '#43', '#44', '#45', '#46', '#47', '#48', '#49', '#50', '#51', '#52', '#53', '#54', '#55', '#56', '#57', '#58', '#59', '#60', '#61', '#62', '#63', '#64', '#65', '#66', '#67', '#68', '#69', '#70', '#71'] | Y12: ['#11', '#12', '#13', '#14', '#15', '#16', '#17', '#18', '#19', '#20', '#21', '#22', '#23', '#24', '#25', '#26', '#27', '#28', '#29', '#30', '#31', '#32', '#33', '#34', '#35', '#36', '#37', '#38', '#39', '#40', '#41', '#42', '#43', '#44', '#45', '#46', '#47', '#48', '#49', '#50', '#51', '#52', '#53', '#54', '#55', '#56', '#57', '#58', '#59', '#60', '#61', '#62', '#63', '#64', '#65', '#66', '#67', '#68', '#69', '#70', '#71']
A13: 11 | B13: 预试 | C13: 考核 | D13: 110kV | E13: 关注 | F13: 茶汉甲线太和乙支线 | G13: 进出线段：#00 | H13: 1 | I13: 2025-10-01 | J13: 2025-10-30 | K13: 否 | L13: 输电管理二所 | M13: 蔡昊晖 | N13: 黄灿明 | O13: 白云中心 | P13: 1 | X13: ['#00'] | Y13: ['#00']
A14: 12 | B14: 预试 | C14: 考核 | D14: 110kV | E14: 关注 | F14: 茶汉甲线民营甲支线 | G14: 进出线段：#00-#02 | H14: 3 | I14: 2025-10-01 | J14: 2025-10-30 | K14: 否 | L14: 输电管理二所 | M14: 蔡昊晖 | N14: 黄灿明 | O14: 白云中心 | P14: 3 | X14: ['#00', '#01', '#02'] | Y14: ['#00', '#01', '#02']
... A44: 42 | B44: 预试 | C44: 考核 | D44: 110kV | E44: 重要 | F44: 汉纲线 | G44: 中间段：#19-#33 | H44: 15 | I44: 2025-10-01 | J44: 2025-10-30 | K44: 否 | L44: 输电管理二所 | M44: 蔡昊晖 | N44: 张春勇 | O44: 白云中心 | P44: 15 | X44: ['#19', '#20', '#21', '#22', '#23', '#24', '#25', '#26', '#27', '#28', '#29', '#30', '#31', '#32', '#33'] | Y44: ['#19', '#20', '#21', '#22', '#23', '#24', '#25', '#26', '#27', '#28', '#29', '#30', '#31', '#32', '#33']
A45: 43 | B45: 预试 | C45: 考核 | D45: 220kV | E45: 重要（5-9月）、其余时段一般 | F45: 汉雀甲线 | G45: 中间段：#33-#34 | H45: 2 | I45: 2025-10-01 | J45: 2025-10-30 | K45: 否 | L45: 输电管理二所 | M45: 蔡昊晖 | O45: 白云中心 | P45: 2 | X45: ['#33', '#34'] | Y45: ['#33', '#34']
A46: 44 | B46: 预试 | C46: 考核 | D46: 220kV | E46: 重要（5-9月）、其余时段一般 | F46: 汉雀乙线 | G46: 中间段：#33-#34 | H46: 2 | I46: 2025-10-01 | J46: 2025-10-30 | K46: 否 | L46: 输电管理二所 | M46: 蔡昊晖 | O46: 白云中心 | P46: 2 | X46: ['#33', '#34'] | Y46: ['#33', '#34']
A47: 45 | B47: 预试 | C47: 考核 | D47: 220kV | E47: 重要（5-9月）、其余时段一般 | F47: 北郭甲线 | G47: 进出段：#01-#03、#33-#35 | H47: 6 | I47: 2024-01-01 | J47: 2024-04-01 | K47: 否 | L47: 输电管理二所 | M47: 蔡昊晖 | N47: 戴国斌 | O47: 白云中心 | P47: 6 | X47: ['#01', '#02', '#03', '#33', '#34', '#35'] | Y47: ['#01', '#02', '#03', '#33', '#34', '#35']
A48: 46 | B48: 预试 | C48: 考核 | D48: 220kV | E48: 重要（5-9月）、其余时段一般 | F48: 北郭乙线 | G48: 进出段：#01-#03、#33-#35 | H48: 6 | I48: 2024-01-01 | J48: 2024-04-01 | K48: 否 | L48: 输电管理二所 | M48: 蔡昊晖 | N48: 戴国斌 | O48: 白云中心 | P48: 6 | X48: ['#01', '#02', '#03', '#33', '#34', '#35'] | Y48: ['#01', '#02', '#03', '#33', '#34', '#35']
A49: 47 | B49: 预试 | C49: 考核 | D49: 220kV | E49: 重要（5-9月）、其余时段一般 | F49: 北石甲线 | G49: 进出段：#91-#93 | H49: 3 | I49: 2024-01-01 | J49: 2024-04-01 | K49: 否 | L49: 输电管理二所 | M49: 蔡昊晖 | N49: 曾宇 | O49: 白云中心 | P49: 3 | X49: ['#91', '#92', '#93'] | Y49: ['#91', '#92', '#93']
A50: 48 | B50: 预试 | C50: 考核 | D50: 220kV | E50: 重要（5-9月）、其余时段一般 | F50: 北石乙线 | G50: 进出段：#91-#93 | H50: 3 | I50: 2024-01-01 | J50: 2024-04-01 | K50: 否 | L50: 输电管理二所 | M50: 蔡昊晖 | N50: 曾宇 | O50: 白云中心 | P50: 3 | X50: ['#91', '#92', '#93'] | Y50: ['#91', '#92', '#93']
A51: 49 | B51: 预试 | C51: 考核 | D51: 220kV | E51: 重要（5-9月）、其余时段关注 | F51: 北浔甲线 | G51: 进出段：#126-#128 | H51: 3 | I51: 2024-01-01 | J51: 2024-04-01 | K51: 否 | L51: 输电管理二所 | M51: 蔡昊晖 | N51: 曾宇 | O51: 白云中心 | P51: 3 | X51: ['#126', '#127', '#128'] | Y51: ['#126', '#127', '#128']
A52: 50 | B52: 预试 | C52: 考核 | D52: 220kV | E52: 重要（5-9月）、其余时段关注 | F52: 北浔乙线 | G52: 进出段：#126-#128 | H52: 3 | I52: 2024-01-01 | J52: 2024-04-01 | K52: 否 | L52: 输电管理二所 | M52: 蔡昊晖 | N52: 曾宇 | O52: 白云中心 | P52: 3 | X52: ['#126', '#127', '#128'] | Y52: ['#126', '#127', '#128']
A53: 51 | B53: 预试 | C53: 考核 | D53: 110kV | E53: 关键 | F53: 芳花增甲线 | G53: 进出段：#01-#03、#17-#22、#25-#27 中间段：#04-#16、#23-#24 | H53: 27 | I53: 2024-01-01 | J53: 2024-04-01 | K53: 否 | L53: 输电管理二所 | M53: 蔡昊晖 | N53: 林杰 | O53: 白云中心 | P53: 27 | X53: ['#01', '#02', '#03', '#17', '#18', '#19', '#20', '#21', '#22', '#25', '#26', '#27', '#04', '#05', '#06', '#07', '#08', '#09', '#10', '#11', '#12', '#13', '#14', '#15', '#16', '#23', '#24'] | Y53: ['#01', '#02', '#03', '#17', '#18', '#19', '#20', '#21', '#22', '#25', '#26', '#27', '#04', '#05', '#06', '#07', '#08', '#09', '#10', '#11', '#12', '#13', '#14', '#15', '#16', '#23', '#24']
A54: 52 | B54: 预试 | C54: 考核 | D54: 110kV | E54: 关键 | F54: 芳花增甲线冲口甲支线 | G54: 进出段：#00-#02、#16-#18 中间段：#03-#15 | H54: 18 | I54: 2024-01-01 | J54: 2024-04-01 | K54: 否 | L54: 输电管理二所 | M54: 蔡昊晖 | N54: 林杰 | O54: 白云中心 | P54: 18 | X54: ['#00', '#01', '#02', '#16', '#17', '#18', '#03', '#04', '#05', '#06', '#07', '#08', '#09', '#10', '#11', '#12', '#13', '#14', '#15'] | Y54: ['#00', '#01', '#02', '#16', '#17', '#18', '#03', '#04', '#05', '#06', '#07', '#08', '#09', '#10', '#11', '#12', '#13', '#14', '#15']
A55: 53 | B55: 预试 | C55: 考核 | D55: 110kV | E55: 关键 | F55: 芳花增乙线 | G55: 进出段：#01-#03、#17-#22、#25-#27 中间段：#04-#16、#23-#24 | H55: 27 | I55: 2024-01-01 | J55: 2024-04-01 | K55: 否 | L55: 输电管理二所 | M55: 蔡昊晖 | N55: 林杰 | O55: 白云中心 | P55: 27 | X55: ['#01', '#02', '#03', '#17', '#18', '#19', '#20', '#21', '#22', '#25', '#26', '#27', '#04', '#05', '#06', '#07', '#08', '#09', '#10', '#11', '#12', '#13', '#14', '#15', '#16', '#23', '#24'] | Y55: ['#01', '#02', '#03', '#17', '#18', '#19', '#20', '#21', '#22', '#25', '#26', '#27', '#04', '#05', '#06', '#07', '#08', '#09', '#10', '#11', '#12', '#13', '#14', '#15', '#16', '#23', '#24']
A56: 54 | B56: 预试 | C56: 考核 | D56: 110kV | E56: 关键 | F56: 芳花增乙线冲口乙支线 | G56: 进出段：#00-#02、#16-#18 中间段：#03-#15 | H56: 18 | I56: 2024-01-01 | J56: 2024-04-01 | K56: 否 | L56: 输电管理二所 | M56: 蔡昊晖 | N56: 林杰 | O56: 白云中心 | P56: 18 | X56: ['#00', '#01', '#02', '#16', '#17', '#18', '#03', '#04', '#05', '#06', '#07', '#08', '#09', '#10', '#11', '#12', '#13', '#14', '#15'] | Y56: ['#00', '#01', '#02', '#16', '#17', '#18', '#03', '#04', '#05', '#06', '#07', '#08', '#09', '#10', '#11', '#12', '#13', '#14', '#15']
A57: 55 | B57: 预试 | C57: 考核 | D57: 110kV | E57: 重要 | F57: 蚌郭甲线 | G57: 进出段#01-#03、#41-#43 中间段：#04-#40 | H57: 43 | I57: 2024-01-01 | J57: 2024-04-01 | K57: 否 | L57: 输电管理二所 | M57: 蔡昊晖 | N57: 姚河新 | O57: 白云中心 | P57: 43 | X57: ['#01', '#02', '#03', '#41', '#42', '#43', '#04', '#05', '#06', '#07', '#08', '#09', '#10', '#11', '#12', '#13', '#14', '#15', '#16', '#17', '#18', '#19', '#20', '#21', '#22', '#23', '#24', '#25', '#26', '#27', '#28', '#29', '#30', '#31', '#32', '#33', '#34', '#35', '#36', '#37', '#38', '#39', '#40'] | Y57: ['#01', '#02', '#03', '#41', '#42', '#43', '#04', '#05', '#06', '#07', '#08', '#09', '#10', '#11', '#12', '#13', '#14', '#15', '#16', '#17', '#18', '#19', '#20', '#21', '#22', '#23', '#24', '#25', '#26', '#27', '#28', '#29', '#30', '#31', '#32', '#33', '#34', '#35', '#36', '#37', '#38', '#39', '#40']
A58: 56 | B58: 预试 | C58: 考核 | D58: 110kV | E58: 一般 | F58: 蚌嘉甲线 | G58: 进出段#01-#03、#18-#20 中间段：#04-#17 | H58: 20 | I58: 2024-01-01 | J58: 2024-04-01 | K58: 否 | L58: 输电管理二所 | M58: 蔡昊晖 | N58: 姚河新 | O58: 白云中心 | P58: 20 | X58: ['#01', '#02', '#03', '#18', '#19', '#20', '#04', '#05', '#06', '#07', '#08', '#09', '#10', '#11', '#12', '#13', '#14', '#15', '#16', '#17'] | Y58: ['#01', '#02', '#03', '#18', '#19', '#20', '#04', '#05', '#06', '#07', '#08', '#09', '#10', '#11', '#12', '#13', '#14', '#15', '#16', '#17']
... A203: 201 | B203: 预试 | C203: 考核 | D203: 500kV | E203: 关键 | F203: 北增乙线 | G203: 中间段：#83-#96 进出段：#97-#99 | H203: 27 | I203: 2025-08-01 | J203: 2025-08-30 | K203: 否 | L203: 输电管理二所 | M203: 吴达 | N203: 王立新 | O203: 天河中心 | P203: 27 | X203: ['#83', '#84', '#85', '#86', '#87', '#88', '#89', '#90', '#91', '#92', '#93', '#94', '#95', '#96', '#97', '#98', '#99'] | Y203: ['#83', '#84', '#85', '#86', '#87', '#88', '#89', '#90', '#91', '#92', '#93', '#94', '#95', '#96', '#97', '#98', '#99']

Sheet 3、电缆线路交叉互联预试
A1: 输电管理二所2025年预试检测计划 （电缆线路交叉互联预试：外护套绝缘电阻、护层过电压保护器测试1次/6年，超三十年电缆：1次/3年） 对于新投运的设备，在投运后一年内及时进行首次预防性试验。预防性试验和检修周期在首检完成后开始计算。
A2: 序号 | B2: 工作类型 | C2: 电压等级 | D2: 变电站/线路 | E2: 线路重要度 | F2: 工作内容 | G2: 预试到期时间 | H2: 计划开始日期 | I2: 计划结束日期 | J2: 是否停电 | K2: 责任单位 | L2: 中心负责人 | M2: 责任中心 | N2: 计划完成护层电阻测试数（相） | O2: 计划完成保护器测试数 | P2: 实际完成数 | Q2: 合格数 | R2: 完成率 | S2: 合格率 | T2: 计划完成接地电阻测试数 | U2: 实际完成数.1 | V2: 合格数.1 | W2: 完成率.1 | X2: 合格率.1 | Y2: 备注（未按时完成原因） | Z2: 实际开始日期 | AA2: 实际结束日期 | AB2: 工作地点和内容 | AC2: 计划编号 | AD2: 完成情况 | AE2: 完成月份 | AF2: 计划临期提醒
A3: 1 | B3: 预试 | C3: 110 | D3: 芳鹤甲线 | E3: 一般 | F3: 交叉互联试验 | G3: 45839 | H3: 45658 | I3: 45839 | J3: 是 | K3: 输电管理二所 | L3: 蔡昊晖 | M3: 白云中心 | N3: 3 | O3: 3 | T3: 0
A4: 2 | B4: 预试 | C4: 110 | D4: 医联线 | E4: 一般 | F4: 交叉互联试验 | G4: 45870 | H4: 45658 | I4: 45870 | J4: 是 | K4: 输电管理二所 | L4: 蔡昊晖 | M4: 白云中心 | N4: 9 | O4: 6 | T4: 0
A5: 3 | B5: 预试 | C5: 110 | D5: 医福线 | E5: 一般 | F5: 交叉互联试验 | G5: 45870 | H5: 45658 | I5: 45870 | J5: 是 | K5: 输电管理二所 | L5: 蔡昊晖 | M5: 白云中心 | N5: 9 | O5: 6 | T5: 0
A6: 4 | B6: 预试 | C6: 110 | D6: 蚌嘉甲线 | E6: 一般 | F6: 交叉互联试验 | G6: 45901 | H6: 45658 | I6: 45901 | J6: 是 | K6: 输电管理二所 | L6: 蔡昊晖 | M6: 白云中心 | N6: 9 | O6: 6 | T6: 2
A7: 5 | B7: 预试 | C7: 110 | D7: 蚌郭甲线 | E7: 重要 | F7: 交叉互联试验 | G7: 45901 | H7: 45658 | I7: 45901 | J7: 是 | K7: 输电管理二所 | L7: 蔡昊晖 | M7: 白云中心 | N7: 9 | O7: 6 | T7: 2
A8: 6 | B8: 预试 | C8: 110 | D8: 蚌江线 | E8: 重要 | F8: 交叉互联试验 | G8: 45778 | H8: 45658 | I8: 45778 | J8: 是 | K8: 输电管理二所 | L8: 蔡昊晖 | M8: 白云中心 | N8: 9 | O8: 6 | T8: 2
A9: 7 | B9: 预试 | C9: 110 | D9: 蚌郭乙线 | E9: 一般 | F9: 交叉互联试验 | G9: 45778 | H9: 45658 | I9: 45778 | J9: 是 | K9: 输电管理二所 | L9: 蔡昊晖 | M9: 白云中心 | N9: 9 | O9: 6 | T9: 2
A10: 8 | B10: 预试 | C10: 110 | D10: 环三甲线 | E10: 重要（5-9月）、其余时段一般 | F10: 交叉互联试验 | G10: 46113 | H10: 45658 | I10: 46113 | J10: 是 | K10: 输电管理二所 | L10: 蔡昊晖 | M10: 白云中心 | N10: 9 | O10: 3 | T10: 3
A11: 9 | B11: 预试 | C11: 110 | D11: 环三乙线 | E11: 重要（5-9月）、其余时段关注 | F11: 交叉互联试验 | G11: 46113 | H11: 45658 | I11: 46113 | J11: 是 | K11: 输电管理二所 | L11: 蔡昊晖 | M11: 白云中心 | N11: 9 | O11: 3 | T11: 3
A12: 10 | B12: 预试 | C12: 110 | D12: 环涌甲线南德甲支线 | E12: 一般 | F12: 交叉互联试验 | G12: 45778 | H12: 45658 | I12: 45778 | J12: 是 | K12: 输电管理二所 | L12: 蔡昊晖 | M12: 白云中心 | N12: 21 | O12: 9 | T12: 2
A13: 11 | B13: 预试 | C13: 110 | D13: 环涌乙线南德乙支线 | E13: 一般 | F13: 交叉互联试验 | G13: 45778 | H13: 45658 | I13: 45778 | J13: 是 | K13: 输电管理二所 | L13: 蔡昊晖 | M13: 白云中心 | N13: 21 | O13: 9 | T13: 2
A14: 12 | B14: 预试 | C14: 110 | D14: 泮金线 | E14: 重要 | F14: 交叉互联试验 | G14: 46082 | H14: 45658 | I14: 46082 | J14: 是 | K14: 输电管理二所 | L14: 蔡昊晖 | M14: 白云中心 | N14: 18 | O14: 12 | T14: 5
... A21: 19 | B21: 预试 | C21: 110 | D21: 环大德线 | E21: 一般 | F21: 交叉互联试验 | G21: 45778 | H21: 45658 | I21: 45778 | J21: 是 | K21: 输电管理二所 | L21: 蔡昊晖 | M21: 白云中心 | N21: 42 | O21: 27 | T21: 2
A22: 20 | B22: 预试 | C22: 110kV | D22: 梨利线 | E22: 重要（5-9月）、其余时段一般 | F22: 交叉互联试验 | G22: 45864 | H22: 45658 | I22: 45868 | J22: 是 | K22: 输电管理二所 | L22: 蔡昊晖 | M22: 白云中心 | N22: 21 | O22: 15 | T22: 3
A23: 21 | B23: 预试 | C23: 110kV | D23: 汉纲线 | E23: 重要 | F23: 交叉互联试验 | G23: 45805 | H23: 45659 | I23: 45807 | J23: 是 | K23: 输电管理二所 | L23: 蔡昊晖 | M23: 白云中心 | N23: 3 | O23: 3 | T23: 3
A24: 22 | B24: 预试 | C24: 110kV | D24: 旋石线 | E24: 重要 | F24: 交叉互联试验 | G24: 45944 | H24: 45660 | I24: 45960 | J24: 是 | K24: 输电管理二所 | L24: 蔡昊晖 | M24: 白云中心 | N24: 18 | O24: 12 | T24: 8
A25: 23 | B25: 预试 | C25: 110kV | D25: 茶观乙线 | E25: 关注 | F25: 交叉互联试验 | G25: 45811 | H25: 45662 | I25: 45838 | J25: 是 | K25: 输电管理二所 | L25: 蔡昊晖 | M25: 白云中心 | N25: 3 | O25: 3 | T25: 12
A26: 24 | B26: 预试 | C26: 110kV | D26: 泮关龙线 | E26: 重要 | F26: 交叉互联试验 | G26: 45962 | H26: 45658 | I26: 45962 | J26: 是 | K26: 输电管理二所 | L26: 蔡昊晖 | M26: 白云中心 | N26: 21 | O26: 15 | T26: 4
A27: 25 | B27: 预试 | C27: 110kV | D27: 林军线 | E27: 重要（5-9月）、其余时段关注 | F27: 交叉互联试验 | G27: 45839 | H27: 45658 | I27: 45839 | J27: 是 | K27: 输电管理二所 | L27: 叶翔 | M27: 花都中心 | N27: 6 | O27: 6 | T27: 12
A28: 26 | B28: 预试 | C28: 110kV | D28: 林军线杨屋乙支线 | E28: 重要（5-9月）、其余时段关注 | F28: 交叉互联试验 | G28: 46082 | H28: 45658 | I28: 45992 | J28: 是 | K28: 输电管理二所 | L28: 叶翔 | M28: 花都中心 | N28: 9 | O28: 6 | T28: 12
A29: 27 | B29: 预试 | C29: 110kV | D29: 林军芙线 | E29: 重要（5-9月）、其余时段一般 | F29: 交叉互联试验 | G29: 45839 | H29: 45658 | I29: 45839 | J29: 是 | K29: 输电管理二所 | L29: 叶翔 | M29: 花都中心 | N29: 9 | O29: 9 | T29: 18
A30: 28 | B30: 预试 | C30: 110kV | D30: 林军芙线杨屋甲支线 | E30: 重要（5-9月）、其余时段一般 | F30: 交叉互联试验 | G30: 46082 | H30: 45658 | I30: 45992 | J30: 是 | K30: 输电管理二所 | L30: 叶翔 | M30: 花都中心 | N30: 9 | O30: 6 | T30: 12
A31: 29 | B31: 预试 | C31: 110kV | D31: 林乐公线雅宝甲支线 | E31: 关注 | F31: 交叉互联试验 | G31: 45748 | H31: 45658 | I31: 45748 | J31: 是 | K31: 输电管理二所 | L31: 叶翔 | M31: 花都中心 | N31: 9 | O31: 9 | T31: 15
A32: 30 | B32: 预试 | C32: 110kV | D32: 益田甲线雅宝乙支线 | E32: 关注 | F32: 交叉互联试验 | G32: 45931 | H32: 45658 | I32: 45931 | J32: 是 | K32: 输电管理二所 | L32: 叶翔 | M32: 花都中心 | N32: 9 | O32: 9 | T32: 15
A33: 31 | B33: 预试 | C33: 110kV | D33: 镜合龙凤文线 | E33: 一般 | F33: 交叉互联试验 | G33: 45778 | H33: 45658 | I33: 45778 | J33: 是 | K33: 输电管理二所 | L33: 叶翔 | M33: 花都中心 | N33: 51 | O33: 45 | T33: 75
... A54: 52 | B54: 预试 | C54: 110kV | D54: 永梅线 | E54: 重要 | F54: 交叉互联试验 | G54: 45870 | H54: 45870 | I54: 45899 | J54: 是 | K54: 输电管理二所 | L54: 吴达 | M54: 天河中心 | N54: 18 | O54: 12 | T54: 2

Sheet 4、终端场避雷器试验
A1: 输电管理二所2025年预试检测计划 （终端场避雷器带电试验：新投运后半年内测量一次，运行一年后每年雷雨季前1次。 终端场避雷器停电试验：220kV：1次/3年，110kV：1次/6年，超30年寿命电缆：1次/3年）。 变电站内避雷器以其保护对象区分运维部门，即只要直接保护了变电设备或间隔的避雷器由变电部门运行管理（同时保护了输电、变电设备的也属此类）；仅直接保护输电设备但未直接保护变电设备的避雷器由输电部门运行管理。 对于新投运的设备，在投运后一年内及时进行首次预防性试验和机构检查，可以及早获取设备运行后的重要状态信息。预防性试验和检修周期在首检完成后开始计算。
A2: 序号 | B2: 工作类型 | C2: 电压等级 | D2: 变电站/线路 | E2: 线路重要度 | F2: 设备设施名称 | G2: 工作内容 | H2: 预试到期时间 | I2: 计划开始日期 | J2: 计划结束日期 | K2: 是否停电 | L2: 责任单位 | M2: 中心负责人 | N2: 责任中心 | O2: 计划完成数（相） | P2: 实际开始日期 | Q2: 实际结束日期 | R2: 实际完成数 | S2: 合格数量 | T2: 完成率 | U2: 合格率 | V2: 备注（未按时完成原因） | W2: 工作地点和内容 | X2: 计划编号 | Y2: 完成情况 | Z2: 完成月份 | AA2: 计划临期提醒
A3: 1 | B3: 预试 | C3: 220kV | D3: 花罗甲线 | E3: 关注 | F3: 沙溪A、B终端场 | G3: 避雷器带电试验 | H3: 2025-04-01 | I3: 2025-01-01 | J3: 2025-04-01 | K3: 否 | L3: 输电管理二所 | M3: 蔡昊晖 | N3: 白云中心 | O3: 6
A4: 2 | B4: 预试 | C4: 220kV | D4: 花泮线 | E4: 一般 | F4: 沙溪A、B终端场 | G4: 避雷器带电试验 | H4: 2025-04-01 | I4: 2025-01-01 | J4: 2025-04-01 | K4: 否 | L4: 输电管理二所 | M4: 蔡昊晖 | N4: 白云中心 | O4: 6
A5: 3 | B5: 预试 | C5: 110kV | D5: 三景桂线 | E5: 一般 | F5: 走马岗终端场 | G5: 避雷器带电试验 | H5: 2025-04-01 | I5: 2025-01-01 | J5: 2025-04-01 | K5: 否 | L5: 输电管理二所 | M5: 蔡昊晖 | N5: 白云中心 | O5: 3
A6: 4 | B6: 预试 | C6: 110kV | D6: 罗南线 | E6: 一般 | F6: 西村电厂终端场 | G6: 避雷器带电试验 | H6: 2025-04-01 | I6: 2025-01-01 | J6: 2025-04-01 | K6: 否 | L6: 输电管理二所 | M6: 蔡昊晖 | N6: 白云中心 | O6: 3
A7: 5 | B7: 预试 | C7: 110kV | D7: 花桃甲线 | E7: 关键 | F7: 茶窖电缆终端场 | G7: 避雷器带电试验 | H7: 2025-04-01 | I7: 2025-01-01 | J7: 2025-04-01 | K7: 否 | L7: 输电管理二所 | M7: 蔡昊晖 | N7: 白云中心 | O7: 3
A8: 6 | B8: 预试 | C8: 110kV | D8: 花桃乙线 | E8: 关键 | F8: 茶窖电缆终端场 | G8: 避雷器带电试验 | H8: 2025-04-01 | I8: 2025-01-01 | J8: 2025-04-01 | K8: 否 | L8: 输电管理二所 | M8: 蔡昊晖 | N8: 白云中心 | O8: 3
A9: 7 | B9: 预试 | C9: 110kV | D9: 芳福聚医线 | E9: 关注 | F9: 三山终端场A、三山终端场B | G9: 避雷器带电试验 | H9: 2025-04-01 | I9: 2025-01-01 | J9: 2025-04-01 | K9: 否 | L9: 输电管理二所 | M9: 蔡昊晖 | N9: 白云中心 | O9: 3
A10: 8 | B10: 预试 | C10: 110kV | D10: 石塘甲线 | E10: 关注 | F10: 白云湖终端场 | G10: 避雷器带电试验 | H10: 2025-04-02 | I10: 2025-01-02 | J10: 2025-04-02 | K10: 否 | L10: 输电管理二所 | M10: 蔡昊晖 | N10: 白云中心 | O10: 3
A11: 9 | B11: 预试 | C11: 110kV | D11: 石塘乙线 | E11: 关注 | F11: 白云湖终端场 | G11: 避雷器带电试验 | H11: 2025-04-03 | I11: 2025-01-03 | J11: 2025-04-03 | K11: 否 | L11: 输电管理二所 | M11: 蔡昊晖 | N11: 白云中心 | O11: 3
A12: 10 | B12: 预试 | C12: 110kV | D12: 郭北泉线 | E12: 重要 | F12: 泉溪终端场 | G12: 避雷器带电试验 | H12: 2025-04-04 | I12: 2025-01-04 | J12: 2025-04-04 | K12: 否 | L12: 输电管理二所 | M12: 蔡昊晖 | N12: 白云中心 | O12: 3
A13: 11 | B13: 预试 | C13: 110kV | D13: 蚌郭甲线广北泉溪甲支线 | E13: 重要 | F13: 泉溪终端场 | G13: 避雷器带电试验 | H13: 2025-04-05 | I13: 2025-01-05 | J13: 2025-04-05 | K13: 否 | L13: 输电管理二所 | M13: 蔡昊晖 | N13: 白云中心 | O13: 3
A14: 12 | B14: 预试 | C14: 110kV | D14: 蚌嘉甲线水沥甲支线 | E14: 一般 | F14: 江人二路终端场 | G14: 避雷器带电试验 | H14: 2025-04-06 | I14: 2025-01-06 | J14: 2025-04-06 | K14: 否 | L14: 输电管理二所 | M14: 蔡昊晖 | N14: 白云中心 | O14: 3
... A79: 77 | B79: 预试 | C79: 220kV | D79: 木麒乙线 | E79: 重要（5-9月）、其余时段关注 | F79: 犀牛站终端场避雷器 | G79: 避雷器带电试验 | H79: 2025-05-30 | I79: 2025-05-01 | J79: 2025-05-30 | K79: 否 | L79: 输电管理二所 | M79: 吴达 | N79: 天河中心 | O79: 3

Sheet 5、电缆护套环流检测
A1: 输电管理二所2025年预试检测计划 （外护套接地电流检测：关键线路：2月1次，重要线路：2月1次，一般及关注线路：6月1次）
A2: 序号 | B2: 工作类型 | C2: 电压等级 | D2: 变电站/线路 | E2: 线路重要度 | F2: 工作内容 | G2: 计划开始日期 | H2: 计划结束日期 | I2: 是否停电 | J2: 责任单位 | K2: 中心负责人 | L2: 责任中心 | M2: 计划完成数(相） | N2: 实际开始日期 | O2: 实际结束日期 | P2: 实际完成数 | Q2: 合格数量 | R2: 完成率 | S2: 合格率 | T2: 备注（未能按时完成原因） | U2: 工作地点和内容 | V2: 计划编号 | W2: 完成情况 | X2: 完成月份 | Y2: 计划临期提醒
A3: 1 | B3: 预试 | C3: 110kV | D3: 空机线 | E3: 重要 | F3: 外护套接地电流检测 | G3: 2025-02-01 | H3: 2025-02-28 | I3: 否 | J3: 输电管理二所 | K3: 叶翔 | L3: 花都中心 | M3: 9
A4: 2 | B4: 预试 | C4: 110kV | D4: 空机线 | E4: 重要 | F4: 外护套接地电流检测 | G4: 2025-04-01 | H4: 2025-04-30 | I4: 否 | J4: 输电管理二所 | K4: 叶翔 | L4: 花都中心 | M4: 9
A5: 3 | B5: 预试 | C5: 110kV | D5: 空机线 | E5: 重要 | F5: 外护套接地电流检测 | G5: 2025-06-01 | H5: 2025-06-30 | I5: 否 | J5: 输电管理二所 | K5: 叶翔 | L5: 花都中心 | M5: 9
A6: 4 | B6: 预试 | C6: 110kV | D6: 空机线 | E6: 重要 | F6: 外护套接地电流检测 | G6: 2025-08-01 | H6: 2025-08-31 | I6: 否 | J6: 输电管理二所 | K6: 叶翔 | L6: 花都中心 | M6: 9
A7: 5 | B7: 预试 | C7: 110kV | D7: 空机线 | E7: 重要 | F7: 外护套接地电流检测 | G7: 2025-10-01 | H7: 2025-10-31 | I7: 否 | J7: 输电管理二所 | K7: 叶翔 | L7: 花都中心 | M7: 9
A8: 6 | B8: 预试 | C8: 110kV | D8: 空机线 | E8: 重要 | F8: 外护套接地电流检测 | G8: 2025-12-01 | H8: 2025-12-31 | I8: 否 | J8: 输电管理二所 | K8: 叶翔 | L8: 花都中心 | M8: 9
A9: 7 | B9: 预试 | C9: 110kV | D9: 金机线 | E9: 重要 | F9: 外护套接地电流检测 | G9: 2025-02-01 | H9: 2025-02-28 | I9: 否 | J9: 输电管理二所 | K9: 叶翔 | L9: 花都中心 | M9: 3
A10: 8 | B10: 预试 | C10: 110kV | D10: 金机线 | E10: 重要 | F10: 外护套接地电流检测 | G10: 2025-04-01 | H10: 2025-04-30 | I10: 否 | J10: 输电管理二所 | K10: 叶翔 | L10: 花都中心 | M10: 3
A11: 9 | B11: 预试 | C11: 110kV | D11: 金机线 | E11: 重要 | F11: 外护套接地电流检测 | G11: 2025-06-01 | H11: 2025-06-30 | I11: 否 | J11: 输电管理二所 | K11: 叶翔 | L11: 花都中心 | M11: 3
A12: 10 | B12: 预试 | C12: 110kV | D12: 金机线 | E12: 重要 | F12: 外护套接地电流检测 | G12: 2025-08-01 | H12: 2025-08-31 | I12: 否 | J12: 输电管理二所 | K12: 叶翔 | L12: 花都中心 | M12: 3
A13: 11 | B13: 预试 | C13: 110kV | D13: 金机线 | E13: 重要 | F13: 外护套接地电流检测 | G13: 2025-10-01 | H13: 2025-10-31 | I13: 否 | J13: 输电管理二所 | K13: 叶翔 | L13: 花都中心 | M13: 3
A14: 12 | B14: 预试 | C14: 110kV | D14: 金机线 | E14: 重要 | F14: 外护套接地电流检测 | G14: 2025-12-01 | H14: 2025-12-31 | I14: 否 | J14: 输电管理二所 | K14: 叶翔 | L14: 花都中心 | M14: 3
... A959: 957 | B959: 预试 | C959: 110kV | D959: 环大德线 | E959: 一般 | F959: 外护套接地电流检测 | G959: 2025-07-01 | H959: 2025-12-01 | I959: 否 | J959: 输电管理二所 | K959: 蔡昊晖 | L959: 白云中心 | M959: 12

Sheet 6、电缆终端红外检测
A1: 输电管理二所2025年预试检测计划 （电缆终端红外检测（不含老旧电缆）：关键线路：2月1次，重要线路：2月1次，一般及关注线路110kV：上、下半年各1次；220kV：每季度1次） （超三十年老旧电缆终端红外检测：关键线路：2月1次，重要线路：2月1次，一般及关注线路：每季度1次）
A2: 序号 | B2: 工作类型 | C2: 电压等级 | D2: 变电站/线路 | E2: 线路重要度 | F2: 工作内容 | G2: 计划开始日期 | H2: 计划结束日期 | I2: 是否停电 | J2: 责任单位 | K2: 中心负责人 | L2: 责任中心 | M2: 每次计划完成数（相） | N2: 实际开始日期 | O2: 实际结束日期 | P2: 每次实际完成数 | Q2: 合格数量 | R2: 完成率 | S2: 合格率 | T2: 备注（未按时完成原因） | U2: 工作地点和内容 | V2: 计划编号 | W2: 完成情况 | X2: 完成月份 | Y2: 计划临期提醒
A3: 1 | B3: 预试 | C3: 110kV | D3: 梨集泰线 | E3: 一般 | F3: 电缆终端红外检测 | G3: 45689 | H3: 45690 | I3: 否 | J3: 输电管理二所 | K3: 蔡昊晖 | L3: 白云中心 | M3: 6
A4: 2 | B4: 预试 | C4: 110kV | D4: 梨集泰线 | E4: 一般 | F4: 电缆终端红外检测 | G4: 45870 | H4: 45870 | I4: 否 | J4: 输电管理二所 | K4: 蔡昊晖 | L4: 白云中心 | M4: 6
A5: 3 | B5: 预试 | C5: 110kV | D5: 嘉观临线龙保乙支线 | E5: 重要（5-9月）、其余时段关注 | F5: 电缆终端红外检测 | G5: 45689 | H5: 45690 | I5: 否 | J5: 输电管理二所 | K5: 蔡昊晖 | L5: 白云中心 | M5: 3
A6: 4 | B6: 预试 | C6: 110kV | D6: 嘉观临线龙保乙支线 | E6: 重要（5-9月）、其余时段关注 | F6: 电缆终端红外检测 | G6: 45809 | H6: 45838 | I6: 否 | J6: 输电管理二所 | K6: 蔡昊晖 | L6: 白云中心 | M6: 3
A7: 5 | B7: 预试 | C7: 110kV | D7: 嘉观临线龙保乙支线 | E7: 重要（5-9月）、其余时段关注 | F7: 电缆终端红外检测 | G7: 45870 | H7: 45899 | I7: 否 | J7: 输电管理二所 | K7: 蔡昊晖 | L7: 白云中心 | M7: 3
A8: 6 | B8: 预试 | C8: 110kV | D8: 嘉观临线龙保乙支线 | E8: 重要（5-9月）、其余时段关注 | F8: 电缆终端红外检测 | G8: 45901 | H8: 45930 | I8: 否 | J8: 输电管理二所 | K8: 蔡昊晖 | L8: 白云中心 | M8: 3
A9: 7 | B9: 预试 | C9: 110kV | D9: 汉马线 | E9: 关注 | F9: 电缆终端红外检测 | G9: 45689 | H9: 45690 | I9: 否 | J9: 输电管理二所 | K9: 蔡昊晖 | L9: 白云中心 | M9: 6
A10: 8 | B10: 预试 | C10: 110kV | D10: 汉马线 | E10: 关注 | F10: 电缆终端红外检测 | G10: 45870 | H10: 45870 | I10: 否 | J10: 输电管理二所 | K10: 蔡昊晖 | L10: 白云中心 | M10: 6
A11: 9 | B11: 预试 | C11: 110kV | D11: 汉太线凤尾乙支线 | E11: 重要 | F11: 电缆终端红外检测 | G11: 45689 | H11: 45690 | I11: 否 | J11: 输电管理二所 | K11: 蔡昊晖 | L11: 白云中心 | M11: 3
A12: 10 | B12: 预试 | C12: 110kV | D12: 汉太线凤尾乙支线 | E12: 重要 | F12: 电缆终端红外检测 | G12: 45748 | H12: 45749 | I12: 否 | J12: 输电管理二所 | K12: 蔡昊晖 | L12: 白云中心 | M12: 3
A13: 11 | B13: 预试 | C13: 110kV | D13: 汉太线凤尾乙支线 | E13: 重要 | F13: 电缆终端红外检测 | G13: 45809 | H13: 45810 | I13: 否 | J13: 输电管理二所 | K13: 蔡昊晖 | L13: 白云中心 | M13: 3
A14: 12 | B14: 预试 | C14: 110kV | D14: 汉太线凤尾乙支线 | E14: 重要 | F14: 电缆终端红外检测 | G14: 45870 | H14: 45871 | I14: 否 | J14: 输电管理二所 | K14: 蔡昊晖 | L14: 白云中心 | M14: 3
... A447: 445 | B447: 预试 | C447: 110kV | D447: 郭车甲线新街甲支线 | E447: 一般 | F447: 电缆终端红外检测 | G447: 45931 | H447: 45931 | I447: 否 | J447: 输电管理二所 | K447: 叶翔 | L447: 花都中心 | M447: 6
A448: 446 | B448: 预试 | C448: 110kV | D448: 文石线 | E448: 一般 | F448: 电缆终端红外检测 | G448: 45658 | H448: 45658 | I448: 否 | J448: 输电管理二所 | K448: 叶翔 | L448: 花都中心
A449: 447 | B449: 预试 | C449: 110kV | D449: 文石线 | E449: 一般 | F449: 电缆终端红外检测 | G449: 45839 | H449: 45839 | I449: 否 | J449: 输电管理二所 | K449: 叶翔 | L449: 花都中心
A450: 448 | B450: 预试 | C450: 110kV | D450: 文公乙线石岗乙支线 | E450: 一般 | F450: 电缆终端红外检测 | G450: 45658 | H450: 45658 | I450: 否 | J450: 输电管理二所 | K450: 叶翔 | L450: 花都中心
A451: 449 | B451: 预试 | C451: 110kV | D451: 文公乙线石岗乙支线 | E451: 一般 | F451: 电缆终端红外检测 | G451: 45839 | H451: 45839 | I451: 否 | J451: 输电管理二所 | K451: 叶翔 | L451: 花都中心
A452: 450 | B452: 预试 | C452: 110kV | D452: 车大乙线新街乙支线 | E452: 一般 | F452: 电缆终端红外检测 | G452: 45748 | H452: 45777 | I452: 否 | J452: 输电管理二所 | K452: 叶翔 | L452: 花都中心 | M452: 6
A453: 451 | B453: 预试 | C453: 110kV | D453: 车大乙线新街乙支线 | E453: 一般 | F453: 电缆终端红外检测 | G453: 45931 | H453: 45931 | I453: 否 | J453: 输电管理二所 | K453: 叶翔 | L453: 花都中心 | M453: 6
A454: 452 | B454: 预试 | C454: 110kV | D454: 车金甲线 | E454: 重要 | F454: 电缆终端红外检测 | G454: 45323 | H454: 45323 | I454: 否 | J454: 输电管理二所 | K454: 叶翔 | L454: 花都中心 | M454: 6
A455: 453 | B455: 预试 | C455: 110kV | D455: 车金甲线 | E455: 重要 | F455: 电缆终端红外检测 | G455: 45383 | H455: 45383 | I455: 否 | J455: 输电管理二所 | K455: 叶翔 | L455: 花都中心 | M455: 6
A456: 454 | B456: 预试 | C456: 110kV | D456: 车金甲线 | E456: 重要 | F456: 电缆终端红外检测 | G456: 45444 | H456: 45444 | I456: 否 | J456: 输电管理二所 | K456: 叶翔 | L456: 花都中心 | M456: 6
A457: 455 | B457: 预试 | C457: 110kV | D457: 车金甲线 | E457: 重要 | F457: 电缆终端红外检测 | G457: 45505 | H457: 45505 | I457: 否 | J457: 输电管理二所 | K457: 叶翔 | L457: 花都中心 | M457: 6
A458: 456 | B458: 预试 | C458: 110kV | D458: 车金甲线 | E458: 重要 | F458: 电缆终端红外检测 | G458: 45566 | H458: 45566 | I458: 否 | J458: 输电管理二所 | K458: 叶翔 | L458: 花都中心 | M458: 6
A459: 457 | B459: 预试 | C459: 110kV | D459: 车金甲线 | E459: 重要 | F459: 电缆终端红外检测 | G459: 45627 | H459: 45627 | I459: 否 | J459: 输电管理二所 | K459: 叶翔 | L459: 花都中心 | M459: 6
A460: 458 | B460: 预试 | C460: 110kV | D460: 车金乙线 | E460: 重要 | F460: 电缆终端红外检测 | G460: 45323 | H460: 45323 | I460: 否 | J460: 输电管理二所 | K460: 叶翔 | L460: 花都中心 | M460: 6
A461: 459 | B461: 预试 | C461: 110kV | D461: 车金乙线 | E461: 重要 | F461: 电缆终端红外检测 | G461: 45383 | H461: 45383 | I461: 否 | J461: 输电管理二所 | K461: 叶翔 | L461: 花都中心 | M461: 6
A462: 460 | B462: 预试 | C462: 110kV | D462: 车金乙线 | E462: 重要 | F462: 电缆终端红外检测 | G462: 45444 | H462: 45444 | I462: 否 | J462: 输电管理二所 | K462: 叶翔 | L462: 花都中心 | M462: 6
A463: 461 | B463: 预试 | C463: 110kV | D463: 车金乙线 | E463: 重要 | F463: 电缆终端红外检测 | G463: 45505 | H463: 45505 | I463: 否 | J463: 输电管理二所 | K463: 叶翔 | L463: 花都中心 | M463: 6
... A777: 775 | B777: 预试 | C777: 110kV | D777: 热北线 | E777: 一般 | F777: 电缆终端红外检测 | G777: 46022 | H777: 46022 | I777: 否 | J777: 输电管理二所 | K777: 吴达 | L777: 天河中心 | M777: 3

Sheet 7、避雷器红外检测
A1: 输电管理二所2025年预试检测计划 （电缆避雷器红外检测（不含老旧电缆）：关键线路：2月1次，重要线路：2月1次，一般及关注线路110kV：上、下半年各1次；220kV：每季度1次） （超三十年老旧电缆避雷器红外检测：关键线路：2月1次，重要线路：2月1次，一般及关注线路：每季度1次）
A2: 序号 | B2: 工作类型 | C2: 电压等级 | D2: 变电站/线路 | E2: 线路重要度 | F2: 工作内容 | G2: 计划开始日期 | H2: 计划结束日期 | I2: 是否停电 | J2: 责任单位 | K2: 中心负责人 | L2: 责任中心 | M2: 计划完成数(相） | N2: 实际开始日期 | O2: 实际结束日期 | P2: 实际完成数 | Q2: 合格数量 | R2: 完成率 | S2: 合格率 | T2: 备注（未完成原因） | V2: 工作地点和内容 | W2: 计划编号 | X2: 完成情况 | Y2: 完成月份 | Z2: 计划临期提醒
A3: 1 | B3: 预试 | C3: 110kV | D3: 汉马线 | E3: 关注 | F3: 避雷器红外检测 | G3: 45689 | H3: 45690 | I3: 否 | J3: 输电管理二所 | K3: 蔡昊晖 | L3: 白云中心 | M3: 3
A4: 2 | B4: 预试 | C4: 110kV | D4: 汉马线 | E4: 关注 | F4: 避雷器红外检测 | G4: 45870 | H4: 45870 | I4: 否 | J4: 输电管理二所 | K4: 蔡昊晖 | L4: 白云中心 | M4: 3
A5: 3 | B5: 预试 | C5: 110kV | D5: 汉太线凤尾乙支线 | E5: 重要 | F5: 避雷器红外检测 | G5: 45689 | H5: 45690 | I5: 否 | J5: 输电管理二所 | K5: 蔡昊晖 | L5: 白云中心 | M5: 3
A6: 4 | B6: 预试 | C6: 110kV | D6: 汉太线凤尾乙支线 | E6: 重要 | F6: 避雷器红外检测 | G6: 45748 | H6: 45749 | I6: 否 | J6: 输电管理二所 | K6: 蔡昊晖 | L6: 白云中心 | M6: 3
A7: 5 | B7: 预试 | C7: 110kV | D7: 汉太线凤尾乙支线 | E7: 重要 | F7: 避雷器红外检测 | G7: 45809 | H7: 45810 | I7: 否 | J7: 输电管理二所 | K7: 蔡昊晖 | L7: 白云中心 | M7: 3
A8: 6 | B8: 预试 | C8: 110kV | D8: 汉太线凤尾乙支线 | E8: 重要 | F8: 避雷器红外检测 | G8: 45870 | H8: 45871 | I8: 否 | J8: 输电管理二所 | K8: 蔡昊晖 | L8: 白云中心 | M8: 3
A9: 7 | B9: 预试 | C9: 110kV | D9: 汉太线凤尾乙支线 | E9: 重要 | F9: 避雷器红外检测 | G9: 45931 | H9: 45932 | I9: 否 | J9: 输电管理二所 | K9: 蔡昊晖 | L9: 白云中心 | M9: 3
A10: 8 | B10: 预试 | C10: 110kV | D10: 汉太线凤尾乙支线 | E10: 重要 | F10: 避雷器红外检测 | G10: 45992 | H10: 45993 | I10: 否 | J10: 输电管理二所 | K10: 蔡昊晖 | L10: 白云中心 | M10: 3
A11: 9 | B11: 预试 | C11: 110kV | D11: 汉云乙线凤尾甲支线 | E11: 重要 | F11: 避雷器红外检测 | G11: 45689 | H11: 45690 | I11: 否 | J11: 输电管理二所 | K11: 蔡昊晖 | L11: 白云中心 | M11: 3
A12: 10 | B12: 预试 | C12: 110kV | D12: 汉云乙线凤尾甲支线 | E12: 重要 | F12: 避雷器红外检测 | G12: 45748 | H12: 45749 | I12: 否 | J12: 输电管理二所 | K12: 蔡昊晖 | L12: 白云中心 | M12: 3
A13: 11 | B13: 预试 | C13: 110kV | D13: 汉云乙线凤尾甲支线 | E13: 重要 | F13: 避雷器红外检测 | G13: 45809 | H13: 45810 | I13: 否 | J13: 输电管理二所 | K13: 蔡昊晖 | L13: 白云中心 | M13: 3
A14: 12 | B14: 预试 | C14: 110kV | D14: 汉云乙线凤尾甲支线 | E14: 重要 | F14: 避雷器红外检测 | G14: 45870 | H14: 45871 | I14: 否 | J14: 输电管理二所 | K14: 蔡昊晖 | L14: 白云中心 | M14: 3
... A452: 450 | B452: 预试 | C452: 110kV | D452: 犀上牛麒线 | E452: 重要（5-9月）、其余时段一般 | F452: 避雷器红外检测 | G452: 45992 | H452: 46022 | I452: 否 | J452: 输电管理二所 | K452: 吴达 | L452: 天河中心 | M452: 3

Sheet 8、非直埋式中间接头红外检测 
A1: 输电管理二所2025年预试检测计划 （电缆非直埋中间接头红外检测（不含老旧电缆）：关键线路：2月1次，重要线路：2月1次，一般及关注线路110kV：上、下半年各1次；220kV：每季度1次） （超三十年老旧电缆非直埋中间接头红外检测：关键线路：2月1次，重要线路：2月1次，一般及关注线路：每季度1次） 对于敷设在同一隧道同一舱内的所有电缆线路，红外检测周期按照最高电压等级要求同时执行。
A2: 序号 | B2: 工作类型 | C2: 电压等级 | D2: 变电站/线路 | E2: 线路重要度 | F2: 工作内容 | G2: 计划开始日期 | H2: 计划结束日期 | I2: 是否停电 | J2: 责任单位 | K2: 中心负责人 | L2: 责任中心 | M2: 每次计划完成数（相） | N2: 实际开始日期 | O2: 实际结束日期 | P2: 每次实际完成数 | Q2: 合格数量 | R2: 完成率 | S2: 合格率 | T2: 备注（未按时完成原因） | U2: 工作地点和内容 | V2: 计划编号 | W2: 完成情况 | X2: 完成月份 | Y2: 计划临期提醒
A3: 1 | B3: 预试 | C3: 110kV | D3: 航苗隆鹤线 | E3: 重要（5-9月）、其余时段一般 | F3: 非直埋式中间接头红外检测 | G3: 45689 | H3: 45690 | I3: 否 | J3: 输电管理二所 | K3: 蔡昊晖 | L3: 白云中心 | M3: 3
A4: 2 | B4: 预试 | C4: 110kV | D4: 航苗隆鹤线 | E4: 重要（5-9月）、其余时段一般 | F4: 非直埋式中间接头红外检测 | G4: 45748 | H4: 45749 | I4: 否 | J4: 输电管理二所 | K4: 蔡昊晖 | L4: 白云中心 | M4: 3
A5: 3 | B5: 预试 | C5: 110kV | D5: 航苗隆鹤线 | E5: 重要（5-9月）、其余时段一般 | F5: 非直埋式中间接头红外检测 | G5: 45809 | H5: 45810 | I5: 否 | J5: 输电管理二所 | K5: 蔡昊晖 | L5: 白云中心 | M5: 3
A6: 4 | B6: 预试 | C6: 110kV | D6: 航苗隆鹤线 | E6: 重要（5-9月）、其余时段一般 | F6: 非直埋式中间接头红外检测 | G6: 45870 | H6: 45871 | I6: 否 | J6: 输电管理二所 | K6: 蔡昊晖 | L6: 白云中心 | M6: 3
A7: 5 | B7: 预试 | C7: 110kV | D7: 航苗隆鹤线 | E7: 重要（5-9月）、其余时段一般 | F7: 非直埋式中间接头红外检测 | G7: 45931 | H7: 45932 | I7: 否 | J7: 输电管理二所 | K7: 蔡昊晖 | L7: 白云中心 | M7: 3
A8: 6 | B8: 预试 | C8: 110kV | D8: 航苗隆鹤线 | E8: 重要（5-9月）、其余时段一般 | F8: 非直埋式中间接头红外检测 | G8: 45992 | H8: 45993 | I8: 否 | J8: 输电管理二所 | K8: 蔡昊晖 | L8: 白云中心 | M8: 3
A9: 7 | B9: 预试 | C9: 110kV | D9: 凯陈夏隆线 | E9: 重要 | F9: 非直埋式中间接头红外检测 | G9: 45689 | H9: 45690 | I9: 否 | J9: 输电管理二所 | K9: 蔡昊晖 | L9: 白云中心 | M9: 3
A10: 8 | B10: 预试 | C10: 110kV | D10: 凯陈夏隆线 | E10: 重要 | F10: 非直埋式中间接头红外检测 | G10: 45748 | H10: 45749 | I10: 否 | J10: 输电管理二所 | K10: 蔡昊晖 | L10: 白云中心 | M10: 3
A11: 9 | B11: 预试 | C11: 110kV | D11: 凯陈夏隆线 | E11: 重要 | F11: 非直埋式中间接头红外检测 | G11: 45809 | H11: 45810 | I11: 否 | J11: 输电管理二所 | K11: 蔡昊晖 | L11: 白云中心 | M11: 3
A12: 10 | B12: 预试 | C12: 110kV | D12: 凯陈夏隆线 | E12: 重要 | F12: 非直埋式中间接头红外检测 | G12: 45870 | H12: 45871 | I12: 否 | J12: 输电管理二所 | K12: 蔡昊晖 | L12: 白云中心 | M12: 3
A13: 11 | B13: 预试 | C13: 110kV | D13: 凯陈夏隆线 | E13: 重要 | F13: 非直埋式中间接头红外检测 | G13: 45931 | H13: 45932 | I13: 否 | J13: 输电管理二所 | K13: 蔡昊晖 | L13: 白云中心 | M13: 3
A14: 12 | B14: 预试 | C14: 110kV | D14: 凯陈夏隆线 | E14: 重要 | F14: 非直埋式中间接头红外检测 | G14: 45992 | H14: 45993 | I14: 否 | J14: 输电管理二所 | K14: 蔡昊晖 | L14: 白云中心 | M14: 3
... A281: 279 | B281: 预试 | C281: 110kV | D281: 文公乙线 | E281: 一般 | F281: 非直埋式中间接头红外检测 | G281: 45839 | H281: 45839 | I281: 否 | J281: 输电管理二所 | K281: 叶翔 | L281: 花都中心 | M281: 6
A282: 280 | B282: 预试 | C282: 110kV | D282: 文石线 | E282: 一般 | F282: 非直埋式中间接头红外检测 | G282: 45658 | H282: 45658 | I282: 否 | J282: 输电管理二所 | K282: 叶翔 | L282: 花都中心
A283: 281 | B283: 预试 | C283: 110kV | D283: 文石线 | E283: 一般 | F283: 非直埋式中间接头红外检测 | G283: 45839 | H283: 45839 | I283: 否 | J283: 输电管理二所 | K283: 叶翔 | L283: 花都中心
A284: 282 | B284: 预试 | C284: 110kV | D284: 文公乙线石岗乙支线 | E284: 一般 | F284: 非直埋式中间接头红外检测 | G284: 45658 | H284: 45658 | I284: 否 | J284: 输电管理二所 | K284: 叶翔 | L284: 花都中心
A285: 283 | B285: 预试 | C285: 110kV | D285: 文公乙线石岗乙支线 | E285: 一般 | F285: 非直埋式中间接头红外检测 | G285: 45839 | H285: 45839 | I285: 否 | J285: 输电管理二所 | K285: 叶翔 | L285: 花都中心
A286: 284 | B286: 预试 | C286: 110kV | D286: 田龙甲线 | E286: 一般 | F286: 非直埋式中间接头红外检测 | G286: 45689 | H286: 45689 | I286: 否 | J286: 输电管理二所 | K286: 叶翔 | L286: 花都中心 | M286: 24
A287: 285 | B287: 预试 | C287: 110kV | D287: 田龙甲线 | E287: 一般 | F287: 非直埋式中间接头红外检测 | G287: 45809 | H287: 45809 | I287: 否 | J287: 输电管理二所 | K287: 叶翔 | L287: 花都中心 | M287: 24
A288: 286 | B288: 预试 | C288: 110kV | D288: 田龙甲线 | E288: 一般 | F288: 非直埋式中间接头红外检测 | G288: 45870 | H288: 45870 | I288: 否 | J288: 输电管理二所 | K288: 叶翔 | L288: 花都中心 | M288: 24
A289: 287 | B289: 预试 | C289: 110kV | D289: 田龙甲线 | E289: 一般 | F289: 非直埋式中间接头红外检测 | G289: 45931 | H289: 45931 | I289: 否 | J289: 输电管理二所 | K289: 叶翔 | L289: 花都中心 | M289: 24
A290: 288 | B290: 预试 | C290: 220kV | D290: 镜田甲线 | E290: 一般 | F290: 非直埋式中间接头红外检测 | G290: 45689 | H290: 45689 | I290: 否 | J290: 输电管理二所 | K290: 叶翔 | L290: 花都中心 | M290: 24
A291: 289 | B291: 预试 | C291: 220kV | D291: 镜田甲线 | E291: 一般 | F291: 非直埋式中间接头红外检测 | G291: 45809 | H291: 45809 | I291: 否 | J291: 输电管理二所 | K291: 叶翔 | L291: 花都中心 | M291: 24
A292: 290 | B292: 预试 | C292: 220kV | D292: 镜田甲线 | E292: 一般 | F292: 非直埋式中间接头红外检测 | G292: 45870 | H292: 45870 | I292: 否 | J292: 输电管理二所 | K292: 叶翔 | L292: 花都中心 | M292: 24
A293: 291 | B293: 预试 | C293: 220kV | D293: 镜田甲线 | E293: 一般 | F293: 非直埋式中间接头红外检测 | G293: 45931 | H293: 45931 | I293: 否 | J293: 输电管理二所 | K293: 叶翔 | L293: 花都中心 | M293: 24
A294: 292 | B294: 预试 | C294: 220kV | D294: 镜田乙线 | E294: 一般 | F294: 非直埋式中间接头红外检测 | G294: 45689 | H294: 45689 | I294: 否 | J294: 输电管理二所 | K294: 叶翔 | L294: 花都中心 | M294: 24
A295: 293 | B295: 预试 | C295: 220kV | D295: 镜田乙线 | E295: 一般 | F295: 非直埋式中间接头红外检测 | G295: 45809 | H295: 45809 | I295: 否 | J295: 输电管理二所 | K295: 叶翔 | L295: 花都中心 | M295: 24
A296: 294 | B296: 预试 | C296: 220kV | D296: 镜田乙线 | E296: 一般 | F296: 非直埋式中间接头红外检测 | G296: 45870 | H296: 45870 | I296: 否 | J296: 输电管理二所 | K296: 叶翔 | L296: 花都中心 | M296: 24
A297: 295 | B297: 预试 | C297: 220kV | D297: 镜田乙线 | E297: 一般 | F297: 非直埋式中间接头红外检测 | G297: 45931 | H297: 45931 | I297: 否 | J297: 输电管理二所 | K297: 叶翔 | L297: 花都中心 | M297: 24
... A646: 644 | B646: 预试 | C646: 110kV | D646: 猎凌桥线 | E646: 一般 | F646: 非直埋式中间接头红外检测 | G646: 45992 | H646: 46021 | I646: 否 | J646: 输电管理二所 | K646: 吴达 | L646: 天河中心 | M646: 9

Sheet 9、局放试验计划
A1: 输电管理二所2025年预试检测计划 （局放试验：110kV电缆线路投运后3年内一次，运行20年后每6年一次；220kV电缆线路投运后3年内一次，之后每6年一次。） （超三十年老旧电缆：1年一次）
A2: 序号 | B2: 工作类型 | C2: 电压等级 | D2: 变电站/线路 | E2: 线路重要度 | F2: 工作内容 | G2: 计划开始日期 | H2: 计划结束日期 | I2: 是否停电 | J2: 责任单位 | K2: 中心负责人 | L2: 责任中心 | M2: 计划完成数(相） | N2: 实际开始日期 | O2: 实际结束日期 | P2: 实际完成数 | Q2: 合格数量 | R2: 完成率 | S2: 合格率 | T2: 备注
